Workbook

Sheet Lookup
A1: \ | B1: Paid Leave | C1: Worked day 30 | D1: Paid Leave | E1: Worked day 29 | F1: Paid Leave | G1: Worked day 28 | H1: Paid Leave
A2: 1 | B2: 0 | C2: 1 | D2: 0 | E2: 1 | F2: 0 | G2: 1 | H2: 0
A3: 2 | B3: 0 | C3: 2 | D3: 0 | E3: 2 | F3: 0 | G3: 2 | H3: 0
A4: 3 | B4: 0 | C4: 3 | D4: 0 | E4: 3 | F4: 0 | G4: 3 | H4: 0
A5: 4 | B5: 0 | C5: 4 | D5: 0 | E5: 4 | F5: 0 | G5: 4 | H5: 0
A6: 5 | B6: 0 | C6: 5 | D6: 0 | E6: 5 | F6: 0 | G6: 5 | H6: 0
A7: 6 | B7: 0 | C7: 6 | D7: 0 | E7: 6 | F7: 0 | G7: 6 | H7: 0
A8: 7 | B8: 0 | C8: 7 | D8: 0 | E8: 7 | F8: 0 | G8: 7 | H8: 0
A9: 8 | B9: 0 | C9: 8 | D9: 0 | E9: 8 | F9: 0 | G9: 8 | H9: 0
A10: 9 | B10: 0 | C10: 9 | D10: 0 | E10: 9 | F10: 0 | G10: 9 | H10: 0
A11: 10 | B11: 0 | C11: 10 | D11: 0 | E11: 10 | F11: 0 | G11: 10 | H11: 0
A12: 11 | B12: 0 | C12: 11 | D12: 0 | E12: 11 | F12: 0 | G12: 11 | H12: 0
A13: 12 | B13: 0 | C13: 12 | D13: 0 | E13: 12 | F13: 0 | G13: 12 | H13: 0
... A29: 28 | B29: 1 | C29: 28 | D29: 2 | E29: 28 | F29: 2 | G29: 28 | H29: 2
A30: 29 | B30: 2 | C30: 29 | D30: 2 | E30: 29 | F30: 2
A31: 30 | B31: 2 | C31: 30 | D31: 2
A32: 31 | B32: 2

Sheet November-24
D1: =day(EOMONTH(T2,0)) -> 30 | E1: =iferror(concatenate(" Enter ", 'Attendance key'!$B$7, " for ",'Attendance key'!$C$7, ", ", 'Attendance key'!$B$8, " for ", 'Attendance key'!$C$8, ", ", 'Attendance key'!$B$9, " for ", 'Attendance key'!$C$9, ", and ", 'Attendance key'!$B$10, " for ", 'Attendance key'!$C$10, ". Use the 'Attendance key' tab to customise. "),"") -> Enter Present for Present, Off for Leave, Half Day for Half Day, and Left for Attried. Use the 'Attendance key' tab to customise.
B2: Month | E2: 45597 | F2: =IF(MONTH(E2+1)=MONTH(EOMONTH($E$2,0)),E2+1,"") -> 45598 | G2: =IF(MONTH(F2+1)=MONTH(EOMONTH($E$2,0)),F2+1,"") -> 45599 | H2: =IF(MONTH(G2+1)=MONTH(EOMONTH($E$2,0)),G2+1,"") -> 45600 | I2: =IF(MONTH(H2+1)=MONTH(EOMONTH($E$2,0)),H2+1,"") -> 45601 | J2: =IF(MONTH(I2+1)=MONTH(EOMONTH($E$2,0)),I2+1,"") -> 45602 | K2: =IF(MONTH(J2+1)=MONTH(EOMONTH($E$2,0)),J2+1,"") -> 45603 | L2: =IF(MONTH(K2+1)=MONTH(EOMONTH($E$2,0)),K2+1,"") -> 45604 | M2: =IF(MONTH(L2+1)=MONTH(EOMONTH($E$2,0)),L2+1,"") -> 45605 | ... AI2: =IF(MONTH(AH2+1)=MONTH(EOMONTH($E$2,0)),AH2+1,"") | AJ2: ='Attendance key'!$C7 -> Present | AK2: ='Attendance key'!$C8 -> Leave | AL2: ='Attendance key'!$C9 -> Half Day | AM2: Total Payable Days
A3: Key | B3: Name | D3: Department | E3: =E2 -> 45597 | F3: =F2 -> 45598 | G3: =G2 -> 45599 | H3: =H2 -> 45600 | I3: =I2 -> 45601 | J3: =J2 -> 45602 | K3: =K2 -> 45603 | L3: =L2 -> 45604 | ... AI3: =AI2 | AJ3: ='Attendance key'!$B7 -> Present | AK3: ='Attendance key'!$B8 -> Off | AL3: ='Attendance key'!$B9 -> Half Day
A4: =B4&C4&D4 -> AkhilCaptainService | B4: Akhil | C4: Captain | D4: Service | E4: Present | F4: Present | G4: Present | H4: Present | I4: Present | J4: Present | K4: Present | L4: Present | M4: Present | N4: Present | O4: Present | P4: Present | Q4: Present | R4: Present | S4: Present | T4: Present | U4: Present | V4: Present | W4: Present | X4: Present | Y4: Present | Z4: Present | AA4: Present | AB4: Present | AC4: Present | AD4: Present | AE4: Present | AF4: Present | AG4: Present | AH4: Present | AJ4: =if(countif($E4:$AI4,AJ$3)>day(EOMONTH($T$2,0)),"Error",countif($E4:$AI4,AJ$3)) -> 30 | AK4: =countif($E4:$AI4,AK$3) -> 0 | AL4: =countif($E4:$AI4,AL$3) -> 0 | AM4: =AJ4 + AK4 +(AL4 / 2) -> 30
A5: =B5&C5&D5 -> Laxmi BaiHelperMori | B5: Laxmi Bai | C5: Helper | D5: Mori | E5: Present | F5: Present | G5: Present | H5: Present | I5: Present | J5: Present | K5: Present | L5: Present | M5: Present | N5: Present | O5: Present | P5: Present | Q5: Present | R5: Present | S5: Present | T5: Present | U5: Present | V5: Present | W5: Present | X5: Present | Y5: Present | Z5: Present | AA5: Present | AB5: Present | AC5: Present | AD5: Present | AE5: Present | AF5: Present | AG5: Present | AH5: Present | AJ5: =if(countif($E5:$AI5,AJ$3)>day(EOMONTH($T$2,0)),"Error",countif($E5:$AI5,AJ$3)) -> 30 | AK5: =countif($E5:$AI5,AK$3) -> 0 | AL5: =countif($E5:$AI5,AL$3) -> 0 | AM5: =AJ5 + AK5 +(AL5 / 2) -> 30
A6: =B6&C6&D6 -> MoleemChefTandoor | B6: Moleem | C6: Chef | D6: Tandoor | E6: Present | F6: Present | G6: Present | H6: Present | I6: Present | J6: Present | K6: Present | L6: Present | M6: Present | N6: Present | O6: Present | P6: Present | Q6: Present | R6: Present | S6: Present | T6: Present | U6: Present | V6: Off | W6: Present | X6: Present | Y6: Present | Z6: Present | AA6: Present | AB6: Present | AC6: Present | AD6: Present | AE6: Present | AF6: Present | AG6: Present | AH6: Present | AJ6: =if(countif($E6:$AI6,AJ$3)>day(EOMONTH($T$2,0)),"Error",countif($E6:$AI6,AJ$3)) -> 29 | AK6: =countif($E6:$AI6,AK$3) -> 1 | AL6: =countif($E6:$AI6,AL$3) -> 0 | AM6: =AJ6 + AK6 +(AL6 / 2) -> 30
A7: =B7&C7&D7 -> SuhailWaiterService | B7: Suhail | C7: Waiter | D7: Service | I7: Present | J7: Present | K7: Present | L7: Present | M7: Present | N7: Present | O7: Present | P7: Present | Q7: Present | R7: Present | S7: Present | T7: Present | U7: Present | V7: Present | W7: Present | X7: Present | Y7: Present | Z7: Present | AA7: Present | AB7: Present | AC7: Off | AD7: Present | AE7: Present | AF7: Present | AG7: Present | AH7: Present | AJ7: =if(countif($E7:$AI7,AJ$3)>day(EOMONTH($T$2,0)),"Error",countif($E7:$AI7,AJ$3)) -> 25 | AK7: =countif($E7:$AI7,AK$3) -> 1 | AL7: =countif($E7:$AI7,AL$3) -> 0 | AM7: =AJ7 + AK7 +(AL7 / 2) -> 26
A8: =B8&C8&D8 -> SameerHelperTandoor | B8: Sameer | C8: Helper | D8: Tandoor | E8: Present | F8: Present | G8: Present | H8: Off | I8: Present | J8: Present | K8: Present | L8: Present | M8: Present | N8: Present | O8: Present | P8: Present | Q8: Present | R8: Present | S8: Present | T8: Present | U8: Present | V8: Present | W8: Present | X8: Present | Y8: Present | Z8: Present | AA8: Present | AB8: Present | AC8: Present | AD8: Present | AE8: Present | AF8: Present | AG8: Present | AH8: Present | AJ8: =if(countif($E8:$AI8,AJ$3)>day(EOMONTH($T$2,0)),"Error",countif($E8:$AI8,AJ$3)) -> 29 | AK8: =countif($E8:$AI8,AK$3) -> 1 | AL8: =countif($E8:$AI8,AL$3) -> 0 | AM8: =AJ8 + AK8 +(AL8 / 2) -> 30
A9: =B9&C9&D9 -> WakilHelperMori | B9: Wakil | C9: Helper | D9: Mori | E9: Present | F9: Present | G9: Present | H9: Present | I9: Off | J9: Present | K9: Present | L9: Present | M9: Present | N9: Present | O9: Off | P9: Present | Q9: Present | R9: Present | S9: Present | T9: Present | U9: Present | V9: Off | W9: Present | X9: Present | Y9: Present | Z9: Present | AA9: Present | AB9: Present | AC9: Present | AD9: Present | AE9: Present | AF9: Present | AG9: Present | AH9: Present | AJ9: =if(countif($E9:$AI9,AJ$3)>day(EOMONTH($T$2,0)),"Error",countif($E9:$AI9,AJ$3)) -> 27 | AK9: =countif($E9:$AI9,AK$3) -> 3 | AL9: =countif($E9:$AI9,AL$3) -> 0 | AM9: =AJ9 + AK9 +(AL9 / 2) -> 30
A10: =B10&C10&D10 -> VijayChefTandoor | B10: Vijay | C10: Chef | D10: Tandoor | E10: Present | F10: Present | G10: Present | H10: Present | I10: Present | J10: Present | K10: Present | L10: Present | M10: Present | N10: Present | O10: Present | P10: Present | Q10: Present | R10: Present | S10: Present | T10: Present | U10: Present | V10: Present | W10: Off | X10: Present | Y10: Present | Z10: Present | AA10: Present | AB10: Present | AC10: Present | AD10: Off | AE10: Off | AF10: Off | AG10: Off | AH10: Off | AJ10: =if(countif($E10:$AI10,AJ$3)>day(EOMONTH($T$2,0)),"Error",countif($E10:$AI10,AJ$3)) -> 24 | AK10: =countif($E10:$AI10,AK$3) -> 6 | AL10: =countif($E10:$AI10,AL$3) -> 0 | AM10: =AJ10 + AK10 +(AL10 / 2) -> 30
A11: =B11&C11&D11 -> NaseemSupervisorSupervisor | B11: Naseem | C11: Supervisor | D11: Supervisor | E11: Present | F11: Present | G11: Present | H11: Present | I11: Present | J11: Present | K11: Present | L11: Present | M11: Present | N11: Present | O11: Present | P11: Present | Q11: Present | R11: Present | S11: Present | T11: Present | U11: Present | V11: Present | W11: Present | X11: Present | Y11: Present | Z11: Present | AA11: Present | AB11: Present | AC11: Present | AD11: Present | AE11: Present | AF11: Present | AG11: Present | AH11: Present | AJ11: =if(countif($E11:$AI11,AJ$3)>day(EOMONTH($T$2,0)),"Error",countif($E11:$AI11,AJ$3)) -> 30 | AK11: =countif($E11:$AI11,AK$3) -> 0 | AL11: =countif($E11:$AI11,AL$3) -> 0 | AM11: =AJ11 + AK11 +(AL11 / 2) -> 30
A12: =B12&C12&D12 -> RajeshCombiTandoor | B12: Rajesh | C12: Combi | D12: Tandoor | T12: Present | U12: Present | V12: Present | W12: Present | X12: Present | Y12: Present | Z12: Present | AA12: Present | AB12: Present | AC12: Present | AD12: Present | AE12: Present | AF12: Present | AG12: Present | AH12: Present | AJ12: =if(countif($E12:$AI12,AJ$3)>day(EOMONTH($T$2,0)),"Error",countif($E12:$AI12,AJ$3)) -> 15 | AK12: =countif($E12:$AI12,AK$3) -> 0 | AL12: =countif($E12:$AI12,AL$3) -> 0 | AM12: =AJ12 + AK12 +(AL12 / 2) -> 15
A13: =B13&C13&D13 -> AyubChefTava | B13: Ayub | C13: Chef | D13: Tava | E13: Present | F13: Present | G13: Present | H13: Present | I13: Present | J13: Present | K13: Off | L13: Present | M13: Present | N13: Present | O13: Present | P13: Present | Q13: Present | R13: Present | S13: Present | T13: Present | U13: Present | V13: Present | W13: Present | X13: Present | Y13: Present | Z13: Present | AA13: Present | AB13: Present | AC13: Present | AD13: Present | AE13: Present | AF13: Present | AG13: Present | AH13: Present | AJ13: =if(countif($E13:$AI13,AJ$3)>day(EOMONTH($T$2,0)),"Error",countif($E13:$AI13,AJ$3)) -> 29 | AK13: =countif($E13:$AI13,AK$3) -> 1 | AL13: =countif($E13:$AI13,AL$3) -> 0 | AM13: =AJ13 + AK13 +(AL13 / 2) -> 30
A14: =B14&C14&D14 -> AasifChefIndian | B14: Aasif | C14: Chef | D14: Indian | E14: Present | F14: Half Day | G14: Present | H14: Present | I14: Present | J14: Present | K14: Present | L14: Present | M14: Present | N14: Present | O14: Present | P14: Present | Q14: Present | R14: Present | S14: Present | T14: Present | U14: Present | V14: Present | W14: Present | X14: Present | Y14: Present | Z14: Present | AA14: Present | AB14: Present | AC14: Present | AD14: Present | AE14: Present | AF14: Present | AG14: Present | AH14: Present | AJ14: =if(countif($E14:$AI14,AJ$3)>day(EOMONTH($T$2,0)),"Error",countif($E14:$AI14,AJ$3)) -> 29 | AK14: =countif($E14:$AI14,AK$3) -> 0 | AL14: =countif($E14:$AI14,AL$3) -> 1 | AM14: =AJ14 + AK14 +(AL14 / 2) -> 29.5
A15: =B15&C15&D15 -> BaitullaCombiIndian | B15: Baitulla | C15: Combi | D15: Indian | E15: Present | F15: Present | G15: Present | H15: Present | I15: Off | J15: Present | K15: Present | L15: Present | M15: Present | N15: Present | O15: Off | P15: Present | Q15: Present | R15: Present | S15: Present | T15: Present | U15: Present | V15: Present | W15: Present | X15: Present | Y15: Present | Z15: Present | AA15: Present | AB15: Present | AC15: Present | AD15: Off | AE15: Present | AF15: Present | AG15: Present | AH15: Present | AJ15: =if(countif($E15:$AI15,AJ$3)>day(EOMONTH($T$2,0)),"Error",countif($E15:$AI15,AJ$3)) -> 27 | AK15: =countif($E15:$AI15,AK$3) -> 3 | AL15: =countif($E15:$AI15,AL$3) -> 0 | AM15: =AJ15 + AK15 +(AL15 / 2) -> 30
A16: =B16&C16&D16 -> Glenn SirManagerManager | B16: Glenn Sir | C16: Manager | D16: Manager | E16: Off | F16: Off | G16: Off | H16: Off | I16: Off | J16: Off | K16: Off | L16: Present | M16: Present | N16: Present | O16: Present | P16: Present | Q16: Present | R16: Present | S16: Left | T16: Left | U16: Left | V16: Left | W16: Left | X16: Left | Y16: Left | Z16: Left | AA16: Left | AB16: Left | AC16: Left | AD16: Left | AE16: Left | AF16: Left | AG16: Left | AH16: Left | AJ16: =if(countif($E16:$AI16,AJ$3)>day(EOMONTH($T$2,0)),"Error",countif($E16:$AI16,AJ$3)) -> 7 | AK16: =countif($E16:$AI16,AK$3) -> 7 | AL16: =countif($E16:$AI16,AL$3) -> 0 | AM16: =AJ16 + AK16 +(AL16 / 2) -> 14
A17: =B17&C17&D17 -> AbdullahCombiChinese | B17: Abdullah | C17: Combi | D17: Chinese | E17: Present | F17: Present | G17: Present | H17: Off | I17: Present | J17: Present | K17: Present | L17: Present | M17: Present | N17: Present | O17: Present | P17: Present | Q17: Present | R17: Present | S17: Present | T17: Present | U17: Present | V17: Present | W17: Present | X17: Present | Y17: Present | Z17: Present | AA17: Present | AB17: Present | AC17: Present | AD17: Present | AE17: Present | AF17: Present | AG17: Present | AH17: Present | AJ17: =if(countif($E17:$AI17,AJ$3)>day(EOMONTH($T$2,0)),"Error",countif($E17:$AI17,AJ$3)) -> 29 | AK17: =countif($E17:$AI17,AK$3) -> 1 | AL17: =countif($E17:$AI17,AL$3) -> 0 | AM17: =AJ17 + AK17 +(AL17 / 2) -> 30
A18: =B18&C18&D18 -> MujeemHelperIndian | B18: Mujeem | C18: Helper | D18: Indian | E18: Present | F18: Present | G18: Present | H18: Present | I18: Off | J18: Present | K18: Present | L18: Present | M18: Present | N18: Off | O18: Present | P18: Present | Q18: Present | R18: Present | S18: Present | T18: Present | U18: Present | V18: Present | W18: Present | X18: Present | Y18: Present | Z18: Present | AA18: Present | AB18: Present | AC18: Off | AD18: Present | AE18: Present | AF18: Present | AG18: Present | AH18: Present | AJ18: =if(countif($E18:$AI18,AJ$3)>day(EOMONTH($T$2,0)),"Error",countif($E18:$AI18,AJ$3)) -> 27 | AK18: =countif($E18:$AI18,AK$3) -> 3 | AL18: =countif($E18:$AI18,AL$3) -> 0 | AM18: =AJ18 + AK18 +(AL18 / 2) -> 30
A19: =B19&C19&D19 -> SameerBillerService | B19: Sameer | C19: Biller | D19: Service | E19: Present | F19: Present | G19: Present | H19: Present | I19: Present | J19: Off | K19: Present | L19: Present | M19: Present | N19: Present | O19: Present | P19: Present | Q19: Present | R19: Present | S19: Present | T19: Present | U19: Present | V19: Present | W19: Present | X19: Off | Y19: Present | Z19: Present | AA19: Present | AB19: Present | AC19: Present | AD19: Present | AE19: Present | AF19: Present | AG19: Off | AH19: Present | AJ19: =if(countif($E19:$AI19,AJ$3)>day(EOMONTH($T$2,0)),"Error",countif($E19:$AI19,AJ$3)) -> 27 | AK19: =countif($E19:$AI19,AK$3) -> 3 | AL19: =countif($E19:$AI19,AL$3) -> 0 | AM19: =AJ19 + AK19 +(AL19 / 2) -> 30
A20: =B20&C20&D20 -> DanishCombiIndian | B20: Danish | C20: Combi | D20: Indian | AA20: Present | AB20: Present | AC20: Present | AD20: Present | AE20: Present | AF20: Present | AG20: Present | AH20: Present | AJ20: =if(countif($E20:$AI20,AJ$3)>day(EOMONTH($T$2,0)),"Error",countif($E20:$AI20,AJ$3)) -> 8 | AK20: =countif($E20:$AI20,AK$3) -> 0 | AL20: =countif($E20:$AI20,AL$3) -> 0 | AM20: =AJ20 + AK20 +(AL20 / 2) -> 8
A21: =B21&C21&D21 -> IrfanChefChinese | B21: Irfan | C21: Chef | D21: Chinese | AC21: Half Day | AD21: Present | AE21: Present | AF21: Present | AG21: Present | AH21: Present | AJ21: =if(countif($E21:$AI21,AJ$3)>day(EOMONTH($T$2,0)),"Error",countif($E21:$AI21,AJ$3)) -> 5 | AK21: =countif($E21:$AI21,AK$3) -> 0 | AL21: =countif($E21:$AI21,AL$3) -> 1 | AM21: =AJ21 + AK21 +(AL21 / 2) -> 5.5
AJ22: =if(countif($E22:$AI22,AJ$3)>day(EOMONTH($T$2,0)),"Error",countif($E22:$AI22,AJ$3)) -> 0 | AK22: =countif($E22:$AI22,AK$3) -> 0 | AL22: =countif($E22:$AI22,AL$3) -> 0 | AM22: =AJ22 + AK22 +(AL22 / 2) -> 0
AJ23: =if(countif($E23:$AI23,AJ$3)>day(EOMONTH($T$2,0)),"Error",countif($E23:$AI23,AJ$3)) -> 0 | AK23: =countif($E23:$AI23,AK$3) -> 0 | AL23: =countif($E23:$AI23,AL$3) -> 0 | AM23: =AJ23 + AK23 +(AL23 / 2) -> 0
AJ24: =if(countif($E24:$AI24,AJ$3)>day(EOMONTH($T$2,0)),"Error",countif($E24:$AI24,AJ$3)) -> 0 | AK24: =countif($E24:$AI24,AK$3) -> 0 | AL24: =countif($E24:$AI24,AL$3) -> 0 | AM24: =AJ24 + AK24 +(AL24 / 2) -> 0
AJ25: =if(countif($E25:$AI25,AJ$3)>day(EOMONTH($T$2,0)),"Error",countif($E25:$AI25,AJ$3)) -> 0 | AK25: =countif($E25:$AI25,AK$3) -> 0 | AL25: =countif($E25:$AI25,AL$3) -> 0 | AM25: =AJ25 + AK25 +(AL25 / 2) -> 0
AJ26: =if(countif($E26:$AI26,AJ$3)>day(EOMONTH($T$2,0)),"Error",countif($E26:$AI26,AJ$3)) -> 0 | AK26: =countif($E26:$AI26,AK$3) -> 0 | AL26: =countif($E26:$AI26,AL$3) -> 0 | AM26: =AJ26 + AK26 +(AL26 / 2) -> 0
AJ27: =if(countif($E27:$AI27,AJ$3)>day(EOMONTH($T$2,0)),"Error",countif($E27:$AI27,AJ$3)) -> 0 | AK27: =countif($E27:$AI27,AK$3) -> 0 | AL27: =countif($E27:$AI27,AL$3) -> 0 | AM27: =AJ27 + AK27 +(AL27 / 2) -> 0
AJ28: =if(countif($E28:$AI28,AJ$3)>day(EOMONTH($T$2,0)),"Error",countif($E28:$AI28,AJ$3)) -> 0 | AK28: =countif($E28:$AI28,AK$3) -> 0 | AL28: =countif($E28:$AI28,AL$3) -> 0 | AM28: =AJ28 + AK28 +(AL28 / 2) -> 0
AJ29: =if(countif($E29:$AI29,AJ$3)>day(EOMONTH($T$2,0)),"Error",countif($E29:$AI29,AJ$3)) -> 0 | AK29: =countif($E29:$AI29,AK$3) -> 0 | AL29: =countif($E29:$AI29,AL$3) -> 0 | AM29: =AJ29 + AK29 +(AL29 / 2) -> 0
AJ30: =if(countif($E30:$AI30,AJ$3)>day(EOMONTH($T$2,0)),"Error",countif($E30:$AI30,AJ$3)) -> 0 | AK30: =countif($E30:$AI30,AK$3) -> 0 | AL30: =countif($E30:$AI30,AL$3) -> 0 | AM30: =AJ30 + AK30 +(AL30 / 2) -> 0
AJ31: =if(countif($E31:$AI31,AJ$3)>day(EOMONTH($T$2,0)),"Error",countif($E31:$AI31,AJ$3)) -> 0 | AK31: =countif($E31:$AI31,AK$3) -> 0 | AL31: =countif($E31:$AI31,AL$3) -> 0 | AM31: =AJ31 + AK31 +(AL31 / 2) -> 0
AJ32: =if(countif($E32:$AI32,AJ$3)>day(EOMONTH($T$2,0)),"Error",countif($E32:$AI32,AJ$3)) -> 0 | AK32: =countif($E32:$AI32,AK$3) -> 0 | AL32: =countif($E32:$AI32,AL$3) -> 0 | AM32: =AJ32 + AK32 +(AL32 / 2) -> 0
AJ33: =if(countif($E33:$AI33,AJ$3)>day(EOMONTH($T$2,0)),"Error",countif($E33:$AI33,AJ$3)) -> 0 | AK33: =countif($E33:$AI33,AK$3) -> 0 | AL33: =countif($E33:$AI33,AL$3) -> 0 | AM33: =AJ33 + AK33 +(AL33 / 2) -> 0
... AJ39: =if(countif($E39:$AI39,AJ$3)>day(EOMONTH($T$2,0)),"Error",countif($E39:$AI39,AJ$3)) -> 0 | AK39: =countif($E39:$AI39,AK$3) -> 0 | AL39: =countif($E39:$AI39,AL$3) -> 0 | AM39: =AJ39 + AK39 +(AL39 / 2) -> 0
AK40: =countif($E40:$Y40,AK$3) -> 0 | AL40: =countif($E40:$Y40,AL$3) -> 0 | AM40: =countif($E40:$Y40,AM$3) -> 0

Sheet Dec-24
D1: =day(EOMONTH(T2,0)) -> 31 | E1: =iferror(concatenate(" Enter ", 'Attendance key'!$B$7, " for ",'Attendance key'!$C$7, ", ", 'Attendance key'!$B$8, " for ", 'Attendance key'!$C$8, ", ", 'Attendance key'!$B$9, " for ", 'Attendance key'!$C$9, ", and ", 'Attendance key'!$B$10, " for ", 'Attendance key'!$C$10, ". Use the 'Attendance key' tab to customise. "),"") -> Enter Present for Present, Off for Leave, Half Day for Half Day, and Left for Attried. Use the 'Attendance key' tab to customise.
B2: Month | E2: 45627 | F2: =IF(MONTH(E2+1)=MONTH(EOMONTH($E$2,0)),E2+1,"") -> 45628 | G2: =IF(MONTH(F2+1)=MONTH(EOMONTH($E$2,0)),F2+1,"") -> 45629 | H2: =IF(MONTH(G2+1)=MONTH(EOMONTH($E$2,0)),G2+1,"") -> 45630 | I2: =IF(MONTH(H2+1)=MONTH(EOMONTH($E$2,0)),H2+1,"") -> 45631 | J2: =IF(MONTH(I2+1)=MONTH(EOMONTH($E$2,0)),I2+1,"") -> 45632 | K2: =IF(MONTH(J2+1)=MONTH(EOMONTH($E$2,0)),J2+1,"") -> 45633 | L2: =IF(MONTH(K2+1)=MONTH(EOMONTH($E$2,0)),K2+1,"") -> 45634 | M2: =IF(MONTH(L2+1)=MONTH(EOMONTH($E$2,0)),L2+1,"") -> 45635 | ... AI2: =IF(MONTH(AH2+1)=MONTH(EOMONTH($E$2,0)),AH2+1,"") -> 45657 | AJ2: ='Attendance key'!$C7 -> Present | AK2: ='Attendance key'!$C8 -> Leave | AL2: ='Attendance key'!$C9 -> Half Day | AM2: Total Payable Days
B3: Name | C3: Role | D3: Department | E3: =E2 -> 45627 | F3: =F2 -> 45628 | G3: =G2 -> 45629 | H3: =H2 -> 45630 | I3: =I2 -> 45631 | J3: =J2 -> 45632 | K3: =K2 -> 45633 | L3: =L2 -> 45634 | ... AI3: =AI2 -> 45657 | AJ3: ='Attendance key'!$B7 -> Present | AK3: ='Attendance key'!$B8 -> Off | AL3: ='Attendance key'!$B9 -> Half Day
A4: =B4&C4&D4 -> AkhilCaptainService | B4: Akhil | C4: Captain | D4: Service | E4: Present | F4: Present | G4: Present | H4: Present | I4: Present | J4: Present | K4: Present | L4: Present | M4: Present | N4: Present | O4: Present | P4: Present | Q4: Present | R4: Present | S4: Present | T4: Present | U4: Present | V4: Present | W4: Present | X4: Present | Y4: Present | Z4: Present | AA4: Present | AB4: Present | AC4: Present | AD4: Present | AE4: Present | AF4: Present | AG4: Present | AH4: Present | AI4: Present | AJ4: =if(countif($E4:$AI4,AJ$3)>day(EOMONTH($T$2,0)),"Error",countif($E4:$AI4,AJ$3)) -> 31 | AK4: =countif($E4:$AI4,AK$3) -> 0 | AL4: =countif($E4:$AI4,AL$3) -> 0 | AM4: =AJ4 + AK4 +(AL4 / 2) -> 31
A5: =B5&C5&D5 -> Laxmi BaiHelperMori | B5: Laxmi Bai | C5: Helper | D5: Mori | E5: Present | F5: Present | G5: Present | H5: Present | I5: Present | J5: Present | K5: Present | L5: Present | M5: Present | N5: Present | O5: Present | P5: Present | Q5: Present | R5: Present | S5: Present | T5: Present | U5: Present | V5: Present | W5: Present | X5: Present | Y5: Present | Z5: Present | AA5: Present | AB5: Present | AC5: Present | AD5: Present | AE5: Present | AF5: Present | AG5: Present | AH5: Present | AI5: Present | AJ5: =if(countif($E5:$AI5,AJ$3)>day(EOMONTH($T$2,0)),"Error",countif($E5:$AI5,AJ$3)) -> 31 | AK5: =countif($E5:$AI5,AK$3) -> 0 | AL5: =countif($E5:$AI5,AL$3) -> 0 | AM5: =AJ5 + AK5 +(AL5 / 2) -> 31
A6: =B6&C6&D6 -> MoleemChefTandoor | B6: Moleem | C6: Chef | D6: Tandoor | E6: Present | F6: Present | G6: Present | H6: Present | I6: Present | J6: Present | K6: Present | L6: Present | M6: Left | N6: Left | O6: Left | P6: Left | Q6: Left | R6: Left | S6: Left | T6: Left | U6: Left | V6: Left | W6: Left | X6: Left | Y6: Left | Z6: Left | AA6: Left | AB6: Left | AC6: Left | AD6: Left | AE6: Left | AF6: Left | AG6: Left | AH6: Left | AI6: Left | AJ6: =if(countif($E6:$AI6,AJ$3)>day(EOMONTH($T$2,0)),"Error",countif($E6:$AI6,AJ$3)) -> 8 | AK6: =countif($E6:$AI6,AK$3) -> 0 | AL6: =countif($E6:$AI6,AL$3) -> 0 | AM6: =AJ6 + AK6 +(AL6 / 2) -> 8
A7: =B7&C7&D7 -> SuhailWaiterService | B7: Suhail | C7: Waiter | D7: Service | E7: Present | F7: Present | G7: Present | H7: Present | I7: Present | J7: Present | K7: Present | L7: Present | M7: Present | N7: Present | O7: Present | P7: Present | Q7: Present | R7: Present | S7: Present | T7: Off | U7: Present | V7: Present | W7: Present | X7: Present | Y7: Present | Z7: Present | AA7: Present | AB7: Off | AC7: Present | AD7: Present | AE7: Present | AF7: Present | AG7: Present | AH7: Present | AI7: Present | AJ7: =if(countif($E7:$AI7,AJ$3)>day(EOMONTH($T$2,0)),"Error",countif($E7:$AI7,AJ$3)) -> 29 | AK7: =countif($E7:$AI7,AK$3) -> 2 | AL7: =countif($E7:$AI7,AL$3) -> 0 | AM7: =AJ7 + AK7 +(AL7 / 2) -> 31
A8: =B8&C8&D8 -> WakilHelperMori | B8: Wakil | C8: Helper | D8: Mori | E8: Present | F8: Present | G8: Present | H8: Present | I8: Present | J8: Present | K8: Present | L8: Present | M8: Present | N8: Present | O8: Present | P8: Present | Q8: Present | R8: Present | S8: Present | T8: Present | U8: Present | V8: Present | W8: Present | X8: Present | Y8: Present | Z8: Present | AA8: Present | AB8: Present | AC8: Present | AD8: Present | AE8: Present | AF8: Present | AG8: Present | AH8: Present | AI8: Present | AJ8: =if(countif($E8:$AI8,AJ$3)>day(EOMONTH($T$2,0)),"Error",countif($E8:$AI8,AJ$3)) -> 31 | AK8: =countif($E8:$AI8,AK$3) -> 0 | AL8: =countif($E8:$AI8,AL$3) -> 0 | AM8: =AJ8 + AK8 +(AL8 / 2) -> 31
A9: =B9&C9&D9 -> VijayChefTandoor | B9: Vijay | C9: Chef | D9: Tandoor | E9: Off | F9: Off | G9: Present | H9: Present | I9: Present | J9: Present | K9: Present | L9: Present | M9: Present | N9: Present | O9: Present | P9: Present | Q9: Present | R9: Present | S9: Present | T9: Present | U9: Present | V9: Present | W9: Present | X9: Present | Y9: Present | Z9: Present | AA9: Present | AB9: Present | AC9: Present | AD9: Present | AE9: Present | AF9: Present | AG9: Present | AH9: Present | AI9: Present | AJ9: =if(countif($E9:$AI9,AJ$3)>day(EOMONTH($T$2,0)),"Error",countif($E9:$AI9,AJ$3)) -> 29 | AK9: =countif($E9:$AI9,AK$3) -> 2 | AL9: =countif($E9:$AI9,AL$3) -> 0 | AM9: =AJ9 + AK9 +(AL9 / 2) -> 31
A10: =B10&C10&D10 -> NaseemSupervisorSupervisor | B10: Naseem | C10: Supervisor | D10: Supervisor | E10: Present | F10: Present | G10: Present | H10: Present | I10: Present | J10: Present | K10: Present | L10: Present | M10: Present | N10: Present | O10: Present | P10: Present | Q10: Present | R10: Present | S10: Present | T10: Present | U10: Present | V10: Present | W10: Present | X10: Present | Y10: Present | Z10: Present | AA10: Present | AB10: Present | AC10: Present | AD10: Present | AE10: Present | AF10: Present | AG10: Present | AH10: Present | AI10: Present | AJ10: =if(countif($E10:$AI10,AJ$3)>day(EOMONTH($T$2,0)),"Error",countif($E10:$AI10,AJ$3)) -> 31 | AK10: =countif($E10:$AI10,AK$3) -> 0 | AL10: =countif($E10:$AI10,AL$3) -> 0 | AM10: =AJ10 + AK10 +(AL10 / 2) -> 31
A11: =B11&C11&D11 -> RajeshCombiTandoor | B11: Rajesh | C11: Combi | D11: Tandoor | E11: Present | F11: Present | G11: Present | H11: Present | I11: Present | J11: Present | K11: Present | L11: Present | M11: Present | N11: Present | O11: Present | P11: Present | Q11: Present | R11: Present | S11: Present | T11: Present | U11: Present | V11: Present | W11: Present | X11: Present | Y11: Present | Z11: Present | AA11: Present | AB11: Present | AC11: Present | AD11: Present | AE11: Present | AF11: Present | AG11: Present | AH11: Present | AI11: Present | AJ11: =if(countif($E11:$AI11,AJ$3)>day(EOMONTH($T$2,0)),"Error",countif($E11:$AI11,AJ$3)) -> 31 | AK11: =countif($E11:$AI11,AK$3) -> 0 | AL11: =countif($E11:$AI11,AL$3) -> 0 | AM11: =AJ11 + AK11 +(AL11 / 2) -> 31
A12: =B12&C12&D12 -> AyubChefTava | B12: Ayub | C12: Chef | D12: Tava | E12: Present | F12: Present | G12: Present | H12: Present | I12: Present | J12: Present | K12: Present | L12: Present | M12: Present | N12: Present | O12: Present | P12: Present | Q12: Present | R12: Present | S12: Present | T12: Present | U12: Present | V12: Present | W12: Present | X12: Present | Y12: Present | Z12: Present | AA12: Present | AB12: Present | AC12: Present | AD12: Present | AE12: Present | AF12: Present | AG12: Present | AH12: Present | AI12: Present | AJ12: =if(countif($E12:$AI12,AJ$3)>day(EOMONTH($T$2,0)),"Error",countif($E12:$AI12,AJ$3)) -> 31 | AK12: =countif($E12:$AI12,AK$3) -> 0 | AL12: =countif($E12:$AI12,AL$3) -> 0 | AM12: =AJ12 + AK12 +(AL12 / 2) -> 31
A13: =B13&C13&D13 -> AasifChefIndian | B13: Aasif | C13: Chef | D13: Indian | E13: Present | F13: Present | G13: Present | H13: Present | I13: Present | J13: Present | K13: Present | L13: Present | M13: Present | N13: Present | O13: Present | P13: Present | Q13: Present | R13: Present | S13: Present | T13: Present | U13: Present | V13: Present | W13: Present | X13: Present | Y13: Present | Z13: Present | AA13: Present | AB13: Present | AC13: Present | AD13: Present | AE13: Present | AF13: Present | AG13: Present | AH13: Present | AI13: Present | AJ13: =if(countif($E13:$AI13,AJ$3)>day(EOMONTH($T$2,0)),"Error",countif($E13:$AI13,AJ$3)) -> 31 | AK13: =countif($E13:$AI13,AK$3) -> 0 | AL13: =countif($E13:$AI13,AL$3) -> 0 | AM13: =AJ13 + AK13 +(AL13 / 2) -> 31
A14: =B14&C14&D14 -> BaitullaCombiIndian | B14: Baitulla | C14: Combi | D14: Indian | E14: Present | F14: Left | G14: Left | H14: Left | I14: Left | J14: Left | K14: Left | L14: Left | M14: Left | N14: Left | O14: Left | P14: Left | Q14: Left | R14: Left | S14: Left | T14: Left | U14: Left | V14: Left | W14: Left | X14: Left | Y14: Left | Z14: Left | AA14: Left | AB14: Left | AC14: Left | AD14: Left | AE14: Left | AF14: Left | AG14: Left | AH14: Left | AI14: Left | AJ14: =if(countif($E14:$AI14,AJ$3)>day(EOMONTH($T$2,0)),"Error",countif($E14:$AI14,AJ$3)) -> 1 | AK14: =countif($E14:$AI14,AK$3) -> 0 | AL14: =countif($E14:$AI14,AL$3) -> 0 | AM14: =AJ14 + AK14 +(AL14 / 2) -> 1
A15: =B15&C15&D15 -> AbdullahCombiChinese | B15: Abdullah | C15: Combi | D15: Chinese | E15: Present | F15: Present | G15: Off | H15: Present | I15: Present | J15: Present | K15: Present | L15: Present | M15: Present | N15: Left | O15: Left | P15: Left | Q15: Left | R15: Left | S15: Left | T15: Left | U15: Left | V15: Left | W15: Left | X15: Left | Y15: Left | Z15: Left | AA15: Left | AB15: Left | AC15: Left | AD15: Left | AE15: Left | AF15: Left | AG15: Left | AH15: Left | AI15: Left | AJ15: =if(countif($E15:$AI15,AJ$3)>day(EOMONTH($T$2,0)),"Error",countif($E15:$AI15,AJ$3)) -> 8 | AK15: =countif($E15:$AI15,AK$3) -> 1 | AL15: =countif($E15:$AI15,AL$3) -> 0 | AM15: =AJ15 + AK15 +(AL15 / 2) -> 9
... A19: =B19&C19&D19 -> IrfanChefChinese | B19: Irfan | C19: Chef | D19: Chinese | E19: Present | F19: Present | G19: Present | H19: Present | I19: Off | J19: Present | K19: Present | L19: Present | M19: Present | N19: Present | O19: Present | P19: Present | Q19: Present | R19: Present | S19: Present | T19: Present | U19: Present | V19: Present | W19: Present | X19: Present | Y19: Present | Z19: Present | AA19: Present | AB19: Off | AC19: Present | AD19: Present | AE19: Present | AF19: Present | AG19: Present | AH19: Present | AI19: Present | AJ19: =if(countif($E19:$AI19,AJ$3)>day(EOMONTH($T$2,0)),"Error",countif($E19:$AI19,AJ$3)) -> 29 | AK19: =countif($E19:$AI19,AK$3) -> 2 | AL19: =countif($E19:$AI19,AL$3) -> 0 | AM19: =AJ19 + AK19 +(AL19 / 2) -> 31
A20: =B20&C20&D20 -> SantoshWaiterService | B20: Santosh | C20: Waiter | D20: Service | Q20: Present | R20: Present | S20: Present | T20: Present | U20: Present | V20: Present | W20: Present | X20: Present | Y20: Present | Z20: Present | AA20: Off | AB20: Present | AC20: Present | AD20: Present | AE20: Present | AF20: Present | AG20: Present | AH20: Present | AI20: Present | AJ20: =if(countif($E20:$AI20,AJ$3)>day(EOMONTH($T$2,0)),"Error",countif($E20:$AI20,AJ$3)) -> 18 | AK20: =countif($E20:$AI20,AK$3) -> 1 | AL20: =countif($E20:$AI20,AL$3) -> 0 | AM20: =AJ20 + AK20 +(AL20 / 2) -> 19
A21: =B21&C21&D21 -> KhenyaHelperMori | B21: Khenya | C21: Helper | D21: Mori | T21: Present | U21: Present | V21: Present | W21: Present | X21: Present | Y21: Present | Z21: Present | AA21: Present | AB21: Present | AC21: Present | AD21: Present | AE21: Present | AF21: Present | AG21: Present | AH21: Present | AI21: Present | AJ21: =if(countif($E21:$AI21,AJ$3)>day(EOMONTH($T$2,0)),"Error",countif($E21:$AI21,AJ$3)) -> 16 | AK21: =countif($E21:$AI21,AK$3) -> 0 | AL21: =countif($E21:$AI21,AL$3) -> 0 | AM21: =AJ21 + AK21 +(AL21 / 2) -> 16
A22: =B22&C22&D22 | AJ22: =if(countif($E22:$AI22,AJ$3)>day(EOMONTH($T$2,0)),"Error",countif($E22:$AI22,AJ$3)) -> 0 | AK22: =countif($E22:$AI22,AK$3) -> 0 | AL22: =countif($E22:$AI22,AL$3) -> 0 | AM22: =AJ22 + AK22 +(AL22 / 2) -> 0
A23: =B23&C23&D23 | AJ23: =if(countif($E23:$AI23,AJ$3)>day(EOMONTH($T$2,0)),"Error",countif($E23:$AI23,AJ$3)) -> 0 | AK23: =countif($E23:$AI23,AK$3) -> 0 | AL23: =countif($E23:$AI23,AL$3) -> 0 | AM23: =AJ23 + AK23 +(AL23 / 2) -> 0
A24: =B24&C24&D24 | AJ24: =if(countif($E24:$AI24,AJ$3)>day(EOMONTH($T$2,0)),"Error",countif($E24:$AI24,AJ$3)) -> 0 | AK24: =countif($E24:$AI24,AK$3) -> 0 | AL24: =countif($E24:$AI24,AL$3) -> 0 | AM24: =AJ24 + AK24 +(AL24 / 2) -> 0
A25: =B25&C25&D25 | AJ25: =if(countif($E25:$AI25,AJ$3)>day(EOMONTH($T$2,0)),"Error",countif($E25:$AI25,AJ$3)) -> 0 | AK25: =countif($E25:$AI25,AK$3) -> 0 | AL25: =countif($E25:$AI25,AL$3) -> 0 | AM25: =AJ25 + AK25 +(AL25 / 2) -> 0
A26: =B26&C26&D26 | AJ26: =if(countif($E26:$AI26,AJ$3)>day(EOMONTH($T$2,0)),"Error",countif($E26:$AI26,AJ$3)) -> 0 | AK26: =countif($E26:$AI26,AK$3) -> 0 | AL26: =countif($E26:$AI26,AL$3) -> 0 | AM26: =AJ26 + AK26 +(AL26 / 2) -> 0
A27: =B27&C27&D27 | AJ27: =if(countif($E27:$AI27,AJ$3)>day(EOMONTH($T$2,0)),"Error",countif($E27:$AI27,AJ$3)) -> 0 | AK27: =countif($E27:$AI27,AK$3) -> 0 | AL27: =countif($E27:$AI27,AL$3) -> 0 | AM27: =AJ27 + AK27 +(AL27 / 2) -> 0
A28: =B28&C28&D28 | AJ28: =if(countif($E28:$AI28,AJ$3)>day(EOMONTH($T$2,0)),"Error",countif($E28:$AI28,AJ$3)) -> 0 | AK28: =countif($E28:$AI28,AK$3) -> 0 | AL28: =countif($E28:$AI28,AL$3) -> 0 | AM28: =AJ28 + AK28 +(AL28 / 2) -> 0
A29: =B29&C29&D29 | AJ29: =if(countif($E29:$AI29,AJ$3)>day(EOMONTH($T$2,0)),"Error",countif($E29:$AI29,AJ$3)) -> 0 | AK29: =countif($E29:$AI29,AK$3) -> 0 | AL29: =countif($E29:$AI29,AL$3) -> 0 | AM29: =AJ29 + AK29 +(AL29 / 2) -> 0
A30: =B30&C30&D30 | AJ30: =if(countif($E30:$AI30,AJ$3)>day(EOMONTH($T$2,0)),"Error",countif($E30:$AI30,AJ$3)) -> 0 | AK30: =countif($E30:$AI30,AK$3) -> 0 | AL30: =countif($E30:$AI30,AL$3) -> 0 | AM30: =AJ30 + AK30 +(AL30 / 2) -> 0
A31: =B31&C31&D31 | AJ31: =if(countif($E31:$AI31,AJ$3)>day(EOMONTH($T$2,0)),"Error",countif($E31:$AI31,AJ$3)) -> 0 | AK31: =countif($E31:$AI31,AK$3) -> 0 | AL31: =countif($E31:$AI31,AL$3) -> 0 | AM31: =AJ31 + AK31 +(AL31 / 2) -> 0
A32: =B32&C32&D32 | AJ32: =if(countif($E32:$AI32,AJ$3)>day(EOMONTH($T$2,0)),"Error",countif($E32:$AI32,AJ$3)) -> 0 | AK32: =countif($E32:$AI32,AK$3) -> 0 | AL32: =countif($E32:$AI32,AL$3) -> 0 | AM32: =AJ32 + AK32 +(AL32 / 2) -> 0
A33: =B33&C33&D33 | AJ33: =if(countif($E33:$AI33,AJ$3)>day(EOMONTH($T$2,0)),"Error",countif($E33:$AI33,AJ$3)) -> 0 | AK33: =countif($E33:$AI33,AK$3) -> 0 | AL33: =countif($E33:$AI33,AL$3) -> 0 | AM33: =AJ33 + AK33 +(AL33 / 2) -> 0
... A37: =B37&C37&D37 | AJ37: =if(countif($E37:$AI37,AJ$3)>day(EOMONTH($T$2,0)),"Error",countif($E37:$AI37,AJ$3)) -> 0 | AK37: =countif($E37:$AI37,AK$3) -> 0 | AL37: =countif($E37:$AI37,AL$3) -> 0 | AM37: =AJ37 + AK37 +(AL37 / 2) -> 0
A38: =B38&C38&D38 | AK38: =countif($E38:$Y38,AK$3) -> 0 | AL38: =countif($E38:$Y38,AL$3) -> 0 | AM38: =countif($E38:$Y38,AM$3) -> 0
A39: =B39&C39&D39

Sheet Jan-2025
D1: =day(EOMONTH(T2,0)) -> 31 | E1: =iferror(concatenate(" Enter ", 'Attendance key'!$B$7, " for ",'Attendance key'!$C$7, ", ", 'Attendance key'!$B$8, " for ", 'Attendance key'!$C$8, ", ", 'Attendance key'!$B$9, " for ", 'Attendance key'!$C$9, ", and ", 'Attendance key'!$B$10, " for ", 'Attendance key'!$C$10, ". Use the 'Attendance key' tab to customise. "),"") -> Enter Present for Present, Off for Leave, Half Day for Half Day, and Left for Attried. Use the 'Attendance key' tab to customise.
B2: Month | E2: 45658 | F2: =IF(MONTH(E2+1)=MONTH(EOMONTH($E$2,0)),E2+1,"") -> 45659 | G2: =IF(MONTH(F2+1)=MONTH(EOMONTH($E$2,0)),F2+1,"") -> 45660 | H2: =IF(MONTH(G2+1)=MONTH(EOMONTH($E$2,0)),G2+1,"") -> 45661 | I2: =IF(MONTH(H2+1)=MONTH(EOMONTH($E$2,0)),H2+1,"") -> 45662 | J2: =IF(MONTH(I2+1)=MONTH(EOMONTH($E$2,0)),I2+1,"") -> 45663 | K2: =IF(MONTH(J2+1)=MONTH(EOMONTH($E$2,0)),J2+1,"") -> 45664 | L2: =IF(MONTH(K2+1)=MONTH(EOMONTH($E$2,0)),K2+1,"") -> 45665 | M2: =IF(MONTH(L2+1)=MONTH(EOMONTH($E$2,0)),L2+1,"") -> 45666 | ... AI2: =IF(MONTH(AH2+1)=MONTH(EOMONTH($E$2,0)),AH2+1,"") -> 45688 | AJ2: ='Attendance key'!$C7 -> Present | AK2: ='Attendance key'!$C8 -> Leave | AL2: ='Attendance key'!$C9 -> Half Day | AM2: Total Payable Days | AN2: Advance
B3: Name | C3: Role | D3: Department | E3: =E2 -> 45658 | F3: =F2 -> 45659 | G3: =G2 -> 45660 | H3: =H2 -> 45661 | I3: =I2 -> 45662 | J3: =J2 -> 45663 | K3: =K2 -> 45664 | L3: =L2 -> 45665 | ... AI3: =AI2 -> 45688 | AJ3: ='Attendance key'!$B7 -> Present | AK3: ='Attendance key'!$B8 -> Off | AL3: ='Attendance key'!$B9 -> Half Day
A4: =B4&C4&D4 -> AkhilCaptainService | B4: Akhil | C4: Captain | D4: Service | E4: Present | F4: Present | G4: Present | H4: Present | I4: Present | J4: Present | K4: Present | L4: Present | M4: Present | N4: Present | O4: Present | P4: Present | Q4: Present | R4: Present | S4: Present | T4: Present | U4: Present | V4: Present | W4: Present | X4: Present | Y4: Present | Z4: Present | AA4: Left | AB4: Left | AC4: Left | AD4: Left | AE4: Left | AF4: Left | AG4: Left | AH4: Left | AI4: Left | AJ4: =if(countif($E4:$AI4,AJ$3)>day(EOMONTH($T$2,0)),"Error",countif($E4:$AI4,AJ$3)) -> 22 | AK4: =countif($E4:$AF4,AK$3)+(sum(AL4)/2) -> 0 | AL4: =value(countif($E4:$AI4,AL$3)) -> 0 | AM4: =AJ4 + AK4 +(AL4 / 2) -> 22
A5: =B5&C5&D5 -> Laxmi BaiHelperMori | B5: Laxmi Bai | C5: Helper | D5: Mori | E5: Present | F5: Present | G5: Present | H5: Present | I5: Present | J5: Present | K5: Present | L5: Present | M5: Present | N5: Present | O5: Present | P5: Present | Q5: Present | R5: Present | S5: Present | T5: Present | U5: Present | V5: Present | W5: Present | X5: Present | Y5: Present | Z5: Present | AA5: Present | AB5: Present | AC5: Present | AD5: Present | AE5: Present | AF5: Present | AG5: Present | AH5: Present | AI5: Present | AJ5: =if(countif($E5:$AI5,AJ$3)>day(EOMONTH($T$2,0)),"Error",countif($E5:$AI5,AJ$3)) -> 31 | AK5: =countif($E5:$AF5,AK$3)+(sum(AL5)/2) -> 0 | AL5: =countif($E5:$AI5,AL$3) -> 0 | AM5: =AJ5 + AK5 +(AL5 / 2) -> 31 | AN5: 6000
A6: =B6&C6&D6 -> SuhailWaiterService | B6: Suhail | C6: Waiter | D6: Service | E6: Present | F6: Present | G6: Present | H6: Present | I6: Present | J6: Present | K6: Present | L6: Present | M6: Present | N6: Present | O6: Present | P6: Present | Q6: Off | R6: Present | S6: Present | T6: Present | U6: Present | V6: Present | W6: Present | X6: Present | Y6: Off | Z6: Present | AA6: Present | AB6: Present | AC6: Present | AD6: Present | AE6: Present | AF6: Present | AG6: Present | AH6: Present | AI6: Present | AJ6: =if(countif($E6:$AI6,AJ$3)>day(EOMONTH($T$2,0)),"Error",countif($E6:$AI6,AJ$3)) -> 29 | AK6: =countif($E6:$AF6,AK$3)+(sum(AL6)/2) -> 2 | AL6: =countif($E6:$AI6,AL$3) -> 0 | AM6: =AJ6 + AK6 +(AL6 / 2) -> 31
A7: =B7&C7&D7 -> WakilHelperMori | B7: Wakil | C7: Helper | D7: Mori | E7: Present | F7: Present | G7: Present | H7: Present | I7: Present | J7: Present | K7: Present | L7: Present | M7: Off | N7: Present | O7: Present | P7: Present | Q7: Present | R7: Off | S7: Present | T7: Present | U7: Present | V7: Present | W7: Present | X7: Present | Y7: Present | Z7: Present | AA7: Present | AB7: Present | AC7: Present | AD7: Present | AE7: Present | AF7: Present | AG7: Present | AH7: Present | AI7: Present | AJ7: =if(countif($E7:$AI7,AJ$3)>day(EOMONTH($T$2,0)),"Error",countif($E7:$AI7,AJ$3)) -> 29 | AK7: =countif($E7:$AF7,AK$3)+(sum(AL7)/2) -> 2 | AL7: =countif($E7:$AI7,AL$3) -> 0 | AM7: =AJ7 + AK7 +(AL7 / 2) -> 31
A8: =B8&C8&D8 -> VijayChefTandoor | B8: Vijay | C8: Chef | D8: Tandoor | E8: Present | F8: Present | G8: Present | H8: Present | I8: Present | J8: Half Day | K8: Present | L8: Present | M8: Present | N8: Present | O8: Present | P8: Present | Q8: Half Day | R8: Present | S8: Present | T8: Present | U8: Present | V8: Present | W8: Present | X8: Half Day | Y8: Half Day | Z8: Present | AA8: Present | AB8: Present | AC8: Present | AD8: Present | AE8: Present | AF8: Present | AG8: Present | AH8: Present | AI8: Present | AJ8: =if(countif($E8:$AI8,AJ$3)>day(EOMONTH($T$2,0)),"Error",countif($E8:$AI8,AJ$3)) -> 27 | AK8: =countif($E8:$AF8,AK$3)+(sum(AL8)/2) -> 2 | AL8: =countif($E8:$AI8,AL$3) -> 4 | AM8: =AJ8 + AK8 +(AL8 / 2) -> 31
A9: =B9&C9&D9 -> NaseemSupervisorSupervisor | B9: Naseem | C9: Supervisor | D9: Supervisor | E9: Present | F9: Present | G9: Present | H9: Present | I9: Present | J9: Present | K9: Present | L9: Present | M9: Present | N9: Present | O9: Present | P9: Present | Q9: Present | R9: Present | S9: Present | T9: Present | U9: Present | V9: Present | W9: Present | X9: Present | Y9: Present | Z9: Present | AA9: Present | AB9: Present | AC9: Present | AD9: Present | AE9: Present | AF9: Present | AG9: Present | AH9: Present | AI9: Present | AJ9: =if(countif($E9:$AI9,AJ$3)>day(EOMONTH($T$2,0)),"Error",countif($E9:$AI9,AJ$3)) -> 31 | AK9: =countif($E9:$AF9,AK$3)+(sum(AL9)/2) -> 0 | AL9: =countif($E9:$AI9,AL$3) -> 0 | AM9: =AJ9 + AK9 +(AL9 / 2) -> 31
A10: =B10&C10&D10 -> RajeshCombiTandoor | B10: Rajesh | C10: Combi | D10: Tandoor | E10: Present | F10: Present | G10: Present | H10: Present | I10: Present | J10: Off | K10: Present | L10: Present | M10: Present | N10: Present | O10: Present | P10: Present | Q10: Present | R10: Present | S10: Present | T10: Present | U10: Present | V10: Present | W10: Present | X10: Present | Y10: Present | Z10: Present | AA10: Present | AB10: Off | AC10: Present | AD10: Present | AE10: Present | AF10: Present | AG10: Present | AH10: Present | AI10: Present | AJ10: =if(countif($E10:$AI10,AJ$3)>day(EOMONTH($T$2,0)),"Error",countif($E10:$AI10,AJ$3)) -> 29 | AK10: =countif($E10:$AF10,AK$3)+(sum(AL10)/2) -> 2 | AL10: =countif($E10:$AI10,AL$3) -> 0 | AM10: =AJ10 + AK10 +(AL10 / 2) -> 31 | AN10: 7000
A11: =B11&C11&D11 -> AyubChefTava | B11: Ayub | C11: Chef | D11: Tava | E11: Present | F11: Present | G11: Present | H11: Present | I11: Present | J11: Present | K11: Present | L11: Present | M11: Present | N11: Present | O11: Present | P11: Present | Q11: Present | R11: Present | S11: Present | T11: Present | U11: Present | V11: Present | W11: Present | X11: Present | Y11: Present | Z11: Present | AA11: Present | AB11: Present | AC11: Present | AD11: Present | AE11: Present | AF11: Present | AG11: Present | AH11: Present | AI11: Present | AJ11: =if(countif($E11:$AI11,AJ$3)>day(EOMONTH($T$2,0)),"Error",countif($E11:$AI11,AJ$3)) -> 31 | AK11: =countif($E11:$AF11,AK$3)+(sum(AL11)/2) -> 0 | AL11: =countif($E11:$AI11,AL$3) -> 0 | AM11: =AJ11 + AK11 +(AL11 / 2) -> 31 | AN11: 500
A12: =B12&C12&D12 -> AasifChefIndian | B12: Aasif | C12: Chef | D12: Indian | E12: Present | F12: Present | G12: Present | H12: Present | I12: Present | J12: Present | K12: Present | L12: Present | M12: Present | N12: Present | O12: Present | P12: Present | Q12: Present | R12: Present | S12: Present | T12: Present | U12: Present | V12: Present | W12: Present | X12: Present | Y12: Present | Z12: Present | AA12: Present | AB12: Present | AC12: Present | AD12: Present | AE12: Present | AF12: Present | AG12: Present | AH12: Present | AI12: Present | AJ12: =if(countif($E12:$AI12,AJ$3)>day(EOMONTH($T$2,0)),"Error",countif($E12:$AI12,AJ$3)) -> 31 | AK12: =countif($E12:$AF12,AK$3)+(sum(AL12)/2) -> 0 | AL12: =countif($E12:$AI12,AL$3) -> 0 | AM12: =AJ12 + AK12 +(AL12 / 2) -> 31
A13: =B13&C13&D13 -> MujeemHelperIndian | B13: Mujeem | C13: Helper | D13: Indian | E13: Present | F13: Present | G13: Present | H13: Present | I13: Present | J13: Present | K13: Off | L13: Present | M13: Present | N13: Present | O13: Present | P13: Present | Q13: Present | R13: Present | S13: Present | T13: Present | U13: Present | V13: Present | W13: Present | X13: Present | Y13: Off | Z13: Present | AA13: Present | AB13: Present | AC13: Present | AD13: Present | AE13: Present | AF13: Present | AG13: Present | AH13: Present | AI13: Present | AJ13: =if(countif($E13:$AI13,AJ$3)>day(EOMONTH($T$2,0)),"Error",countif($E13:$AI13,AJ$3)) -> 29 | AK13: =countif($E13:$AF13,AK$3)+(sum(AL13)/2) -> 2 | AL13: =countif($E13:$AI13,AL$3) -> 0 | AM13: =AJ13 + AK13 +(AL13 / 2) -> 31 | AN13: 1000
A14: =B14&C14&D14 -> SameerBillerService | B14: Sameer | C14: Biller | D14: Service | E14: Present | F14: Present | G14: Present | H14: Present | I14: Present | J14: Off | K14: Present | L14: Present | M14: Present | N14: Present | O14: Present | P14: Present | Q14: Present | R14: Present | S14: Present | T14: Present | U14: Present | V14: Present | W14: Present | X14: Off | Y14: Present | Z14: Present | AA14: Present | AB14: Present | AC14: Present | AD14: Present | AE14: Present | AF14: Present | AG14: Present | AH14: Present | AI14: Present | AJ14: =if(countif($E14:$AI14,AJ$3)>day(EOMONTH($T$2,0)),"Error",countif($E14:$AI14,AJ$3)) -> 29 | AK14: =countif($E14:$AF14,AK$3)+(sum(AL14)/2) -> 2 | AL14: =countif($E14:$AI14,AL$3) -> 0 | AM14: =AJ14 + AK14 +(AL14 / 2) -> 31 | AN14: 10000
A15: =B15&C15&D15 -> DanishCombiIndian | B15: Danish | C15: Combi | D15: Indian | E15: Present | F15: Present | G15: Present | H15: Present | I15: Present | J15: Present | K15: Present | L15: Present | M15: Present | N15: Present | O15: Present | P15: Present | Q15: Present | R15: Present | S15: Present | T15: Present | U15: Present | V15: Present | W15: Present | X15: Present | Y15: Present | Z15: Present | AA15: Present | AB15: Present | AC15: Present | AD15: Present | AE15: Half Day | AF15: Present | AG15: Present | AH15: Present | AI15: Present | AJ15: =if(countif($E15:$AI15,AJ$3)>day(EOMONTH($T$2,0)),"Error",countif($E15:$AI15,AJ$3)) -> 30 | AK15: =countif($E15:$AF15,AK$3)+(sum(AL15)/2) -> 0.5 | AL15: =countif($E15:$AI15,AL$3) -> 1 | AM15: =AJ15 + AK15 +(AL15 / 2) -> 31 | AN15: 3500
A16: =B16&C16&D16 -> IrfanChefChinese | B16: Irfan | C16: Chef | D16: Chinese | E16: Present | F16: Present | G16: Present | H16: Present | I16: Present | J16: Present | K16: Present | L16: Present | M16: Present | N16: Present | O16: Present | P16: Present | Q16: Present | R16: Present | S16: Present | T16: Present | U16: Present | V16: Present | W16: Present | X16: Off | Y16: Present | Z16: Present | AA16: Present | AB16: Present | AC16: Present | AD16: Present | AE16: Present | AF16: Present | AG16: Present | AH16: Present | AI16: Present | AJ16: =if(countif($E16:$AI16,AJ$3)>day(EOMONTH($T$2,0)),"Error",countif($E16:$AI16,AJ$3)) -> 30 | AK16: =countif($E16:$AF16,AK$3)+(sum(AL16)/2) -> 1 | AL16: =countif($E16:$AI16,AL$3) -> 0 | AM16: =AJ16 + AK16 +(AL16 / 2) -> 31 | AN16: 1000
A17: =B17&C17&D17 -> SantoshWaiterService | B17: Santosh | C17: Waiter | D17: Service | E17: Off | F17: Present | G17: Present | H17: Present | I17: Present | J17: Present | K17: Present | L17: Present | M17: Off | N17: Present | O17: Present | P17: Present | Q17: Present | R17: Present | S17: Present | T17: Present | U17: Present | V17: Present | W17: Off | X17: Off | Y17: Present | Z17: Present | AA17: Present | AB17: Present | AC17: Present | AD17: Present | AE17: Present | AF17: Present | AG17: Present | AH17: Present | AI17: Half Day | AJ17: =if(countif($E17:$AI17,AJ$3)>day(EOMONTH($T$2,0)),"Error",countif($E17:$AI17,AJ$3)) -> 26 | AK17: =countif($E17:$AF17,AK$3)+(sum(AL17)/2) -> 4.5 | AL17: =countif($E17:$AI17,AL$3) -> 1 | AM17: =AJ17 + AK17 +(AL17 / 2) -> 31 | AN17: 5000
A18: =B18&C18&D18 -> KhenyaHelpermori | B18: Khenya | C18: Helper | D18: mori | E18: Present | F18: Present | G18: Present | H18: Present | I18: Present | J18: Present | K18: Present | L18: Present | M18: Present | N18: Present | O18: Present | P18: Present | Q18: Off | R18: Present | S18: Present | T18: Present | U18: Present | V18: Present | W18: Present | X18: Present | Y18: Present | Z18: Off | AA18: Present | AB18: Present | AC18: Present | AD18: Present | AE18: Present | AF18: Present | AG18: Present | AH18: Present | AI18: Present | AJ18: =if(countif($E18:$AI18,AJ$3)>day(EOMONTH($T$2,0)),"Error",countif($E18:$AI18,AJ$3)) -> 29 | AK18: =countif($E18:$AF18,AK$3)+(sum(AL18)/2) -> 2 | AL18: =countif($E18:$AI18,AL$3) -> 0 | AM18: =AJ18 + AK18 +(AL18 / 2) -> 31 | AN18: 200
AJ19: =if(countif($E19:$AI19,AJ$3)>day(EOMONTH($T$2,0)),"Error",countif($E19:$AI19,AJ$3)) -> 0 | AK19: =countif($E19:$AF19,AK$3)+(sum(AL19)/2) -> 0 | AL19: =countif($E19:$AI19,AL$3) -> 0 | AM19: =AJ19 + AK19 +(AL19 / 2) -> 0
AJ20: =if(countif($E20:$AI20,AJ$3)>day(EOMONTH($T$2,0)),"Error",countif($E20:$AI20,AJ$3)) -> 0 | AK20: =countif($E20:$AF20,AK$3)+(sum(AL20)/2) -> 0 | AL20: =countif($E20:$AI20,AL$3) -> 0 | AM20: =AJ20 + AK20 +(AL20 / 2) -> 0
AJ21: =if(countif($E21:$AI21,AJ$3)>day(EOMONTH($T$2,0)),"Error",countif($E21:$AI21,AJ$3)) -> 0 | AK21: =countif($E21:$AF21,AK$3)+(sum(AL21)/2) -> 0 | AL21: =countif($E21:$AI21,AL$3) -> 0 | AM21: =AJ21 + AK21 +(AL21 / 2) -> 0
AJ22: =if(countif($E22:$AI22,AJ$3)>day(EOMONTH($T$2,0)),"Error",countif($E22:$AI22,AJ$3)) -> 0 | AK22: =countif($E22:$AF22,AK$3)+(sum(AL22)/2) -> 0 | AL22: =countif($E22:$AI22,AL$3) -> 0 | AM22: =AJ22 + AK22 +(AL22 / 2) -> 0
AJ23: =if(countif($E23:$AI23,AJ$3)>day(EOMONTH($T$2,0)),"Error",countif($E23:$AI23,AJ$3)) -> 0 | AK23: =countif($E23:$AF23,AK$3)+(sum(AL23)/2) -> 0 | AL23: =countif($E23:$AI23,AL$3) -> 0 | AM23: =AJ23 + AK23 +(AL23 / 2) -> 0
AJ24: =if(countif($E24:$AI24,AJ$3)>day(EOMONTH($T$2,0)),"Error",countif($E24:$AI24,AJ$3)) -> 0 | AK24: =countif($E24:$AF24,AK$3)+(sum(AL24)/2) -> 0 | AL24: =countif($E24:$AI24,AL$3) -> 0 | AM24: =AJ24 + AK24 +(AL24 / 2) -> 0
AJ25: =if(countif($E25:$AI25,AJ$3)>day(EOMONTH($T$2,0)),"Error",countif($E25:$AI25,AJ$3)) -> 0 | AK25: =countif($E25:$AF25,AK$3)+(sum(AL25)/2) -> 0 | AL25: =countif($E25:$AI25,AL$3) -> 0 | AM25: =AJ25 + AK25 +(AL25 / 2) -> 0
AJ26: =if(countif($E26:$AI26,AJ$3)>day(EOMONTH($T$2,0)),"Error",countif($E26:$AI26,AJ$3)) -> 0 | AK26: =countif($E26:$AF26,AK$3)+(sum(AL26)/2) -> 0 | AL26: =countif($E26:$AI26,AL$3) -> 0 | AM26: =AJ26 + AK26 +(AL26 / 2) -> 0
AJ27: =if(countif($E27:$AI27,AJ$3)>day(EOMONTH($T$2,0)),"Error",countif($E27:$AI27,AJ$3)) -> 0 | AK27: =countif($E27:$AF27,AK$3)+(sum(AL27)/2) -> 0 | AL27: =countif($E27:$AI27,AL$3) -> 0 | AM27: =AJ27 + AK27 +(AL27 / 2) -> 0
AJ28: =if(countif($E28:$AI28,AJ$3)>day(EOMONTH($T$2,0)),"Error",countif($E28:$AI28,AJ$3)) -> 0 | AK28: =countif($E28:$AF28,AK$3)+(sum(AL28)/2) -> 0 | AL28: =countif($E28:$AI28,AL$3) -> 0 | AM28: =AJ28 + AK28 +(AL28 / 2) -> 0
AJ29: =if(countif($E29:$AI29,AJ$3)>day(EOMONTH($T$2,0)),"Error",countif($E29:$AI29,AJ$3)) -> 0 | AK29: =countif($E29:$AF29,AK$3)+(sum(AL29)/2) -> 0 | AL29: =countif($E29:$AI29,AL$3) -> 0 | AM29: =AJ29 + AK29 +(AL29 / 2) -> 0
AJ30: =if(countif($E30:$AI30,AJ$3)>day(EOMONTH($T$2,0)),"Error",countif($E30:$AI30,AJ$3)) -> 0 | AK30: =countif($E30:$AF30,AK$3)+(sum(AL30)/2) -> 0 | AL30: =countif($E30:$AI30,AL$3) -> 0 | AM30: =AJ30 + AK30 +(AL30 / 2) -> 0
... AJ34: =if(countif($E34:$AI34,AJ$3)>day(EOMONTH($T$2,0)),"Error",countif($E34:$AI34,AJ$3)) -> 0 | AK34: =countif($E34:$AF34,AK$3)+(sum(AL34)/2) -> 0 | AL34: =countif($E34:$AI34,AL$3) -> 0 | AM34: =AJ34 + AK34 +(AL34 / 2) -> 0
AK35: =countif($E35:$AF35,AK$3)+(sum(AL35)/2) -> 0 | AL35: =countif($E35:$Y35,AL$3) -> 0 | AM35: =countif($E35:$Y35,AM$3) -> 0

Sheet Feb-2025
D1: =day(EOMONTH(T2,0)) -> 28 | E1: =iferror(concatenate(" Enter ", 'Attendance key'!$B$7, " for ",'Attendance key'!$C$7, ", ", 'Attendance key'!$B$8, " for ", 'Attendance key'!$C$8, ", ", 'Attendance key'!$B$9, " for ", 'Attendance key'!$C$9, ", and ", 'Attendance key'!$B$10, " for ", 'Attendance key'!$C$10, ". Use the 'Attendance key' tab to customise. "),"") -> Enter Present for Present, Off for Leave, Half Day for Half Day, and Left for Attried. Use the 'Attendance key' tab to customise.
B2: Month | E2: 45689 | F2: =IF(MONTH(E2+1)=MONTH(EOMONTH($E$2,0)),E2+1,"") -> 45690 | G2: =IF(MONTH(F2+1)=MONTH(EOMONTH($E$2,0)),F2+1,"") -> 45691 | H2: =IF(MONTH(G2+1)=MONTH(EOMONTH($E$2,0)),G2+1,"") -> 45692 | I2: =IF(MONTH(H2+1)=MONTH(EOMONTH($E$2,0)),H2+1,"") -> 45693 | J2: =IF(MONTH(I2+1)=MONTH(EOMONTH($E$2,0)),I2+1,"") -> 45694 | K2: =IF(MONTH(J2+1)=MONTH(EOMONTH($E$2,0)),J2+1,"") -> 45695 | L2: =IF(MONTH(K2+1)=MONTH(EOMONTH($E$2,0)),K2+1,"") -> 45696 | M2: =IF(MONTH(L2+1)=MONTH(EOMONTH($E$2,0)),L2+1,"") -> 45697 | ... AI2: =IF(MONTH(AH2+1)=MONTH(EOMONTH($E$2,0)),AH2+1,"") | AJ2: ='Attendance key'!$C7 -> Present | AK2: ='Attendance key'!$C8 -> Leave | AL2: ='Attendance key'!$C9 -> Half Day | AM2: Total Payable Days | AN2: =sum(AN4:AN35) -> 21600
B3: Name | C3: Role | D3: Department | E3: =E2 -> 45689 | F3: =F2 -> 45690 | G3: =G2 -> 45691 | H3: =H2 -> 45692 | I3: =I2 -> 45693 | J3: =J2 -> 45694 | K3: =K2 -> 45695 | L3: =L2 -> 45696 | ... AI3: =AI2 | AJ3: ='Attendance key'!$B7 -> Present | AK3: ='Attendance key'!$B8 -> Off | AL3: ='Attendance key'!$B9 -> Half Day | AN3: Ad.Payment | AO3: LWD
A4: =B4&C4&D4 -> AkhilCaptainService | B4: Akhil | C4: Captain | D4: Service | E4: Left | F4: Left | G4: Left | H4: Left | I4: Left | J4: Left | K4: Left | L4: Left | M4: Left | N4: Left | O4: Left | P4: Left | Q4: Left | R4: Left | S4: Left | T4: Left | U4: Left | V4: Left | W4: Left | X4: Left | Y4: Left | Z4: Left | AA4: Left | AB4: Left | AC4: Left | AD4: Left | AE4: Left | AF4: Present | AJ4: =if(countif($E4:$AF4,AJ$3)>day(EOMONTH($T$2,0)),"Error",countif($E4:$AF4,AJ$3)) -> 1 | AK4: =countif($E4:$AF4,AK$3)+(sum(AL4)/2) -> 0 | AL4: =countif($E4:$AF4,AL$3) -> 0 | AM4: =AJ4 + AK4 +(AL4 / 2) -> 1
A5: =B5&C5&D5 -> Laxmi BaiHelperMori | B5: Laxmi Bai | C5: Helper | D5: Mori | E5: Present | F5: Present | G5: Present | H5: Present | I5: Present | J5: Present | K5: Present | L5: Present | M5: Present | N5: Present | O5: Present | P5: Present | Q5: Present | R5: Present | S5: Present | T5: Present | U5: Present | V5: Off | W5: Present | X5: Present | Y5: Present | Z5: Present | AA5: Present | AB5: Present | AC5: Present | AD5: Off | AE5: Off | AF5: Off | AJ5: =if(countif($E5:$AF5,AJ$3)>day(EOMONTH($T$2,0)),"Error",countif($E5:$AF5,AJ$3)) -> 24 | AK5: =countif($E5:$AF5,AK$3)+(sum(AL5)/2) -> 4 | AL5: =countif($E5:$AF5,AL$3) -> 0 | AM5: =AJ5 + AK5 +(AL5 / 2) -> 28 | AN5: 6000
A6: =B6&C6&D6 -> SuhailWaiterService | B6: Suhail | C6: Waiter | D6: Service | E6: Present | F6: Present | G6: Present | H6: Present | I6: Present | J6: Present | K6: Present | L6: Present | M6: Present | N6: Present | O6: Present | P6: Present | Q6: Present | R6: Present | S6: Present | T6: Present | U6: Present | V6: Present | W6: Present | X6: Present | Y6: Present | Z6: Present | AA6: Present | AB6: Off | AC6: Present | AD6: Present | AE6: Present | AF6: Present | AJ6: =if(countif($E6:$AF6,AJ$3)>day(EOMONTH($T$2,0)),"Error",countif($E6:$AF6,AJ$3)) -> 27 | AK6: =countif($E6:$AF6,AK$3)+(sum(AL6)/2) -> 1 | AL6: =countif($E6:$AF6,AL$3) -> 0 | AM6: =AJ6 + AK6 +(AL6 / 2) -> 28
A7: =B7&C7&D7 -> WakilHelperMori | B7: Wakil | C7: Helper | D7: Mori | E7: Present | F7: Present | G7: Present | H7: Present | I7: Present | J7: Present | K7: Present | L7: Present | M7: Present | N7: Off | O7: Present | P7: Present | Q7: Present | R7: Present | S7: Present | T7: Present | U7: Present | V7: Present | W7: Present | X7: Present | Y7: Present | Z7: Present | AA7: Present | AB7: Present | AC7: Present | AD7: Off | AE7: Present | AF7: Present | AJ7: =if(countif($E7:$AF7,AJ$3)>day(EOMONTH($T$2,0)),"Error",countif($E7:$AF7,AJ$3)) -> 26 | AK7: =countif($E7:$AF7,AK$3)+(sum(AL7)/2) -> 2 | AL7: =countif($E7:$AF7,AL$3) -> 0 | AM7: =AJ7 + AK7 +(AL7 / 2) -> 28
A8: =B8&C8&D8 -> VijayChefTandoor | B8: Vijay | C8: Chef | D8: Tandoor | E8: Present | F8: Present | G8: Half Day | H8: Present | I8: Half Day | J8: Present | K8: Present | L8: Present | M8: Present | N8: Present | O8: Present | P8: Half Day | Q8: Half Day | R8: Present | S8: Present | T8: Present | U8: Present | V8: Present | W8: Present | X8: Present | Y8: Present | Z8: Present | AA8: Present | AB8: Present | AC8: Present | AD8: Off | AE8: Present | AF8: Present | AJ8: =if(countif($E8:$AF8,AJ$3)>day(EOMONTH($T$2,0)),"Error",countif($E8:$AF8,AJ$3)) -> 23 | AK8: =countif($E8:$AF8,AK$3)+(sum(AL8)/2) -> 3 | AL8: =countif($E8:$AF8,AL$3) -> 4 | AM8: =AJ8 + AK8 +(AL8 / 2) -> 28
A9: =B9&C9&D9 -> NaseemSupervisorSupervisor | B9: Naseem | C9: Supervisor | D9: Supervisor | E9: Present | F9: Present | G9: Present | H9: Present | I9: Present | J9: Present | K9: Present | L9: Present | M9: Present | N9: Present | O9: Present | P9: Present | Q9: Present | R9: Present | S9: Present | T9: Present | U9: Present | V9: Present | W9: Present | X9: Present | Y9: Present | Z9: Present | AA9: Present | AB9: Present | AC9: Present | AD9: Off | AE9: Present | AF9: Present | AJ9: =if(countif($E9:$AF9,AJ$3)>day(EOMONTH($T$2,0)),"Error",countif($E9:$AF9,AJ$3)) -> 27 | AK9: =countif($E9:$AF9,AK$3)+(sum(AL9)/2) -> 1 | AL9: =countif($E9:$AF9,AL$3) -> 0 | AM9: =AJ9 + AK9 +(AL9 / 2) -> 28
A10: =B10&C10&D10 -> RajeshCombiTandoor | B10: Rajesh | C10: Combi | D10: Tandoor | E10: Present | F10: Present | G10: Present | H10: Present | I10: Present | J10: Present | K10: Present | L10: Present | M10: Present | N10: Off | O10: Off | P10: Present | Q10: Present | R10: Present | S10: Present | T10: Present | U10: Present | V10: Present | W10: Present | X10: Present | Y10: Present | Z10: Present | AA10: Present | AB10: Present | AC10: Present | AD10: Off | AE10: Present | AF10: Present | AJ10: =if(countif($E10:$AF10,AJ$3)>day(EOMONTH($T$2,0)),"Error",countif($E10:$AF10,AJ$3)) -> 25 | AK10: =countif($E10:$AF10,AK$3)+(sum(AL10)/2) -> 3 | AL10: =countif($E10:$AF10,AL$3) -> 0 | AM10: =AJ10 + AK10 +(AL10 / 2) -> 28 | AN10: 6000
A11: =B11&C11&D11 -> AyubChefTava | B11: Ayub | C11: Chef | D11: Tava | E11: Present | F11: Present | G11: Present | H11: Present | I11: Present | J11: Present | K11: Present | L11: Present | M11: Present | N11: Present | O11: Present | P11: Present | Q11: Present | R11: Present | S11: Present | T11: Present | U11: Present | V11: Present | W11: Present | X11: Present | Y11: Present | Z11: Present | AA11: Present | AB11: Present | AC11: Present | AD11: Off | AE11: Present | AF11: Present | AJ11: =if(countif($E11:$AF11,AJ$3)>day(EOMONTH($T$2,0)),"Error",countif($E11:$AF11,AJ$3)) -> 27 | AK11: =countif($E11:$AF11,AK$3)+(sum(AL11)/2) -> 1 | AL11: =countif($E11:$AF11,AL$3) -> 0 | AM11: =AJ11 + AK11 +(AL11 / 2) -> 28 | AN11: 1000
A12: =B12&C12&D12 -> AasifChefIndian | B12: Aasif | C12: Chef | D12: Indian | E12: Present | F12: Present | G12: Present | H12: Present | I12: Present | J12: Present | K12: Present | L12: Present | M12: Present | N12: Present | O12: Present | P12: Present | Q12: Present | R12: Present | S12: Present | T12: Present | U12: Present | V12: Present | W12: Present | X12: Present | Y12: Present | Z12: Present | AA12: Present | AB12: Present | AC12: Present | AD12: Off | AE12: Present | AF12: Present | AJ12: =if(countif($E12:$AF12,AJ$3)>day(EOMONTH($T$2,0)),"Error",countif($E12:$AF12,AJ$3)) -> 27 | AK12: =countif($E12:$AF12,AK$3)+(sum(AL12)/2) -> 1 | AL12: =countif($E12:$AF12,AL$3) -> 0 | AM12: =AJ12 + AK12 +(AL12 / 2) -> 28
A13: =B13&C13&D13 -> MujeemHelperIndian | B13: Mujeem | C13: Helper | D13: Indian | E13: Present | F13: Present | G13: Off | H13: Present | I13: Present | J13: Present | K13: Present | L13: Present | M13: Present | N13: Present | O13: Half Day | P13: Present | Q13: Present | R13: Present | S13: Present | T13: Present | U13: Half Day | V13: Present | W13: Present | X13: Present | Y13: Present | Z13: Present | AA13: Present | AB13: Present | AC13: Present | AD13: Off | AE13: Present | AF13: Present | AJ13: =if(countif($E13:$AF13,AJ$3)>day(EOMONTH($T$2,0)),"Error",countif($E13:$AF13,AJ$3)) -> 24 | AK13: =countif($E13:$AF13,AK$3)+(sum(AL13)/2) -> 3 | AL13: =countif($E13:$AF13,AL$3) -> 2 | AM13: =AJ13 + AK13 +(AL13 / 2) -> 28 | AN13: 500
A14: =B14&C14&D14 -> SameerBillerService | B14: Sameer | C14: Biller | D14: Service | E14: Present | F14: Present | G14: Present | H14: Half Day | I14: Present | J14: Off | K14: Off | L14: Half Day | M14: Off | N14: Off | O14: Off | P14: Off | Q14: Off | R14: Off | S14: Off | T14: Off | U14: Off | V14: Off | W14: Off | X14: Off | Y14: Off | Z14: Off | AA14: Off | AB14: Off | AC14: Off | AD14: Off | AE14: Off | AF14: Off | AJ14: =if(countif($E14:$AF14,AJ$3)>day(EOMONTH($T$2,0)),"Error",countif($E14:$AF14,AJ$3)) -> 4 | AK14: =countif($E14:$AF14,AK$3)+(sum(AL14)/2) -> 23 | AL14: =countif($E14:$AF14,AL$3) -> 2 | AM14: =AJ14 + AK14 +(AL14 / 2) -> 28
A15: =B15&C15&D15 -> DanishCombiIndian | B15: Danish | C15: Combi | D15: Indian | E15: Present | F15: Present | G15: Present | H15: Present | I15: Present | J15: Present | K15: Present | L15: Present | M15: Present | N15: Present | O15: Present | P15: Present | Q15: Present | R15: Present | S15: Present | T15: Present | U15: Present | V15: Present | W15: Present | X15: Present | Y15: Present | Z15: Present | AA15: Present | AB15: Half Day | AC15: Present | AD15: Off | AE15: Present | AF15: Present | AJ15: =if(countif($E15:$AF15,AJ$3)>day(EOMONTH($T$2,0)),"Error",countif($E15:$AF15,AJ$3)) -> 26 | AK15: =countif($E15:$AF15,AK$3)+(sum(AL15)/2) -> 1.5 | AL15: =countif($E15:$AF15,AL$3) -> 1 | AM15: =AJ15 + AK15 +(AL15 / 2) -> 28
A16: =B16&C16&D16 -> IrfanChefChinese | B16: Irfan | C16: Chef | D16: Chinese | E16: Present | F16: Present | G16: Present | H16: Present | I16: Present | J16: Present | K16: Present | L16: Present | M16: Present | N16: Present | O16: Present | P16: Present | Q16: Present | R16: Present | S16: Present | T16: Present | U16: Present | V16: Present | W16: Present | X16: Present | Y16: Present | Z16: Present | AA16: Present | AB16: Present | AC16: Present | AD16: Off | AE16: Off | AF16: Present | AJ16: =if(countif($E16:$AF16,AJ$3)>day(EOMONTH($T$2,0)),"Error",countif($E16:$AF16,AJ$3)) -> 26 | AK16: =countif($E16:$AF16,AK$3)+(sum(AL16)/2) -> 2 | AL16: =countif($E16:$AF16,AL$3) -> 0 | AM16: =AJ16 + AK16 +(AL16 / 2) -> 28
