Workbook

Sheet Dashboard
A1: Billing Dashboard
A3: Total Mismatches Found: | B3: =COUNTA(Discrepancies!A2:A1000) -> 0

Sheet Bill Entry
A1: Date | B1: BillNo | C1: Item | D1: QtyReceived | E1: QtyDamaged | F1: VendorRate | G1: VendorAmount | H1: NetQty | I1: EffectiveRate | J1: ExpectedAmount | K1: VarianceAmt | L1: VariancePct | M1: Status

Sheet Discrepancies
A1: Row | B1: Date | C1: BillNo | D1: Item | E1: NetQty | F1: EffectiveRate | G1: ExpectedAmount | H1: VendorRate | I1: VendorAmount | J1: VarianceAmt | K1: VariancePct | L1: Status

Sheet PriceHistory
A1: Date | B1: Tandoori Paper Rate | C1: Boiler Paper Rate | D1: Egg Paper Rate | F1: Tandoori Effective Rate | G1: Spl Leg Effective Rate | H1: Boneless Effective Rate | I1: Full Leg Effective Rate | J1: Wings Effective Rate | K1: Dressing Tandoori Effective Rate | L1: Boiler Effective Rate | M1: Egg Effective Rate
A2: 45878 | B2: 124 | C2: 105 | D2: 495 | F2: 144 | G2: 149 | H2: 200 | I2: 125 | J2: 130 | K2: 174 | L2: 125 | M2: 495

Sheet Raw Data
D7: Date | E7: Tandoor | F7: Boiler | G7: Egg | J7: 138
D8: 45564 | E8: 131 | F8: 118 | G8: 580 | J8: =J7-'Raw Data'!$F8 -> 20
D9: =D8+1 -> 45565 | E9: 131 | F9: 118 | G9: 580
D10: =D9+1 -> 45566 | E10: 131 | F10: 118 | G10: 580
D11: =D10+1 -> 45567 | E11: 131 | F11: 116 | G11: 580
D12: =D11+1 -> 45568 | E12: 131 | F12: 116 | G12: 580
D13: =D12+1 -> 45569 | E13: 131 | F13: 116 | G13: 560
D14: =D13+1 -> 45570 | E14: 131 | F14: 118 | G14: 560
D15: =D14+1 -> 45571 | E15: 133 | F15: 118 | G15: 560
D16: =D15+1 -> 45572 | E16: 133 | F16: 118 | G16: 560
D17: =D16+1 -> 45573 | E17: 133 | F17: 118 | G17: 560
D18: =D17+1 -> 45574 | E18: 131 | F18: 114 | G18: 560
D19: =D18+1 -> 45575 | E19: 131 | F19: 110 | G19: 560
D20: =D19+1 -> 45576 | E20: 131 | F20: 110 | G20: 560
... D160: =D159+1 -> 45716 | E160: 122 | F160: 105 | G160: 510
D161: =D160+1 -> 45717 | E161: 124 | F161: 110
D162: =D161+1 -> 45718 | E162: 128 | F162: 113 | G162: 510
D163: =D162+1 -> 45719 | E163: 130 | F163: 113 | G163: 490
D164: =D163+1 -> 45720 | E164: 130 | F164: 113 | G164: 480
D165: =D164+1 -> 45721 | E165: 128 | F165: 113
D166: =D165+1 -> 45722 | E166: 126 | F166: 105
D167: =D166+1 -> 45723 | E167: 124 | F167: 100 | G167: 455
D168: =D167+1 -> 45724 | E168: 122 | F168: 90 | G168: 455
D169: =D168+1 -> 45725 | E169: 120 | F169: 90 | G169: 455
D170: =D169+1 -> 45726 | E170: 120 | F170: 90 | G170: 455
D171: =D170+1 -> 45727 | E171: 120 | F171: 90 | G171: 455
D172: =D171+1 -> 45728 | E172: 120 | F172: 90 | G172: 455
D173: =D172+1 -> 45729 | E173: 120 | F173: 95 | G173: 445
D174: =D173+1 -> 45730 | E174: 120 | F174: 107 | G174: 435
D175: =D174+1 -> 45731 | E175: 122 | F175: 112 | G175: 435
D176: =D175+1 -> 45732 | E176: 117 | F176: 124 | G176: 435
D177: =D176+1 -> 45733 | E177: 117 | F177: 124 | G177: 445
D178: =D177+1 -> 45734 | E178: 117 | F178: 124 | G178: 455
... D214: =D213+1 -> 45770 | E214: 126 | F214: 119 | G214: 450
D215: =D214+1 -> 45771 | E215: 126 | F215: 119
D216: =D215+1 -> 45772 | E216: 126 | F216: 119 | G216: 450
D217: =D216+1 -> 45773 | E217: 126 | F217: 121 | G217: 455
D218: =D217+1 -> 45774 | E218: 126 | F218: 123 | G218: 460
D219: =D218+1 -> 45775 | E219: 126 | F219: 123 | G219: 465
D220: =D219+1 -> 45776 | E220: 126 | F220: 123 | G220: 470
...

Sheet Bill
A1: `` | AE1: 3
L2: 20 | M2: 25 | N2: -10 | O2: 20 | P2: 25 | Q2: 50 | R2: 20 | S2: -20
K4: Bill | W4: =SUMIFS(Bill!$W$6:$W$25, Bill!$K$6:$K$25, ">=" & TODAY()-30, Bill!$K$6:$K$25, "<=" & TODAY()) -> 0 | Y4: Weight
A5: Date | B5: Tandoori | C5: Spl Leg | D5: Boneless | E5: Full Leg | F5: Wings | G5: Dressing Tandoori | H5: Boiler | I5: Egg | K5: Date | L5: Tandoori | M5: Spl Leg | N5: Boneless | O5: Full Leg | P5: Wings | Q5: Dressing Tandoori | R5: Boiler | S5: Egg | T5: Chicken Bill | U5: Actual Bill | V5: Validate | W5: Difference | Y5: Date | Z5: Dressing Tandoor | AA5: Tandoori | AB5: Spl Leg | AC5: Boneless | AD5: Full Leg | AE5: Wings | AF5: Boiler | AG5: Egg
A6: =Bill!$Y6 -> 45564 | B6: ='Raw Data'!E8+Bill!$L$2 -> 151 | C6: ='Raw Data'!E8+Bill!$M$2 -> 156 | D6: =('Raw Data'!$F8*2)-10 -> 226 | E6: ='Raw Data'!F8+Bill!$O$2 -> 138 | F6: ='Raw Data'!F8+Bill!$P$2 -> 143 | H6: =('Raw Data'!F8+Bill!$R$2) -> 138 | I6: ='Raw Data'!G8/100 -> 5.8 | K6: =Bill!$Y6 -> 45564 | L6: =Bill!$AA6*('Raw Data'!$E8+$L$2) -> 649.3 | M6: =Bill!$AB6*('Raw Data'!$E8+$M$2) -> 1872 | N6: =(('Raw Data'!$F8 * 2)-10)*Bill!$AC6 -> 0 | O6: =('Raw Data'!F8+Bill!$O$2)*Bill!$AD6 -> 0 | P6: =('Raw Data'!F8+Bill!$P$2)*Bill!$AE6 -> 286 | Q6: =Bill!$Z6*('Raw Data'!$E8+$Q$2) -> 0 | R6: =('Raw Data'!F8+Bill!$R$2)*Bill!$AF6 -> 0 | S6: =('Raw Data'!G8/100)*Bill!$AG6 -> 0 | T6: =SUM(Bill!$L6:$R6) -> 2807.3 | U6: 2807 | V6: =IF(ABS(Bill!$T6 - Bill!$U6) > 20, 1, 0) -> 0 | W6: =Bill!$U6-Bill!$T6 -> -0.3 | Y6: ='Raw Data'!D8 -> 45564 | Z6: 0 | AA6: 4.3 | AB6: 12 | AC6: 0 | AD6: 0 | AE6: 2 | AF6: 0 | AG6: 0
A7: =Bill!$Y7 -> 45565 | B7: ='Raw Data'!E9+Bill!$L$2 -> 151 | C7: ='Raw Data'!E9+Bill!$M$2 -> 156 | D7: =('Raw Data'!$F9*2)-10 -> 226 | E7: ='Raw Data'!F9+Bill!$O$2 -> 138 | F7: ='Raw Data'!F9+Bill!$P$2 -> 143 | H7: =('Raw Data'!F9+Bill!$R$2) -> 138 | I7: ='Raw Data'!G9/100 -> 5.8 | K7: =Bill!$Y7 -> 45565 | L7: =Bill!$AA7*('Raw Data'!$E9+$L$2) -> 1072.1 | M7: =Bill!$AB7*('Raw Data'!$E9+$M$2) -> 1248 | N7: =(('Raw Data'!$F9 * 2)-10)*Bill!$AC7 -> 1130 | O7: =('Raw Data'!F9+Bill!$O$2)*Bill!$AD7 -> 151.8 | P7: =('Raw Data'!F9+Bill!$P$2)*Bill!$AE7 -> 286 | Q7: =Bill!$Z7*('Raw Data'!$E9+$Q$2) -> 0 | R7: =('Raw Data'!F9+Bill!$R$2)*Bill!$AF7 -> 0 | S7: =('Raw Data'!G9/100)*Bill!$AG7 -> 0 | T7: =SUM(Bill!$L7:$R7) -> 3887.9 | U7: 3888 | V7: =IF(ABS(Bill!$T7 - Bill!$U7) > 20, 1, 0) -> 0 | W7: =Bill!$U7-Bill!$T7 -> 0.1 | Y7: ='Raw Data'!D9 -> 45565 | Z7: 0 | AA7: 7.1 | AB7: 8 | AC7: 5 | AD7: 1.1 | AE7: 2 | AF7: 0 | AG7: 0
A8: =Bill!$Y8 -> 45566 | B8: ='Raw Data'!E10+Bill!$L$2 -> 151 | C8: ='Raw Data'!E10+Bill!$M$2 -> 156 | D8: =('Raw Data'!$F10*2)-10 -> 226 | E8: ='Raw Data'!F10+Bill!$O$2 -> 138 | F8: ='Raw Data'!F10+Bill!$P$2 -> 143 | H8: =('Raw Data'!F10+Bill!$R$2) -> 138 | I8: ='Raw Data'!G10/100 -> 5.8 | K8: =Bill!$Y8 -> 45566 | L8: =Bill!$AA8*('Raw Data'!$E10+$L$2) -> 875.8 | M8: =Bill!$AB8*('Raw Data'!$E10+$M$2) -> 780 | N8: =(('Raw Data'!$F10 * 2)-10)*Bill!$AC8 -> 678 | O8: =('Raw Data'!F10+Bill!$O$2)*Bill!$AD8 -> 0 | P8: =('Raw Data'!F10+Bill!$P$2)*Bill!$AE8 -> 0 | Q8: =Bill!$Z8*('Raw Data'!$E10+$Q$2) -> 0 | R8: =('Raw Data'!F10+Bill!$R$2)*Bill!$AF8 -> 0 | S8: =('Raw Data'!G10/100)*Bill!$AG8 -> 870 | T8: =SUM(Bill!$L8:$R8) -> 2333.8 | U8: 2363 | V8: =IF(ABS(Bill!$T8 - Bill!$U8) > 20, 1, 0) -> 1 | W8: =Bill!$U8-Bill!$T8 -> 29.2 | Y8: ='Raw Data'!D10 -> 45566 | Z8: 0 | AA8: 5.8 | AB8: 5 | AC8: 3 | AD8: 0 | AE8: 0 | AF8: 0 | AG8: 150
A9: =Bill!$Y9 -> 45567 | B9: ='Raw Data'!E11+Bill!$L$2 -> 151 | C9: ='Raw Data'!E11+Bill!$M$2 -> 156 | D9: =('Raw Data'!$F11*2)-10 -> 222 | E9: ='Raw Data'!F11+Bill!$O$2 -> 136 | F9: ='Raw Data'!F11+Bill!$P$2 -> 141 | H9: =('Raw Data'!F11+Bill!$R$2) -> 136 | I9: ='Raw Data'!G11/100 -> 5.8 | K9: =Bill!$Y9 -> 45567 | L9: =Bill!$AA9*('Raw Data'!$E11+$L$2) -> 1751.6 | M9: =Bill!$AB9*('Raw Data'!$E11+$M$2) -> 2340 | N9: =(('Raw Data'!$F11 * 2)-10)*Bill!$AC9 -> 888 | O9: =('Raw Data'!F11+Bill!$O$2)*Bill!$AD9 -> 272 | P9: =('Raw Data'!F11+Bill!$P$2)*Bill!$AE9 -> 0 | Q9: =Bill!$Z9*('Raw Data'!$E11+$Q$2) -> 0 | R9: =('Raw Data'!F11+Bill!$R$2)*Bill!$AF9 -> 0 | S9: =('Raw Data'!G11/100)*Bill!$AG9 -> 0 | T9: =SUM(Bill!$L9:$R9) -> 5251.6 | U9: 5310 | V9: =IF(ABS(Bill!$T9 - Bill!$U9) > 20, 1, 0) -> 1 | W9: =Bill!$U9-Bill!$T9 -> 58.4 | Y9: ='Raw Data'!D11 -> 45567 | Z9: 0 | AA9: 11.6 | AB9: 15 | AC9: 4 | AD9: 2 | AE9: 0 | AF9: 0 | AG9: 0
A10: =Bill!$Y10 -> 45568 | B10: ='Raw Data'!E12+Bill!$L$2 -> 151 | C10: ='Raw Data'!E12+Bill!$M$2 -> 156 | D10: =('Raw Data'!$F12*2)-10 -> 222 | E10: ='Raw Data'!F12+Bill!$O$2 -> 136 | F10: ='Raw Data'!F12+Bill!$P$2 -> 141 | H10: =('Raw Data'!F12+Bill!$R$2) -> 136 | I10: ='Raw Data'!G12/100 -> 5.8 | K10: =Bill!$Y10 -> 45568 | L10: =Bill!$AA10*('Raw Data'!$E12+$L$2) -> 1298.6 | M10: =Bill!$AB10*('Raw Data'!$E12+$M$2) -> 1700.4 | N10: =(('Raw Data'!$F12 * 2)-10)*Bill!$AC10 -> 888 | O10: =('Raw Data'!F12+Bill!$O$2)*Bill!$AD10 -> 0 | P10: =('Raw Data'!F12+Bill!$P$2)*Bill!$AE10 -> 423 | Q10: =Bill!$Z10*('Raw Data'!$E12+$Q$2) -> 0 | R10: =('Raw Data'!F12+Bill!$R$2)*Bill!$AF10 -> 0 | S10: =('Raw Data'!G12/100)*Bill!$AG10 -> 0 | T10: =SUM(Bill!$L10:$R10) -> 4310 | U10: 4213 | V10: =IF(ABS(Bill!$T10 - Bill!$U10) > 20, 1, 0) -> 1 | W10: =Bill!$U10-Bill!$T10 -> -97 | Y10: ='Raw Data'!D12 -> 45568 | Z10: 0 | AA10: 8.6 | AB10: 10.9 | AC10: 4 | AD10: 0 | AE10: 3 | AF10: 0 | AG10: 0
A11: =Bill!$Y11 -> 45569 | B11: ='Raw Data'!E13+Bill!$L$2 -> 151 | C11: ='Raw Data'!E13+Bill!$M$2 -> 156 | D11: =('Raw Data'!$F13*2)-10 -> 222 | E11: ='Raw Data'!F13+Bill!$O$2 -> 136 | F11: ='Raw Data'!F13+Bill!$P$2 -> 141 | H11: =('Raw Data'!F13+Bill!$R$2) -> 136 | I11: ='Raw Data'!G13/100 -> 5.6 | K11: =Bill!$Y11 -> 45569 | L11: =Bill!$AA11*('Raw Data'!$E13+$L$2) -> 906 | M11: =Bill!$AB11*('Raw Data'!$E13+$M$2) -> 0 | N11: =(('Raw Data'!$F13 * 2)-10)*Bill!$AC11 -> 0 | O11: =('Raw Data'!F13+Bill!$O$2)*Bill!$AD11 -> 0 | P11: =('Raw Data'!F13+Bill!$P$2)*Bill!$AE11 -> 282 | Q11: =Bill!$Z11*('Raw Data'!$E13+$Q$2) -> 0 | R11: =('Raw Data'!F13+Bill!$R$2)*Bill!$AF11 -> 0 | S11: =('Raw Data'!G13/100)*Bill!$AG11 -> 840 | T11: =SUM(Bill!$L11:$R11) -> 1188 | U11: 1218 | V11: =IF(ABS(Bill!$T11 - Bill!$U11) > 20, 1, 0) -> 1 | W11: =Bill!$U11-Bill!$T11 -> 30 | Y11: ='Raw Data'!D13 -> 45569 | Z11: 0 | AA11: 6 | AB11: 0 | AC11: 0 | AD11: 0 | AE11: 2 | AF11: 0 | AG11: 150
A12: =Bill!$Y12 -> 45570 | B12: ='Raw Data'!E14+Bill!$L$2 -> 151 | C12: ='Raw Data'!E14+Bill!$M$2 -> 156 | D12: =('Raw Data'!$F14*2)-10 -> 226 | E12: ='Raw Data'!F14+Bill!$O$2 -> 138 | F12: ='Raw Data'!F14+Bill!$P$2 -> 143 | H12: =('Raw Data'!F14+Bill!$R$2) -> 138 | I12: ='Raw Data'!G14/100 -> 5.6 | K12: =Bill!$Y12 -> 45570 | L12: =Bill!$AA12*('Raw Data'!$E14+$L$2) -> 868.25 | M12: =Bill!$AB12*('Raw Data'!$E14+$M$2) -> 491.4 | N12: =(('Raw Data'!$F14 * 2)-10)*Bill!$AC12 -> 1130 | O12: =('Raw Data'!F14+Bill!$O$2)*Bill!$AD12 -> 0 | P12: =('Raw Data'!F14+Bill!$P$2)*Bill!$AE12 -> 0 | Q12: =Bill!$Z12*('Raw Data'!$E14+$Q$2) -> 0 | R12: =('Raw Data'!F14+Bill!$R$2)*Bill!$AF12 -> 0 | S12: =('Raw Data'!G14/100)*Bill!$AG12 -> 0 | T12: =SUM(Bill!$L12:$R12) -> 2489.65 | U12: 2518 | V12: =IF(ABS(Bill!$T12 - Bill!$U12) > 20, 1, 0) -> 1 | W12: =Bill!$U12-Bill!$T12 -> 28.35 | Y12: ='Raw Data'!D14 -> 45570 | Z12: 0 | AA12: 5.75 | AB12: 3.15 | AC12: 5 | AD12: 0 | AE12: 0 | AF12: 0 | AG12: 0
A13: =Bill!$Y13 -> 45571 | B13: ='Raw Data'!E15+Bill!$L$2 -> 153 | C13: ='Raw Data'!E15+Bill!$M$2 -> 158 | D13: =('Raw Data'!$F15*2)-10 -> 226 | E13: ='Raw Data'!F15+Bill!$O$2 -> 138 | F13: ='Raw Data'!F15+Bill!$P$2 -> 143 | H13: =('Raw Data'!F15+Bill!$R$2) -> 138 | I13: ='Raw Data'!G15/100 -> 5.6 | K13: =Bill!$Y13 -> 45571 | L13: =Bill!$AA13*('Raw Data'!$E15+$L$2) -> 1407.6 | M13: =Bill!$AB13*('Raw Data'!$E15+$M$2) -> 1580 | N13: =(('Raw Data'!$F15 * 2)-10)*Bill!$AC13 -> 904 | O13: =('Raw Data'!F15+Bill!$O$2)*Bill!$AD13 -> 0 | P13: =('Raw Data'!F15+Bill!$P$2)*Bill!$AE13 -> 143 | Q13: =Bill!$Z13*('Raw Data'!$E15+$Q$2) -> 0 | R13: =('Raw Data'!F15+Bill!$R$2)*Bill!$AF13 -> 414 | S13: =('Raw Data'!G15/100)*Bill!$AG13 -> 0 | T13: =SUM(Bill!$L13:$R13) -> 4448.6 | U13: 4449 | V13: =IF(ABS(Bill!$T13 - Bill!$U13) > 20, 1, 0) -> 0 | W13: =Bill!$U13-Bill!$T13 -> 0.4 | Y13: ='Raw Data'!D15 -> 45571 | Z13: 0 | AA13: 9.2 | AB13: 10 | AC13: 4 | AD13: 0 | AE13: 1 | AF13: 3 | AG13: 0
A14: =Bill!$Y14 -> 45572 | B14: ='Raw Data'!E16+Bill!$L$2 -> 153 | C14: ='Raw Data'!E16+Bill!$M$2 -> 158 | D14: =('Raw Data'!$F16*2)-10 -> 226 | E14: ='Raw Data'!F16+Bill!$O$2 -> 138 | F14: ='Raw Data'!F16+Bill!$P$2 -> 143 | H14: =('Raw Data'!F16+Bill!$R$2) -> 138 | I14: ='Raw Data'!G16/100 -> 5.6 | K14: =Bill!$Y14 -> 45572 | L14: =Bill!$AA14*('Raw Data'!$E16+$L$2) -> 0 | M14: =Bill!$AB14*('Raw Data'!$E16+$M$2) -> 474 | N14: =(('Raw Data'!$F16 * 2)-10)*Bill!$AC14 -> 452 | O14: =('Raw Data'!F16+Bill!$O$2)*Bill!$AD14 -> 138 | P14: =('Raw Data'!F16+Bill!$P$2)*Bill!$AE14 -> 0 | Q14: =Bill!$Z14*('Raw Data'!$E16+$Q$2) -> 0 | R14: =('Raw Data'!F16+Bill!$R$2)*Bill!$AF14 -> 0 | S14: =('Raw Data'!G16/100)*Bill!$AG14 -> 0 | T14: =SUM(Bill!$L14:$R14) -> 1064 | U14: 1064 | V14: =IF(ABS(Bill!$T14 - Bill!$U14) > 20, 1, 0) -> 0 | W14: =Bill!$U14-Bill!$T14 -> 0 | Y14: ='Raw Data'!D16 -> 45572 | Z14: 0 | AA14: 0 | AB14: 3 | AC14: 2 | AD14: 1 | AE14: 0 | AF14: 0 | AG14: 0
A15: =Bill!$Y15 -> 45573 | B15: ='Raw Data'!E17+Bill!$L$2 -> 153 | C15: ='Raw Data'!E17+Bill!$M$2 -> 158 | D15: =('Raw Data'!$F17*2)-10 -> 226 | E15: ='Raw Data'!F17+Bill!$O$2 -> 138 | F15: ='Raw Data'!F17+Bill!$P$2 -> 143 | H15: =('Raw Data'!F17+Bill!$R$2) -> 138 | I15: ='Raw Data'!G17/100 -> 5.6 | K15: =Bill!$Y15 -> 45573 | L15: =Bill!$AA15*('Raw Data'!$E17+$L$2) -> 856.8 | M15: =Bill!$AB15*('Raw Data'!$E17+$M$2) -> 1264 | N15: =(('Raw Data'!$F17 * 2)-10)*Bill!$AC15 -> 678 | O15: =('Raw Data'!F17+Bill!$O$2)*Bill!$AD15 -> 138 | P15: =('Raw Data'!F17+Bill!$P$2)*Bill!$AE15 -> 0 | Q15: =Bill!$Z15*('Raw Data'!$E17+$Q$2) -> 0 | R15: =('Raw Data'!F17+Bill!$R$2)*Bill!$AF15 -> 0 | S15: =('Raw Data'!G17/100)*Bill!$AG15 -> 0 | T15: =SUM(Bill!$L15:$R15) -> 2936.8 | U15: 2937 | V15: =IF(ABS(Bill!$T15 - Bill!$U15) > 20, 1, 0) -> 0 | W15: =Bill!$U15-Bill!$T15 -> 0.2 | Y15: ='Raw Data'!D17 -> 45573 | Z15: 0 | AA15: 5.6 | AB15: 8 | AC15: 3 | AD15: 1 | AE15: 0 | AF15: 0 | AG15: 0
A16: =Bill!$Y16 -> 45574 | B16: ='Raw Data'!E18+Bill!$L$2 -> 151 | C16: ='Raw Data'!E18+Bill!$M$2 -> 156 | D16: =('Raw Data'!$F18*2)-10 -> 218 | E16: ='Raw Data'!F18+Bill!$O$2 -> 134 | F16: ='Raw Data'!F18+Bill!$P$2 -> 139 | H16: =('Raw Data'!F18+Bill!$R$2) -> 134 | I16: ='Raw Data'!G18/100 -> 5.6 | K16: =Bill!$Y16 -> 45574 | L16: =Bill!$AA16*('Raw Data'!$E18+$L$2) -> 0 | M16: =Bill!$AB16*('Raw Data'!$E18+$M$2) -> 0 | N16: =(('Raw Data'!$F18 * 2)-10)*Bill!$AC16 -> 0 | O16: =('Raw Data'!F18+Bill!$O$2)*Bill!$AD16 -> 0 | P16: =('Raw Data'!F18+Bill!$P$2)*Bill!$AE16 -> 0 | Q16: =Bill!$Z16*('Raw Data'!$E18+$Q$2) -> 0 | R16: =('Raw Data'!F18+Bill!$R$2)*Bill!$AF16 -> 0 | S16: =('Raw Data'!G18/100)*Bill!$AG16 -> 840 | T16: =SUM(Bill!$L16:$R16) -> 0 | U16: 0 | V16: =IF(ABS(Bill!$T16 - Bill!$U16) > 20, 1, 0) -> 0 | W16: =Bill!$U16-Bill!$T16 -> 0 | Y16: ='Raw Data'!D18 -> 45574 | Z16: 0 | AA16: 0 | AB16: 0 | AC16: 0 | AD16: 0 | AE16: 0 | AF16: 0 | AG16: 150
A17: =Bill!$Y17 -> 45575 | B17: ='Raw Data'!E19+Bill!$L$2 -> 151 | C17: ='Raw Data'!E19+Bill!$M$2 -> 156 | D17: =('Raw Data'!$F19*2)-10 -> 210 | E17: ='Raw Data'!F19+Bill!$O$2 -> 130 | F17: ='Raw Data'!F19+Bill!$P$2 -> 135 | H17: =('Raw Data'!F19+Bill!$R$2) -> 130 | I17: ='Raw Data'!G19/100 -> 5.6 | K17: =Bill!$Y17 -> 45575 | L17: =Bill!$AA17*('Raw Data'!$E19+$L$2) -> 1555.3 | M17: =Bill!$AB17*('Raw Data'!$E19+$M$2) -> 780 | N17: =(('Raw Data'!$F19 * 2)-10)*Bill!$AC17 -> 1260 | O17: =('Raw Data'!F19+Bill!$O$2)*Bill!$AD17 -> 260 | P17: =('Raw Data'!F19+Bill!$P$2)*Bill!$AE17 -> 0 | Q17: =Bill!$Z17*('Raw Data'!$E19+$Q$2) -> 0 | R17: =('Raw Data'!F19+Bill!$R$2)*Bill!$AF17 -> 0 | S17: =('Raw Data'!G19/100)*Bill!$AG17 -> 0 | T17: =SUM(Bill!$L17:$R17) -> 3855.3 | U17: 3868 | V17: =IF(ABS(Bill!$T17 - Bill!$U17) > 20, 1, 0) -> 0 | W17: =Bill!$U17-Bill!$T17 -> 12.7 | Y17: ='Raw Data'!D19 -> 45575 | Z17: 0 | AA17: 10.3 | AB17: 5 | AC17: 6 | AD17: 2 | AE17: 0 | AF17: 0 | AG17: 0
... A29: =Bill!$Y29 -> 45587 | B29: ='Raw Data'!E31+Bill!$L$2 -> 162 | C29: ='Raw Data'!E31+Bill!$M$2 -> 167 | D29: =('Raw Data'!$F31*2)-10 -> 250 | E29: ='Raw Data'!F31+Bill!$O$2 -> 150 | F29: ='Raw Data'!F31+Bill!$P$2 -> 155 | H29: =('Raw Data'!F31+Bill!$R$2) -> 150 | I29: ='Raw Data'!G31/100 -> 5.75 | K29: =Bill!$Y29 -> 45587 | L29: =Bill!$AA29*('Raw Data'!$E31+$L$2) -> 1765.8 | M29: =Bill!$AB29*('Raw Data'!$E31+$M$2) -> 2004 | N29: =(('Raw Data'!$F31 * 2)-10)*Bill!$AC29 -> 500 | O29: =('Raw Data'!F31+Bill!$O$2)*Bill!$AD29 -> 150 | P29: =('Raw Data'!F31+Bill!$P$2)*Bill!$AE29 -> 0 | Q29: =Bill!$Z29*('Raw Data'!$E31+$Q$2) -> 0 | R29: =('Raw Data'!F31+Bill!$R$2)*Bill!$AF29 -> 0 | S29: =('Raw Data'!G31/100)*Bill!$AG29 -> 0 | T29: =SUM(Bill!$L29:$R29) -> 4419.8 | U29: 4420 | V29: =IF(ABS(Bill!$T29 - Bill!$U29) > 20, 1, 0) -> 0 | W29: =Bill!$U29-Bill!$T29 -> 0.2 | Y29: ='Raw Data'!D31 -> 45587 | Z29: 0 | AA29: 10.9 | AB29: 12 | AC29: 2 | AD29: 1 | AE29: 0 | AF29: 0 | AG29: 0
A30: =Bill!$Y30 -> 45588 | B30: ='Raw Data'!E32+Bill!$L$2 -> 162 | C30: ='Raw Data'!E32+Bill!$M$2 -> 167 | D30: =('Raw Data'!$F32*2)-10 -> 254 | E30: ='Raw Data'!F32+Bill!$O$2 -> 152 | F30: ='Raw Data'!F32+Bill!$P$2 -> 157 | H30: =('Raw Data'!F32+Bill!$R$2) -> 152 | I30: ='Raw Data'!G32/100 -> 5.8 | K30: =Bill!$Y30 -> 45588 | L30: =Bill!$AA30*('Raw Data'!$E32+$L$2) -> 891 | M30: =Bill!$AB30*('Raw Data'!$E32+$M$2) -> 1336 | N30: =(('Raw Data'!$F32 * 2)-10)*Bill!$AC30 -> 762 | O30: =('Raw Data'!F32+Bill!$O$2)*Bill!$AD30 -> 0 | P30: =('Raw Data'!F32+Bill!$P$2)*Bill!$AE30 -> 157 | Q30: =Bill!$Z30*('Raw Data'!$E32+$Q$2) -> 0 | R30: =('Raw Data'!F32+Bill!$R$2)*Bill!$AF30 -> 0 | S30: =('Raw Data'!G32/100)*Bill!$AG30 -> 0 | T30: =SUM(Bill!$L30:$R30) -> 3146 | U30: 3146 | W30: =Bill!$U30-Bill!$T30 -> 0 | Y30: ='Raw Data'!D32 -> 45588 | Z30: 0 | AA30: 5.5 | AB30: 8 | AC30: 3 | AD30: 0 | AE30: 1 | AF30: 0 | AG30: 0
A31: =Bill!$Y31 -> 45589 | B31: ='Raw Data'!E33+Bill!$L$2 -> 162 | C31: ='Raw Data'!E33+Bill!$M$2 -> 167 | D31: =('Raw Data'!$F33*2)-10 -> 254 | E31: ='Raw Data'!F33+Bill!$O$2 -> 152 | F31: ='Raw Data'!F33+Bill!$P$2 -> 157 | H31: =('Raw Data'!F33+Bill!$R$2) -> 152 | I31: ='Raw Data'!G33/100 -> 5.85 | K31: =Bill!$Y31 -> 45589 | L31: =Bill!$AA31*('Raw Data'!$E33+$L$2) -> 810 | M31: =Bill!$AB31*('Raw Data'!$E33+$M$2) -> 1336 | N31: =(('Raw Data'!$F33 * 2)-10)*Bill!$AC31 -> 1270 | O31: =('Raw Data'!F33+Bill!$O$2)*Bill!$AD31 -> 0 | P31: =('Raw Data'!F33+Bill!$P$2)*Bill!$AE31 -> 314 | Q31: =Bill!$Z31*('Raw Data'!$E33+$Q$2) -> 0 | R31: =('Raw Data'!F33+Bill!$R$2)*Bill!$AF31 -> 0 | S31: =('Raw Data'!G33/100)*Bill!$AG31 -> 526.5 | T31: =SUM(Bill!$L31:$R31) -> 3730 | U31: 3754 | W31: =Bill!$U31-Bill!$T31 -> 24 | Y31: ='Raw Data'!D33 -> 45589 | Z31: 0 | AA31: 5 | AB31: 8 | AC31: 5 | AD31: 0 | AE31: 2 | AF31: 0 | AG31: 90
A32: =Bill!$Y32 -> 45590 | B32: ='Raw Data'!E34+Bill!$L$2 -> 162 | C32: ='Raw Data'!E34+Bill!$M$2 -> 167 | D32: =('Raw Data'!$F34*2)-10 -> 258 | E32: ='Raw Data'!F34+Bill!$O$2 -> 154 | F32: ='Raw Data'!F34+Bill!$P$2 -> 159 | H32: =('Raw Data'!F34+Bill!$R$2) -> 154 | I32: ='Raw Data'!G34/100 -> 5.85 | K32: =Bill!$Y32 -> 45590 | L32: =Bill!$AA32*('Raw Data'!$E34+$L$2) -> 2718.36 | M32: =Bill!$AB32*('Raw Data'!$E34+$M$2) -> 1336 | N32: =(('Raw Data'!$F34 * 2)-10)*Bill!$AC32 -> 1290 | O32: =('Raw Data'!F34+Bill!$O$2)*Bill!$AD32 -> 154 | P32: =('Raw Data'!F34+Bill!$P$2)*Bill!$AE32 -> 0 | Q32: =Bill!$Z32*('Raw Data'!$E34+$Q$2) -> 0 | R32: =('Raw Data'!F34+Bill!$R$2)*Bill!$AF32 -> 0 | S32: =('Raw Data'!G34/100)*Bill!$AG32 -> 0 | T32: =SUM(Bill!$L32:$R32) -> 5498.36 | U32: 5494 | W32: =Bill!$U32-Bill!$T32 -> -4.36 | Y32: ='Raw Data'!D34 -> 45590 | Z32: 0 | AA32: 16.78 | AB32: 8 | AC32: 5 | AD32: 1 | AE32: 0 | AF32: 0 | AG32: 0
A33: =Bill!$Y33 -> 45591 | B33: ='Raw Data'!E35+Bill!$L$2 -> 164 | C33: ='Raw Data'!E35+Bill!$M$2 -> 169 | D33: =('Raw Data'!$F35*2)-10 -> 258 | E33: ='Raw Data'!F35+Bill!$O$2 -> 154 | F33: ='Raw Data'!F35+Bill!$P$2 -> 159 | H33: =('Raw Data'!F35+Bill!$R$2) -> 154 | I33: ='Raw Data'!G35/100 -> 5.85 | K33: =Bill!$Y33 -> 45591 | L33: =Bill!$AA33*('Raw Data'!$E35+$L$2) -> 1968 | M33: =Bill!$AB33*('Raw Data'!$E35+$M$2) -> 2535 | N33: =(('Raw Data'!$F35 * 2)-10)*Bill!$AC33 -> 1032 | O33: =('Raw Data'!F35+Bill!$O$2)*Bill!$AD33 -> 0 | P33: =('Raw Data'!F35+Bill!$P$2)*Bill!$AE33 -> 318 | Q33: =Bill!$Z33*('Raw Data'!$E35+$Q$2) -> 0 | R33: =('Raw Data'!F35+Bill!$R$2)*Bill!$AF33 -> 0 | S33: =('Raw Data'!G35/100)*Bill!$AG33 -> 877.5 | T33: =SUM(Bill!$L33:$R33) -> 5853 | U33: 5853 | W33: =Bill!$U33-Bill!$T33 -> 0 | Y33: ='Raw Data'!D35 -> 45591 | Z33: 0 | AA33: 12 | AB33: 15 | AC33: 4 | AD33: 0 | AE33: 2 | AF33: 0 | AG33: 150
A34: =Bill!$Y34 -> 45592 | B34: ='Raw Data'!E36+Bill!$L$2 -> 166 | C34: ='Raw Data'!E36+Bill!$M$2 -> 171 | D34: =('Raw Data'!$F36*2)-10 -> 262 | E34: ='Raw Data'!F36+Bill!$O$2 -> 156 | F34: ='Raw Data'!F36+Bill!$P$2 -> 161 | H34: =('Raw Data'!F36+Bill!$R$2) -> 156 | I34: ='Raw Data'!G36/100 -> 5.85 | K34: =Bill!$Y34 -> 45592 | L34: =Bill!$AA34*('Raw Data'!$E36+$L$2) -> 1759.6 | M34: =Bill!$AB34*('Raw Data'!$E36+$M$2) -> 855 | N34: =(('Raw Data'!$F36 * 2)-10)*Bill!$AC34 -> 1310 | O34: =('Raw Data'!F36+Bill!$O$2)*Bill!$AD34 -> 312 | P34: =('Raw Data'!F36+Bill!$P$2)*Bill!$AE34 -> 322 | Q34: =Bill!$Z34*('Raw Data'!$E36+$Q$2) -> 0 | R34: =('Raw Data'!F36+Bill!$R$2)*Bill!$AF34 -> 0 | S34: =('Raw Data'!G36/100)*Bill!$AG34 -> 0 | T34: =SUM(Bill!$L34:$R34) -> 4558.6 | U34: 4559 | W34: =Bill!$U34-Bill!$T34 -> 0.4 | Y34: ='Raw Data'!D36 -> 45592 | Z34: 0 | AA34: 10.6 | AB34: 5 | AC34: 5 | AD34: 2 | AE34: 2 | AF34: 0 | AG34: 0
A35: =Bill!$Y35 -> 45593 | B35: ='Raw Data'!E37+Bill!$L$2 -> 168 | C35: ='Raw Data'!E37+Bill!$M$2 -> 173 | D35: =('Raw Data'!$F37*2)-10 -> 262 | E35: ='Raw Data'!F37+Bill!$O$2 -> 156 | F35: ='Raw Data'!F37+Bill!$P$2 -> 161 | H35: =('Raw Data'!F37+Bill!$R$2) -> 156 | I35: ='Raw Data'!G37/100 -> 5.8 | K35: =Bill!$Y35 -> 45593 | L35: =Bill!$AA35*('Raw Data'!$E37+$L$2) -> 0 | M35: =Bill!$AB35*('Raw Data'!$E37+$M$2) -> 865 | N35: =(('Raw Data'!$F37 * 2)-10)*Bill!$AC35 -> 1048 | O35: =('Raw Data'!F37+Bill!$O$2)*Bill!$AD35 -> 0 | P35: =('Raw Data'!F37+Bill!$P$2)*Bill!$AE35 -> 483 | Q35: =Bill!$Z35*('Raw Data'!$E37+$Q$2) -> 0 | R35: =('Raw Data'!F37+Bill!$R$2)*Bill!$AF35 -> 0 | S35: =('Raw Data'!G37/100)*Bill!$AG35 -> 0 | T35: =SUM(Bill!$L35:$R35) -> 2396 | U35: 2393 | W35: =Bill!$U35-Bill!$T35 -> -3 | Y35: ='Raw Data'!D37 -> 45593 | Z35: 0 | AA35: 0 | AB35: 5 | AC35: 4 | AD35: 0 | AE35: 3 | AF35: 0 | AG35: 0
A36: =Bill!$Y36 -> 45594 | B36: ='Raw Data'!E38+Bill!$L$2 -> 168 | C36: ='Raw Data'!E38+Bill!$M$2 -> 173 | D36: =('Raw Data'!$F38*2)-10 -> 262 | E36: ='Raw Data'!F38+Bill!$O$2 -> 156 | F36: ='Raw Data'!F38+Bill!$P$2 -> 161 | H36: =('Raw Data'!F38+Bill!$R$2) -> 156 | I36: ='Raw Data'!G38/100 -> 5.9 | K36: =Bill!$Y36 -> 45594 | L36: =Bill!$AA36*('Raw Data'!$E38+$L$2) -> 823.2 | M36: =Bill!$AB36*('Raw Data'!$E38+$M$2) -> 519 | N36: =(('Raw Data'!$F38 * 2)-10)*Bill!$AC36 -> 786 | O36: =('Raw Data'!F38+Bill!$O$2)*Bill!$AD36 -> 0 | P36: =('Raw Data'!F38+Bill!$P$2)*Bill!$AE36 -> 322 | Q36: =Bill!$Z36*('Raw Data'!$E38+$Q$2) -> 0 | R36: =('Raw Data'!F38+Bill!$R$2)*Bill!$AF36 -> 0 | S36: =('Raw Data'!G38/100)*Bill!$AG36 -> 0 | T36: =SUM(Bill!$L36:$R36) -> 2450.2 | U36: 2128 | W36: =Bill!$U36-Bill!$T36 -> -322.2 | Y36: ='Raw Data'!D38 -> 45594 | Z36: 0 | AA36: 4.9 | AB36: 3 | AC36: 3 | AD36: 0 | AE36: 2 | AF36: 0 | AG36: 0
A37: =Bill!$Y37 -> 45595 | B37: ='Raw Data'!E39+Bill!$L$2 -> 168 | C37: ='Raw Data'!E39+Bill!$M$2 -> 173 | D37: =('Raw Data'!$F39*2)-10 -> 262 | E37: ='Raw Data'!F39+Bill!$O$2 -> 156 | F37: ='Raw Data'!F39+Bill!$P$2 -> 161 | H37: =('Raw Data'!F39+Bill!$R$2) -> 156 | I37: ='Raw Data'!G39/100 -> 5.9 | K37: =Bill!$Y37 -> 45595 | L37: =Bill!$AA37*('Raw Data'!$E39+$L$2) -> 1713.6 | M37: =Bill!$AB37*('Raw Data'!$E39+$M$2) -> 2076 | N37: =(('Raw Data'!$F39 * 2)-10)*Bill!$AC37 -> 1048 | O37: =('Raw Data'!F39+Bill!$O$2)*Bill!$AD37 -> 312 | P37: =('Raw Data'!F39+Bill!$P$2)*Bill!$AE37 -> 322 | Q37: =Bill!$Z37*('Raw Data'!$E39+$Q$2) -> 0 | R37: =('Raw Data'!F39+Bill!$R$2)*Bill!$AF37 -> 0 | S37: =('Raw Data'!G39/100)*Bill!$AG37 -> 885 | T37: =SUM(Bill!$L37:$R37) -> 5471.6 | U37: 5472 | W37: =Bill!$U37-Bill!$T37 -> 0.4 | Y37: ='Raw Data'!D39 -> 45595 | Z37: 0 | AA37: 10.2 | AB37: 12 | AC37: 4 | AD37: 2 | AE37: 2 | AF37: 0 | AG37: 150
A38: =Bill!$Y38 -> 45596 | B38: ='Raw Data'!E40+Bill!$L$2 -> 168 | C38: ='Raw Data'!E40+Bill!$M$2 -> 173 | D38: =('Raw Data'!$F40*2)-10 -> 262 | E38: ='Raw Data'!F40+Bill!$O$2 -> 156 | F38: ='Raw Data'!F40+Bill!$P$2 -> 161 | H38: =('Raw Data'!F40+Bill!$R$2) -> 156 | I38: ='Raw Data'!G40/100 -> 6.06 | K38: =Bill!$Y38 -> 45596 | L38: =Bill!$AA38*('Raw Data'!$E40+$L$2) -> 1512 | M38: =Bill!$AB38*('Raw Data'!$E40+$M$2) -> 2595 | N38: =(('Raw Data'!$F40 * 2)-10)*Bill!$AC38 -> 1048 | O38: =('Raw Data'!F40+Bill!$O$2)*Bill!$AD38 -> 0 | P38: =('Raw Data'!F40+Bill!$P$2)*Bill!$AE38 -> 483 | Q38: =Bill!$Z38*('Raw Data'!$E40+$Q$2) -> 0 | R38: =('Raw Data'!F40+Bill!$R$2)*Bill!$AF38 -> 0 | S38: =('Raw Data'!G40/100)*Bill!$AG38 -> 0 | T38: =SUM(Bill!$L38:$R38) -> 5638 | U38: 5638 | W38: =Bill!$U38-Bill!$T38 -> 0 | Y38: ='Raw Data'!D40 -> 45596 | Z38: 0 | AA38: 9 | AB38: 15 | AC38: 4 | AD38: 0 | AE38: 3 | AF38: 0 | AG38: 0
A39: =Bill!$Y39 -> 45597 | B39: ='Raw Data'!E41+Bill!$L$2 -> 168 | C39: ='Raw Data'!E41+Bill!$M$2 -> 173 | D39: =('Raw Data'!$F41*2)-10 -> 266 | E39: ='Raw Data'!F41+Bill!$O$2 -> 158 | F39: ='Raw Data'!F41+Bill!$P$2 -> 163 | H39: =('Raw Data'!F41+Bill!$R$2) -> 158 | I39: ='Raw Data'!G41/100 -> 6.06 | K39: =Bill!$Y39 -> 45597 | L39: =Bill!$AA39*('Raw Data'!$E41+$L$2) -> 873.6 | M39: =Bill!$AB39*('Raw Data'!$E41+$M$2) -> 1730 | N39: =(('Raw Data'!$F41 * 2)-10)*Bill!$AC39 -> 1330 | O39: =('Raw Data'!F41+Bill!$O$2)*Bill!$AD39 -> 316 | P39: =('Raw Data'!F41+Bill!$P$2)*Bill!$AE39 -> 326 | Q39: =Bill!$Z39*('Raw Data'!$E41+$Q$2) -> 0 | R39: =('Raw Data'!F41+Bill!$R$2)*Bill!$AF39 -> 0 | S39: =('Raw Data'!G41/100)*Bill!$AG39 -> 0 | T39: =SUM(Bill!$L39:$R39) -> 4575.6 | U39: 4592 | W39: =Bill!$U39-Bill!$T39 -> 16.4 | Y39: ='Raw Data'!D41 -> 45597 | Z39: 0 | AA39: 5.2 | AB39: 10 | AC39: 5 | AD39: 2 | AE39: 2 | AF39: 0 | AG39: 0
A40: =Bill!$Y40 -> 45598 | B40: ='Raw Data'!E42+Bill!$L$2 -> 168 | C40: ='Raw Data'!E42+Bill!$M$2 -> 173 | D40: =('Raw Data'!$F42*2)-10 -> 278 | E40: ='Raw Data'!F42+Bill!$O$2 -> 164 | F40: ='Raw Data'!F42+Bill!$P$2 -> 169 | H40: =('Raw Data'!F42+Bill!$R$2) -> 164 | I40: ='Raw Data'!G42/100 -> 6.06 | K40: =Bill!$Y40 -> 45598 | L40: =Bill!$AA40*('Raw Data'!$E42+$L$2) -> 2486.4 | M40: =Bill!$AB40*('Raw Data'!$E42+$M$2) -> 2595 | N40: =(('Raw Data'!$F42 * 2)-10)*Bill!$AC40 -> 1668 | O40: =('Raw Data'!F42+Bill!$O$2)*Bill!$AD40 -> 164 | P40: =('Raw Data'!F42+Bill!$P$2)*Bill!$AE40 -> 338 | Q40: =Bill!$Z40*('Raw Data'!$E42+$Q$2) -> 0 | R40: =('Raw Data'!F42+Bill!$R$2)*Bill!$AF40 -> 0 | S40: =('Raw Data'!G42/100)*Bill!$AG40 -> 909 | T40: =SUM(Bill!$L40:$R40) -> 7251.4 | U40: 7252 | W40: =Bill!$U40-Bill!$T40 -> 0.6 | Y40: ='Raw Data'!D42 -> 45598 | Z40: 0 | AA40: 14.8 | AB40: 15 | AC40: 6 | AD40: 1 | AE40: 2 | AF40: 0 | AG40: 150
A41: =Bill!$Y41 -> 45599 | B41: ='Raw Data'!E43+Bill!$L$2 -> 170 | C41: ='Raw Data'!E43+Bill!$M$2 -> 175 | D41: =('Raw Data'!$F43*2)-10 -> 290 | E41: ='Raw Data'!F43+Bill!$O$2 -> 170 | F41: ='Raw Data'!F43+Bill!$P$2 -> 175 | H41: =('Raw Data'!F43+Bill!$R$2) -> 170 | I41: ='Raw Data'!G43/100 -> 6.06 | K41: =Bill!$Y41 -> 45599 | L41: =Bill!$AA41*('Raw Data'!$E43+$L$2) -> 527 | M41: =Bill!$AB41*('Raw Data'!$E43+$M$2) -> 875 | N41: =(('Raw Data'!$F43 * 2)-10)*Bill!$AC41 -> 870 | O41: =('Raw Data'!F43+Bill!$O$2)*Bill!$AD41 -> 0 | P41: =('Raw Data'!F43+Bill!$P$2)*Bill!$AE41 -> 350 | Q41: =Bill!$Z41*('Raw Data'!$E43+$Q$2) -> 0 | R41: =('Raw Data'!F43+Bill!$R$2)*Bill!$AF41 -> 0 | S41: =('Raw Data'!G43/100)*Bill!$AG41 -> 0 | T41: =SUM(Bill!$L41:$R41) -> 2622 | U41: 2622 | W41: =Bill!$U41-Bill!$T41 -> 0 | Y41: ='Raw Data'!D43 -> 45599 | Z41: 0 | AA41: 3.1 | AB41: 5 | AC41: 3 | AE41: 2 | AF41: 0 | AG41: 0
A42: =Bill!$Y42 -> 45600 | B42: ='Raw Data'!E44+Bill!$L$2 -> 170 | C42: ='Raw Data'!E44+Bill!$M$2 -> 175 | D42: =('Raw Data'!$F44*2)-10 -> 290 | E42: ='Raw Data'!F44+Bill!$O$2 -> 170 | F42: ='Raw Data'!F44+Bill!$P$2 -> 175 | H42: =('Raw Data'!F44+Bill!$R$2) -> 170 | I42: ='Raw Data'!G44/100 -> 6.06 | K42: =Bill!$Y42 -> 45600 | L42: =Bill!$AA42*('Raw Data'!$E44+$L$2) -> 748 | M42: =Bill!$AB42*('Raw Data'!$E44+$M$2) -> 875 | N42: =(('Raw Data'!$F44 * 2)-10)*Bill!$AC42 -> 1740 | O42: =('Raw Data'!F44+Bill!$O$2)*Bill!$AD42 -> 323 | P42: =('Raw Data'!F44+Bill!$P$2)*Bill!$AE42 -> 0 | Q42: =Bill!$Z42*('Raw Data'!$E44+$Q$2) -> 0 | R42: =('Raw Data'!F44+Bill!$R$2)*Bill!$AF42 -> 0 | S42: =('Raw Data'!G44/100)*Bill!$AG42 -> 545.4 | T42: =SUM(Bill!$L42:$R42) -> 3686 | U42: 3686 | W42: =Bill!$U42-Bill!$T42 -> 0 | Y42: ='Raw Data'!D44 -> 45600 | Z42: 0 | AA42: 4.4 | AB42: 5 | AC42: 6 | AD42: 1.9 | AE42: 0 | AF42: 0 | AG42: 90
A43: =Bill!$Y43 -> 45601 | B43: ='Raw Data'!E45+Bill!$L$2 -> 170 | C43: ='Raw Data'!E45+Bill!$M$2 -> 175 | D43: =('Raw Data'!$F45*2)-10 -> 282 | E43: ='Raw Data'!F45+Bill!$O$2 -> 166 | F43: ='Raw Data'!F45+Bill!$P$2 -> 171 | H43: =('Raw Data'!F45+Bill!$R$2) -> 166 | I43: ='Raw Data'!G45/100 -> 6.06 | K43: =Bill!$Y43 -> 45601 | L43: =Bill!$AA43*('Raw Data'!$E45+$L$2) -> 0 | M43: =Bill!$AB43*('Raw Data'!$E45+$M$2) -> 875 | N43: =(('Raw Data'!$F45 * 2)-10)*Bill!$AC43 -> 564 | O43: =('Raw Data'!F45+Bill!$O$2)*Bill!$AD43 -> 0 | P43: =('Raw Data'!F45+Bill!$P$2)*Bill!$AE43 -> 0 | Q43: =Bill!$Z43*('Raw Data'!$E45+$Q$2) -> 0 | R43: =('Raw Data'!F45+Bill!$R$2)*Bill!$AF43 -> 0 | S43: =('Raw Data'!G45/100)*Bill!$AG43 -> 0 | T43: =SUM(Bill!$L43:$R43) -> 1439 | U43: 1439 | W43: =Bill!$U43-Bill!$T43 -> 0 | Y43: ='Raw Data'!D45 -> 45601 | Z43: 0 | AA43: 0 | AB43: 5 | AC43: 2 | AD43: 0 | AE43: 0 | AF43: 0 | AG43: 0
A44: =Bill!$Y44 -> 45602 | B44: ='Raw Data'!E46+Bill!$L$2 -> 170 | C44: ='Raw Data'!E46+Bill!$M$2 -> 175 | D44: =('Raw Data'!$F46*2)-10 -> 272 | E44: ='Raw Data'!F46+Bill!$O$2 -> 161 | F44: ='Raw Data'!F46+Bill!$P$2 -> 166 | H44: =('Raw Data'!F46+Bill!$R$2) -> 161 | I44: ='Raw Data'!G46/100 -> 6.11 | K44: =Bill!$Y44 -> 45602 | L44: =Bill!$AA44*('Raw Data'!$E46+$L$2) -> 1683 | M44: =Bill!$AB44*('Raw Data'!$E46+$M$2) -> 1400 | N44: =(('Raw Data'!$F46 * 2)-10)*Bill!$AC44 -> 1088 | O44: =('Raw Data'!F46+Bill!$O$2)*Bill!$AD44 -> 0 | P44: =('Raw Data'!F46+Bill!$P$2)*Bill!$AE44 -> 0 | Q44: =Bill!$Z44*('Raw Data'!$E46+$Q$2) -> 0 | R44: =('Raw Data'!F46+Bill!$R$2)*Bill!$AF44 -> 0 | S44: =('Raw Data'!G46/100)*Bill!$AG44 -> 916.5 | T44: =SUM(Bill!$L44:$R44) -> 4171 | U44: 4171 | W44: =Bill!$U44-Bill!$T44 -> 0 | Y44: ='Raw Data'!D46 -> 45602 | Z44: 0 | AA44: 9.9 | AB44: 8 | AC44: 4 | AD44: 0 | AE44: 0 | AF44: 0 | AG44: 150
A45: =Bill!$Y45 -> 45603 | B45: ='Raw Data'!E47+Bill!$L$2 -> 168 | C45: ='Raw Data'!E47+Bill!$M$2 -> 173 | D45: =('Raw Data'!$F47*2)-10 -> 272 | E45: ='Raw Data'!F47+Bill!$O$2 -> 161 | F45: ='Raw Data'!F47+Bill!$P$2 -> 166 | H45: =('Raw Data'!F47+Bill!$R$2) -> 161 | I45: ='Raw Data'!G47/100 -> 6.11 | K45: =Bill!$Y45 -> 45603 | L45: =Bill!$AA45*('Raw Data'!$E47+$L$2) -> 1251.6 | M45: =Bill!$AB45*('Raw Data'!$E47+$M$2) -> 1730 | N45: =(('Raw Data'!$F47 * 2)-10)*Bill!$AC45 -> 1360 | O45: =('Raw Data'!F47+Bill!$O$2)*Bill!$AD45 -> 0 | P45: =('Raw Data'!F47+Bill!$P$2)*Bill!$AE45 -> 332 | Q45: =Bill!$Z45*('Raw Data'!$E47+$Q$2) -> 0 | R45: =('Raw Data'!F47+Bill!$R$2)*Bill!$AF45 -> 0 | S45: =('Raw Data'!G47/100)*Bill!$AG45 -> 0 | T45: =SUM(Bill!$L45:$R45) -> 4673.6 | U45: 4673 | W45: =Bill!$U45-Bill!$T45 -> -0.6 | Y45: ='Raw Data'!D47 -> 45603 | Z45: 0 | AA45: 7.45 | AB45: 10 | AC45: 5 | AD45: 0 | AE45: 2 | AF45: 0 | AG45: 0
A46: =Bill!$Y46 -> 45604 | B46: ='Raw Data'!E48+Bill!$L$2 -> 168 | C46: ='Raw Data'!E48+Bill!$M$2 -> 173 | D46: =('Raw Data'!$F48*2)-10 -> 272 | E46: ='Raw Data'!F48+Bill!$O$2 -> 161 | F46: ='Raw Data'!F48+Bill!$P$2 -> 166 | H46: =('Raw Data'!F48+Bill!$R$2) -> 161 | I46: ='Raw Data'!G48/100 -> 6.15 | K46: =Bill!$Y46 -> 45604 | L46: =Bill!$AA46*('Raw Data'!$E48+$L$2) -> 1848 | M46: =Bill!$AB46*('Raw Data'!$E48+$M$2) -> 3460 | N46: =(('Raw Data'!$F48 * 2)-10)*Bill!$AC46 -> 816 | O46: =('Raw Data'!F48+Bill!$O$2)*Bill!$AD46 -> 322 | P46: =('Raw Data'!F48+Bill!$P$2)*Bill!$AE46 -> 0 | Q46: =Bill!$Z46*('Raw Data'!$E48+$Q$2) -> 0 | R46: =('Raw Data'!F48+Bill!$R$2)*Bill!$AF46 -> 0 | S46: =('Raw Data'!G48/100)*Bill!$AG46 -> 0 | T46: =SUM(Bill!$L46:$R46) -> 6446 | U46: 6446 | W46: =Bill!$U46-Bill!$T46 -> 0 | Y46: ='Raw Data'!D48 -> 45604 | Z46: 0 | AA46: 11 | AB46: 20 | AC46: 3 | AD46: 2 | AE46: 0 | AF46: 0 | AG46: 0
A47: =Bill!$Y47 -> 45605 | B47: ='Raw Data'!E49+Bill!$L$2 -> 168 | C47: ='Raw Data'!E49+Bill!$M$2 -> 173 | D47: =('Raw Data'!$F49*2)-10 -> 272 | E47: ='Raw Data'!F49+Bill!$O$2 -> 161 | F47: ='Raw Data'!F49+Bill!$P$2 -> 166 | H47: =('Raw Data'!F49+Bill!$R$2) -> 161 | I47: ='Raw Data'!G49/100 -> 6.15 | K47: =Bill!$Y47 -> 45605 | L47: =Bill!$AA47*('Raw Data'!$E49+$L$2) -> 1562.4 | M47: =Bill!$AB47*('Raw Data'!$E49+$M$2) -> 2595 | N47: =(('Raw Data'!$F49 * 2)-10)*Bill!$AC47 -> 1632 | O47: =('Raw Data'!F49+Bill!$O$2)*Bill!$AD47 -> 0 | P47: =('Raw Data'!F49+Bill!$P$2)*Bill!$AE47 -> 0 | Q47: =Bill!$Z47*('Raw Data'!$E49+$Q$2) -> 0 | R47: =('Raw Data'!F49+Bill!$R$2)*Bill!$AF47 -> 0 | S47: =('Raw Data'!G49/100)*Bill!$AG47 -> 553.5 | T47: =SUM(Bill!$L47:$R47) -> 5789.4 | U47: 5789 | W47: =Bill!$U47-Bill!$T47 -> -0.4 | Y47: ='Raw Data'!D49 -> 45605 | Z47: 0 | AA47: 9.3 | AB47: 15 | AC47: 6 | AD47: 0 | AE47: 0 | AF47: 0 | AG47: 90
A48: =Bill!$Y48 -> 45606 | B48: ='Raw Data'!E50+Bill!$L$2 -> 168 | C48: ='Raw Data'!E50+Bill!$M$2 -> 173 | D48: =('Raw Data'!$F50*2)-10 -> 268 | E48: ='Raw Data'!F50+Bill!$O$2 -> 159 | F48: ='Raw Data'!F50+Bill!$P$2 -> 164 | H48: =('Raw Data'!F50+Bill!$R$2) -> 159 | I48: ='Raw Data'!G50/100 -> 6.15 | K48: =Bill!$Y48 -> 45606 | L48: =Bill!$AA48*('Raw Data'!$E50+$L$2) -> 0 | M48: =Bill!$AB48*('Raw Data'!$E50+$M$2) -> 519 | N48: =(('Raw Data'!$F50 * 2)-10)*Bill!$AC48 -> 2144 | O48: =('Raw Data'!F50+Bill!$O$2)*Bill!$AD48 -> 0 | P48: =('Raw Data'!F50+Bill!$P$2)*Bill!$AE48 -> 328 | Q48: =Bill!$Z48*('Raw Data'!$E50+$Q$2) -> 0 | R48: =('Raw Data'!F50+Bill!$R$2)*Bill!$AF48 -> 564.45 | S48: =('Raw Data'!G50/100)*Bill!$AG48 -> 0 | T48: =SUM(Bill!$L48:$R48) -> 3555.45 | U48: 3587 | W48: =Bill!$U48-Bill!$T48 -> 31.55 | Y48: ='Raw Data'!D50 -> 45606 | Z48: 0 | AA48: 0 | AB48: 3 | AC48: 8 | AE48: 2 | AF48: 3.55 | AG48: 0
A49: =Bill!$Y49 -> 45607 | B49: ='Raw Data'!E51+Bill!$L$2 -> 168 | C49: ='Raw Data'!E51+Bill!$M$2 -> 173 | D49: =('Raw Data'!$F51*2)-10 -> 268 | E49: ='Raw Data'!F51+Bill!$O$2 -> 159 | F49: ='Raw Data'!F51+Bill!$P$2 -> 164 | H49: =('Raw Data'!F51+Bill!$R$2) -> 159 | I49: ='Raw Data'!G51/100 -> 6.15 | K49: =Bill!$Y49 -> 45607 | L49: =Bill!$AA49*('Raw Data'!$E51+$L$2) -> 1848 | M49: =Bill!$AB49*('Raw Data'!$E51+$M$2) -> 3114 | N49: =(('Raw Data'!$F51 * 2)-10)*Bill!$AC49 -> 2144 | O49: =('Raw Data'!F51+Bill!$O$2)*Bill!$AD49 -> 492.9 | P49: =('Raw Data'!F51+Bill!$P$2)*Bill!$AE49 -> 328 | Q49: =Bill!$Z49*('Raw Data'!$E51+$Q$2) -> 0 | R49: =('Raw Data'!F51+Bill!$R$2)*Bill!$AF49 -> 0 | S49: =('Raw Data'!G51/100)*Bill!$AG49 -> 922.5 | T49: =SUM(Bill!$L49:$R49) -> 7926.9 | U49: 7927 | W49: =Bill!$U49-Bill!$T49 -> 0.1 | Y49: ='Raw Data'!D51 -> 45607 | Z49: 0 | AA49: 11 | AB49: 18 | AC49: 8 | AD49: 3.1 | AE49: 2 | AF49: 0 | AG49: 150
A50: =Bill!$Y50 -> 45608 | B50: ='Raw Data'!E52+Bill!$L$2 -> 166 | C50: ='Raw Data'!E52+Bill!$M$2 -> 171 | D50: =('Raw Data'!$F52*2)-10 -> 262 | E50: ='Raw Data'!F52+Bill!$O$2 -> 156 | F50: ='Raw Data'!F52+Bill!$P$2 -> 161 | H50: =('Raw Data'!F52+Bill!$R$2) -> 156 | I50: ='Raw Data'!G52/100 -> 6.15 | K50: =Bill!$Y50 -> 45608 | L50: =Bill!$AA50*('Raw Data'!$E52+$L$2) -> 747 | M50: =Bill!$AB50*('Raw Data'!$E52+$M$2) -> 0 | N50: =(('Raw Data'!$F52 * 2)-10)*Bill!$AC50 -> 1310 | O50: =('Raw Data'!F52+Bill!$O$2)*Bill!$AD50 -> 0 | P50: =('Raw Data'!F52+Bill!$P$2)*Bill!$AE50 -> 483 | Q50: =Bill!$Z50*('Raw Data'!$E52+$Q$2) -> 0 | R50: =('Raw Data'!F52+Bill!$R$2)*Bill!$AF50 -> 0 | S50: =('Raw Data'!G52/100)*Bill!$AG50 -> 0 | T50: =SUM(Bill!$L50:$R50) -> 2540 | U50: 2562 | W50: =Bill!$U50-Bill!$T50 -> 22 | Y50: ='Raw Data'!D52 -> 45608 | Z50: 0 | AA50: 4.5 | AB50: 0 | AC50: 5 | AD50: 0 | AE50: 3 | AF50: 0 | AG50: 0
A51: =Bill!$Y51 -> 45609 | B51: ='Raw Data'!E53+Bill!$L$2 -> 162 | C51: ='Raw Data'!E53+Bill!$M$2 -> 167 | D51: =('Raw Data'!$F53*2)-10 -> 250 | E51: ='Raw Data'!F53+Bill!$O$2 -> 150 | F51: ='Raw Data'!F53+Bill!$P$2 -> 155 | H51: =('Raw Data'!F53+Bill!$R$2) -> 150 | I51: ='Raw Data'!G53/100 -> 6 | K51: =Bill!$Y51 -> 45609 | L51: =Bill!$AA51*('Raw Data'!$E53+$L$2) -> 1684.8 | M51: =Bill!$AB51*('Raw Data'!$E53+$M$2) -> 2004 | N51: =(('Raw Data'!$F53 * 2)-10)*Bill!$AC51 -> 2000 | O51: =('Raw Data'!F53+Bill!$O$2)*Bill!$AD51 -> 0 | P51: =('Raw Data'!F53+Bill!$P$2)*Bill!$AE51 -> 465 | Q51: =Bill!$Z51*('Raw Data'!$E53+$Q$2) -> 0 | R51: =('Raw Data'!F53+Bill!$R$2)*Bill!$AF51 -> 0 | S51: =('Raw Data'!G53/100)*Bill!$AG51 -> 1260 | T51: =SUM(Bill!$L51:$R51) -> 6153.8 | U51: 6153 | W51: =Bill!$U51-Bill!$T51 -> -0.8 | Y51: ='Raw Data'!D53 -> 45609 | Z51: 0 | AA51: 10.4 | AB51: 12 | AC51: 8 | AD51: 0 | AE51: 3 | AF51: 0 | AG51: 210
A52: =Bill!$Y52 -> 45610 | B52: ='Raw Data'!E54+Bill!$L$2 -> 158 | C52: ='Raw Data'!E54+Bill!$M$2 -> 163 | D52: =('Raw Data'!$F54*2)-10 -> 238 | E52: ='Raw Data'!F54+Bill!$O$2 -> 144 | F52: ='Raw Data'!F54+Bill!$P$2 -> 149 | H52: =('Raw Data'!F54+Bill!$R$2) -> 144 | I52: ='Raw Data'!G54/100 -> 6 | K52: =Bill!$Y52 -> 45610 | L52: =Bill!$AA52*('Raw Data'!$E54+$L$2) -> 900.6 | M52: =Bill!$AB52*('Raw Data'!$E54+$M$2) -> 1972.3 | N52: =(('Raw Data'!$F54 * 2)-10)*Bill!$AC52 -> 2380 | O52: =('Raw Data'!F54+Bill!$O$2)*Bill!$AD52 -> 0 | P52: =('Raw Data'!F54+Bill!$P$2)*Bill!$AE52 -> 298 | Q52: =Bill!$Z52*('Raw Data'!$E54+$Q$2) -> 0 | R52: =('Raw Data'!F54+Bill!$R$2)*Bill!$AF52 -> 0 | S52: =('Raw Data'!G54/100)*Bill!$AG52 -> 0 | T52: =SUM(Bill!$L52:$R52) -> 5550.9 | U52: 5551 | W52: =Bill!$U52-Bill!$T52 -> 0.1 | Y52: ='Raw Data'!D54 -> 45610 | Z52: 0 | AA52: 5.7 | AB52: 12.1 | AC52: 10 | AD52: 0 | AE52: 2 | AF52: 0 | AG52: 0
...
