Workbook

Sheet Daily Transactions
A1: Date | B1: Item/Description | C1: Amount | D1: Mode | E1: Remarks/Vendors | F1: Month | G1: Paid/Unpaid | H1: Paid By | I1: Payment Date | J1: Category | K1: ID | L1: Adv Check
A2: 45679 | B2: Electricity | C2: 19470 | D2: Bank | F2: =TEXT(A2,"MM-YYYY") -> 01-2025 | G2: Paid | H2: Sameer | J2: =VLOOKUP(B2,Table3[#All],2,0) -> Fixed Maintance | K2: =TEXT(ROW(), "0000") -> 0002 | M2: Paid
A3: 45679 | B3: Sales | C3: 19422 | D3: Wallet | F3: =TEXT(A3,"MM-YYYY") -> 01-2025 | J3: =VLOOKUP(B3,Table3[#All],2,0) -> Sales | K3: =TEXT(ROW(), "0000") -> 0003 | M3: Unpaid
A4: 45679 | B4: Chicken | C4: 5627 | D4: Bank | E4: Golden | F4: =TEXT(A4,"MM-YYYY") -> 01-2025 | G4: Paid | H4: Sameer | J4: =VLOOKUP(B4,Table3[#All],2,0) -> Inventory | K4: =TEXT(ROW(), "0000") -> 0004
A5: 45679 | B5: Sales | C5: 4759 | D5: Cash | F5: =TEXT(A5,"MM-YYYY") -> 01-2025 | J5: =VLOOKUP(B5,Table3[#All],2,0) -> Sales | K5: =TEXT(ROW(), "0000") -> 0005
A6: 45679 | B6: Grocery | C6: 2801 | D6: Bank | E6: Balaji | F6: =TEXT(A6,"MM-YYYY") -> 01-2025 | G6: Paid | H6: Sameer | J6: =VLOOKUP(B6,Table3[#All],2,0) -> Inventory | K6: =TEXT(ROW(), "0000") -> 0006
A7: 45679 | B7: Sales | C7: 2183 | D7: Online Sale | F7: =TEXT(A7,"MM-YYYY") -> 01-2025 | J7: =VLOOKUP(B7,Table3[#All],2,0) -> Sales | K7: =TEXT(ROW(), "0000") -> 0007
A8: 45679 | B8: Dairy | C8: 1617 | D8: Bank | E8: Adarsh | F8: =TEXT(A8,"MM-YYYY") -> 01-2025 | G8: Paid | H8: Sameer | J8: =VLOOKUP(B8,Table3[#All],2,0) -> Inventory | K8: =TEXT(ROW(), "0000") -> 0008
A9: 45679 | B9: Sales | C9: 1314 | D9: Card | F9: =TEXT(A9,"MM-YYYY") -> 01-2025 | J9: =VLOOKUP(B9,Table3[#All],2,0) -> Sales | K9: =TEXT(ROW(), "0000") -> 0009
A10: 45679 | B10: Dairy | C10: 825 | D10: Cash | E10: Egg | F10: =TEXT(A10,"MM-YYYY") -> 01-2025 | G10: Paid | H10: Sameer | J10: =VLOOKUP(B10,Table3[#All],2,0) -> Inventory | K10: =TEXT(ROW(), "0000") -> 0010
A11: 45679 | B11: Vegetables | C11: 469 | D11: Bank | E11: Gatha | F11: =TEXT(A11,"MM-YYYY") -> 01-2025 | G11: Paid | H11: Sameer | J11: =VLOOKUP(B11,Table3[#All],2,0) -> Inventory | K11: =TEXT(ROW(), "0000") -> 0011
A12: 45679 | B12: Petrol | C12: 400 | D12: Cash | F12: =TEXT(A12,"MM-YYYY") -> 01-2025 | G12: Paid | H12: Sameer | J12: =VLOOKUP(B12,Table3[#All],2,0) -> Bike Maintance | K12: =TEXT(ROW(), "0000") -> 0012
A13: 45679 | B13: Bakery | C13: 325 | D13: Cash | F13: =TEXT(A13,"MM-YYYY") -> 01-2025 | G13: Paid | H13: Sameer | J13: =VLOOKUP(B13,Table3[#All],2,0) -> Grocery | K13: =TEXT(ROW(), "0000") -> 0013
A14: 45679 | B14: Sales | C14: 240 | D14: UPI | F14: =TEXT(A14,"MM-YYYY") -> 01-2025 | J14: =VLOOKUP(B14,Table3[#All],2,0) -> Sales | K14: =TEXT(ROW(), "0000") -> 0014
A15: 45679 | B15: Tea | C15: 129 | D15: Cash | F15: =TEXT(A15,"MM-YYYY") -> 01-2025 | G15: Paid | H15: Sameer | J15: =VLOOKUP(B15,Table3[#All],2,0) -> Staff Expenses | K15: =TEXT(ROW(), "0000") -> 0015
A16: 45679 | B16: Stationary | C16: 100 | D16: Cash | F16: =TEXT(A16,"MM-YYYY") -> 01-2025 | G16: Paid | H16: Sameer | J16: =VLOOKUP(B16,Table3[#All],2,0) -> Inventory | K16: =TEXT(ROW(), "0000") -> 0016
A17: 45679 | B17: Vegetables | C17: 90 | D17: Cash | F17: =TEXT(A17,"MM-YYYY") -> 01-2025 | G17: Paid | H17: Sameer | J17: =VLOOKUP(B17,Table3[#All],2,0) -> Inventory | K17: =TEXT(ROW(), "0000") -> 0017
A18: 45679 | B18: Electric Work | C18: 60 | D18: Cash | F18: =TEXT(A18,"MM-YYYY") -> 01-2025 | G18: Paid | H18: Sameer | J18: =VLOOKUP(B18,Table3[#All],2,0) -> Maintance | K18: =TEXT(ROW(), "0000") -> 0018
A19: 45679 | B19: Dairy | C19: 30 | D19: Cash | F19: =TEXT(A19,"MM-YYYY") -> 01-2025 | G19: Paid | H19: Sameer | J19: =VLOOKUP(B19,Table3[#All],2,0) -> Inventory | K19: =TEXT(ROW(), "0000") -> 0019
A20: 45679 | B20: Kinners | C20: 0 | D20: Cash | F20: =TEXT(A20,"MM-YYYY") -> 01-2025 | G20: Paid | H20: Sameer | J20: =VLOOKUP(B20,Table3[#All],2,0) -> Maintance | K20: =TEXT(ROW(), "0000") -> 0020
A21: 45680 | B21: Sales | C21: 10553 | D21: Wallet | F21: =TEXT(A21,"MM-YYYY") -> 01-2025 | J21: =VLOOKUP(B21,Table3[#All],2,0) -> Sales | K21: =TEXT(ROW(), "0000") -> 0021
A22: 45680 | B22: Chicken | C22: 6577 | D22: Bank | E22: Pita Bread | F22: =TEXT(A22,"MM-YYYY") -> 01-2025 | G22: Paid | H22: Sameer | J22: =VLOOKUP(B22,Table3[#All],2,0) -> Inventory | K22: =TEXT(ROW(), "0000") -> 0022
A23: 45680 | B23: Grocery | C23: 2540 | D23: Bank | F23: =TEXT(A23,"MM-YYYY") -> 01-2025 | G23: Paid | H23: Sameer | J23: =VLOOKUP(B23,Table3[#All],2,0) -> Inventory | K23: =TEXT(ROW(), "0000") -> 0023
A24: 45680 | B24: Sales | C24: 2410 | D24: Cash | F24: =TEXT(A24,"MM-YYYY") -> 01-2025 | J24: =VLOOKUP(B24,Table3[#All],2,0) -> Sales | K24: =TEXT(ROW(), "0000") -> 0024
A25: 45680 | B25: Dairy | C25: 1486 | D25: Bank | E25: Newspaper | F25: =TEXT(A16,"MM-YYYY") -> 01-2025 | G25: Paid | H25: Sameer | J25: =VLOOKUP(B25,Table3[#All],2,0) -> Inventory | K25: =TEXT(ROW(), "0000") -> 0025
A26: 45680 | B26: Mutton | C26: 1480 | D26: Cash | E26: Papaya | F26: =TEXT(A17,"MM-YYYY") -> 01-2025 | G26: Paid | H26: Sameer | J26: =VLOOKUP(B26,Table3[#All],2,0) -> Inventory | K26: =TEXT(ROW(), "0000") -> 0026
A27: 45680 | B27: Vegetables | C27: 680 | D27: Bank | F27: =TEXT(A18,"MM-YYYY") -> 01-2025 | G27: Paid | H27: Sameer | J27: =VLOOKUP(B27,Table3[#All],2,0) -> Inventory | K27: =TEXT(ROW(), "0000") -> 0027
A28: 45680 | B28: Sales | C28: 467 | D28: Online Sale | E28: Milk | F28: =TEXT(A19,"MM-YYYY") -> 01-2025 | J28: =VLOOKUP(B28,Table3[#All],2,0) -> Sales | K28: =TEXT(ROW(), "0000") -> 0028
A29: 45680 | B29: Maintenance | C29: 350 | D29: Cash | F29: =TEXT(A20,"MM-YYYY") -> 01-2025 | G29: Paid | H29: Sameer | J29: =VLOOKUP(B29,Table3[#All],2,0) -> Maintance | K29: =TEXT(ROW(), "0000") -> 0029
A30: 45680 | B30: Bakery | C30: 160 | D30: Cash | F30: =TEXT(A21,"MM-YYYY") -> 01-2025 | G30: Paid | H30: Sameer | J30: =VLOOKUP(B30,Table3[#All],2,0) -> Grocery | K30: =TEXT(ROW(), "0000") -> 0030
A31: 45680 | B31: Tea | C31: 120 | D31: Cash | E31: Golden | F31: =TEXT(A22,"MM-YYYY") -> 01-2025 | G31: Paid | H31: Sameer | J31: =VLOOKUP(B31,Table3[#All],2,0) -> Staff Expenses | K31: =TEXT(ROW(), "0000") -> 0031
A32: 45681 | B32: Sales | C32: 19947 | D32: Wallet | E32: Balaji | F32: =TEXT(A23,"MM-YYYY") -> 01-2025 | J32: =VLOOKUP(B32,Table3[#All],2,0) -> Sales | K32: =TEXT(ROW(), "0000") -> 0032
A33: 45681 | B33: Advance | C33: 10300 | D33: Bank_Cash | F33: =TEXT(A24,"MM-YYYY") -> 01-2025 | G33: Paid | H33: Sameer | J33: =VLOOKUP(B33,Table3[#All],2,0) -> Salary | K33: =TEXT(ROW(), "0000") -> 0033
A34: 45681 | B34: Chicken | C34: 4243 | D34: Bank | E34: Adarsh | F34: =TEXT(A25,"MM-YYYY") -> 01-2025 | G34: Paid | H34: Sameer | J34: =VLOOKUP(B34,Table3[#All],2,0) -> Inventory | K34: =TEXT(ROW(), "0000") -> 0034
A35: 45681 | B35: Grocery | C35: 3967 | D35: Bank | E35: A1 | F35: =TEXT(A26,"MM-YYYY") -> 01-2025 | G35: Paid | H35: Sameer | J35: =VLOOKUP(B35,Table3[#All],2,0) -> Inventory | K35: =TEXT(ROW(), "0000") -> 0035
A36: 45681 | B36: Sales | C36: 3140 | D36: Cash | F36: =TEXT(A27,"MM-YYYY") -> 01-2025 | J36: =VLOOKUP(B36,Table3[#All],2,0) -> Sales | K36: =TEXT(ROW(), "0000") -> 0036
A37: 45681 | B37: Dairy | C37: 1250 | D37: Bank | E37: Adarsh | F37: =TEXT(A37,"MM-YYYY") -> 01-2025 | G37: Paid | H37: Sameer | J37: =VLOOKUP(B37,Table3[#All],2,0) -> Inventory | K37: =TEXT(ROW(), "0000") -> 0037
A38: 45681 | B38: Sales | C38: 1038 | D38: Online Sale | F38: =TEXT(A38,"MM-YYYY") -> 01-2025 | J38: =VLOOKUP(B38,Table3[#All],2,0) -> Sales | K38: =TEXT(ROW(), "0000") -> 0038
A39: 45681 | B39: Charcoal | C39: 840 | D39: Bank | E39: Gyanshweri | F39: =TEXT(A39,"MM-YYYY") -> 01-2025 | G39: Paid | H39: Sameer | J39: =VLOOKUP(B39,Table3[#All],2,0) -> Inventory | K39: =TEXT(ROW(), "0000") -> 0039
A40: 45681 | B40: Vegetables | C40: 580 | D40: Bank | F40: =TEXT(A40,"MM-YYYY") -> 01-2025 | G40: Paid | H40: Sameer | J40: =VLOOKUP(B40,Table3[#All],2,0) -> Inventory | K40: =TEXT(ROW(), "0000") -> 0040
...

Sheet Summary
D1: Cash | E1: Bank_Cash | F1: Bank
H2: =SUM(Summary[Gross ]) -> 1366741
A3: Date | B3: Total Sale | C3: Total Expense | D3: Cash Expense | E3: Bank_Cash_Expenses | F3: Bank_Expenses | G3: Gross | H3: Opening Cash | I3: Cash Sales | J3: Remaining Cash (Bank_Cash) | K3: Bank Cash To Give | L3: Cash Shortage | M3: ID
A4: 45658 | B4: =SUMIFS('Daily Transactions'!C:C,'Daily Transactions'!A:A,$A4,'Daily Transactions'!B:B,"Sales") -> 0 | C4: =SUMIFS('Daily Transactions'!C:C,'Daily Transactions'!A:A,$A4,'Daily Transactions'!B:B,"<>Sales") -> 0 | D4: =SUMIFS('Daily Transactions'!C:C,'Daily Transactions'!A:A,$A4,'Daily Transactions'!B:B,"<>Sales",'Daily Transactions'!D:D,"Cash") -> 0 | E4: =SUMIFS('Daily Transactions'!C:C,'Daily Transactions'!A:A,$A4,'Daily Transactions'!B:B,"<>Sales",'Daily Transactions'!D:D,"Bank_Cash") -> 0 | F4: =SUMIFS('Daily Transactions'!C:C,'Daily Transactions'!A:A,$A4,'Daily Transactions'!B:B,"<>Sales",'Daily Transactions'!D:D,"Bank") -> 0 | G4: =B4-C4 -> 0 | H4: 0 | I4: =SUMIFS('Daily Transactions'!C:C,'Daily Transactions'!A:A,$A4,'Daily Transactions'!B:B,"Sales",'Daily Transactions'!D:D,"Cash") -> 0 | J4: =(H4+I4)-(D4+E4) -> 0 | L4: =SUMIFS('Daily Transactions'!C:C,'Daily Transactions'!A:A,$A4,'Daily Transactions'!B:B,"Cash Shortage",'Daily Transactions'!D:D,"Cash") -> 0
A5: =A4+1 -> 45659 | B5: =SUMIFS('Daily Transactions'!C:C,'Daily Transactions'!A:A,$A5,'Daily Transactions'!B:B,"Sales") -> 0 | C5: =SUMIFS('Daily Transactions'!C:C,'Daily Transactions'!A:A,$A5,'Daily Transactions'!B:B,"<>Sales") -> 0 | D5: =SUMIFS('Daily Transactions'!C:C,'Daily Transactions'!A:A,$A5,'Daily Transactions'!B:B,"<>Sales",'Daily Transactions'!D:D,"Cash") -> 0 | E5: =SUMIFS('Daily Transactions'!C:C,'Daily Transactions'!A:A,$A5,'Daily Transactions'!B:B,"<>Sales",'Daily Transactions'!D:D,"Bank_Cash") -> 0 | F5: =SUMIFS('Daily Transactions'!C:C,'Daily Transactions'!A:A,$A5,'Daily Transactions'!B:B,"<>Sales",'Daily Transactions'!D:D,"Bank") -> 0 | G5: =B5-C5 -> 0 | H5: =J4 -> 0 | I5: =SUMIFS('Daily Transactions'!C:C,'Daily Transactions'!A:A,$A5,'Daily Transactions'!B:B,"Sales",'Daily Transactions'!D:D,"Cash") -> 0 | J5: =(H5+I5)-(D5+E5) -> 0 | L5: =SUMIFS('Daily Transactions'!C:C,'Daily Transactions'!A:A,$A5,'Daily Transactions'!B:B,"Cash Shortage",'Daily Transactions'!D:D,"Cash") -> 0
A6: =A5+1 -> 45660 | B6: =SUMIFS('Daily Transactions'!C:C,'Daily Transactions'!A:A,$A6,'Daily Transactions'!B:B,"Sales") -> 0 | C6: =SUMIFS('Daily Transactions'!C:C,'Daily Transactions'!A:A,$A6,'Daily Transactions'!B:B,"<>Sales") -> 0 | D6: =SUMIFS('Daily Transactions'!C:C,'Daily Transactions'!A:A,$A6,'Daily Transactions'!B:B,"<>Sales",'Daily Transactions'!D:D,"Cash") -> 0 | E6: =SUMIFS('Daily Transactions'!C:C,'Daily Transactions'!A:A,$A6,'Daily Transactions'!B:B,"<>Sales",'Daily Transactions'!D:D,"Bank_Cash") -> 0 | F6: =SUMIFS('Daily Transactions'!C:C,'Daily Transactions'!A:A,$A6,'Daily Transactions'!B:B,"<>Sales",'Daily Transactions'!D:D,"Bank") -> 0 | G6: =B6-C6 -> 0 | H6: =J5 -> 0 | I6: =SUMIFS('Daily Transactions'!C:C,'Daily Transactions'!A:A,$A6,'Daily Transactions'!B:B,"Sales",'Daily Transactions'!D:D,"Cash") -> 0 | J6: =(H6+I6)-(D6+E6) -> 0 | L6: =SUMIFS('Daily Transactions'!C:C,'Daily Transactions'!A:A,$A6,'Daily Transactions'!B:B,"Cash Shortage",'Daily Transactions'!D:D,"Cash") -> 0
A7: =A6+1 -> 45661 | B7: =SUMIFS('Daily Transactions'!C:C,'Daily Transactions'!A:A,$A7,'Daily Transactions'!B:B,"Sales") -> 0 | C7: =SUMIFS('Daily Transactions'!C:C,'Daily Transactions'!A:A,$A7,'Daily Transactions'!B:B,"<>Sales") -> 0 | D7: =SUMIFS('Daily Transactions'!C:C,'Daily Transactions'!A:A,$A7,'Daily Transactions'!B:B,"<>Sales",'Daily Transactions'!D:D,"Cash") -> 0 | E7: =SUMIFS('Daily Transactions'!C:C,'Daily Transactions'!A:A,$A7,'Daily Transactions'!B:B,"<>Sales",'Daily Transactions'!D:D,"Bank_Cash") -> 0 | F7: =SUMIFS('Daily Transactions'!C:C,'Daily Transactions'!A:A,$A7,'Daily Transactions'!B:B,"<>Sales",'Daily Transactions'!D:D,"Bank") -> 0 | G7: =B7-C7 -> 0 | H7: =J6 -> 0 | I7: =SUMIFS('Daily Transactions'!C:C,'Daily Transactions'!A:A,$A7,'Daily Transactions'!B:B,"Sales",'Daily Transactions'!D:D,"Cash") -> 0 | J7: =(H7+I7)-(D7+E7) -> 0 | L7: =SUMIFS('Daily Transactions'!C:C,'Daily Transactions'!A:A,$A7,'Daily Transactions'!B:B,"Cash Shortage",'Daily Transactions'!D:D,"Cash") -> 0
A8: =A7+1 -> 45662 | B8: =SUMIFS('Daily Transactions'!C:C,'Daily Transactions'!A:A,$A8,'Daily Transactions'!B:B,"Sales") -> 0 | C8: =SUMIFS('Daily Transactions'!C:C,'Daily Transactions'!A:A,$A8,'Daily Transactions'!B:B,"<>Sales") -> 0 | D8: =SUMIFS('Daily Transactions'!C:C,'Daily Transactions'!A:A,$A8,'Daily Transactions'!B:B,"<>Sales",'Daily Transactions'!D:D,"Cash") -> 0 | E8: =SUMIFS('Daily Transactions'!C:C,'Daily Transactions'!A:A,$A8,'Daily Transactions'!B:B,"<>Sales",'Daily Transactions'!D:D,"Bank_Cash") -> 0 | F8: =SUMIFS('Daily Transactions'!C:C,'Daily Transactions'!A:A,$A8,'Daily Transactions'!B:B,"<>Sales",'Daily Transactions'!D:D,"Bank") -> 0 | G8: =B8-C8 -> 0 | H8: =J7 -> 0 | I8: =SUMIFS('Daily Transactions'!C:C,'Daily Transactions'!A:A,$A8,'Daily Transactions'!B:B,"Sales",'Daily Transactions'!D:D,"Cash") -> 0 | J8: =(H8+I8)-(D8+E8) -> 0 | L8: =SUMIFS('Daily Transactions'!C:C,'Daily Transactions'!A:A,$A8,'Daily Transactions'!B:B,"Cash Shortage",'Daily Transactions'!D:D,"Cash") -> 0
A9: =A8+1 -> 45663 | B9: =SUMIFS('Daily Transactions'!C:C,'Daily Transactions'!A:A,$A9,'Daily Transactions'!B:B,"Sales") -> 0 | C9: =SUMIFS('Daily Transactions'!C:C,'Daily Transactions'!A:A,$A9,'Daily Transactions'!B:B,"<>Sales") -> 0 | D9: =SUMIFS('Daily Transactions'!C:C,'Daily Transactions'!A:A,$A9,'Daily Transactions'!B:B,"<>Sales",'Daily Transactions'!D:D,"Cash") -> 0 | E9: =SUMIFS('Daily Transactions'!C:C,'Daily Transactions'!A:A,$A9,'Daily Transactions'!B:B,"<>Sales",'Daily Transactions'!D:D,"Bank_Cash") -> 0 | F9: =SUMIFS('Daily Transactions'!C:C,'Daily Transactions'!A:A,$A9,'Daily Transactions'!B:B,"<>Sales",'Daily Transactions'!D:D,"Bank") -> 0 | G9: =B9-C9 -> 0 | H9: =J8 -> 0 | I9: =SUMIFS('Daily Transactions'!C:C,'Daily Transactions'!A:A,$A9,'Daily Transactions'!B:B,"Sales",'Daily Transactions'!D:D,"Cash") -> 0 | J9: =(H9+I9)-(D9+E9) -> 0 | L9: =SUMIFS('Daily Transactions'!C:C,'Daily Transactions'!A:A,$A9,'Daily Transactions'!B:B,"Cash Shortage",'Daily Transactions'!D:D,"Cash") -> 0
A10: =A9+1 -> 45664 | B10: =SUMIFS('Daily Transactions'!C:C,'Daily Transactions'!A:A,$A10,'Daily Transactions'!B:B,"Sales") -> 0 | C10: =SUMIFS('Daily Transactions'!C:C,'Daily Transactions'!A:A,$A10,'Daily Transactions'!B:B,"<>Sales") -> 0 | D10: =SUMIFS('Daily Transactions'!C:C,'Daily Transactions'!A:A,$A10,'Daily Transactions'!B:B,"<>Sales",'Daily Transactions'!D:D,"Cash") -> 0 | E10: =SUMIFS('Daily Transactions'!C:C,'Daily Transactions'!A:A,$A10,'Daily Transactions'!B:B,"<>Sales",'Daily Transactions'!D:D,"Bank_Cash") -> 0 | F10: =SUMIFS('Daily Transactions'!C:C,'Daily Transactions'!A:A,$A10,'Daily Transactions'!B:B,"<>Sales",'Daily Transactions'!D:D,"Bank") -> 0 | G10: =B10-C10 -> 0 | H10: =J9 -> 0 | I10: =SUMIFS('Daily Transactions'!C:C,'Daily Transactions'!A:A,$A10,'Daily Transactions'!B:B,"Sales",'Daily Transactions'!D:D,"Cash") -> 0 | J10: =(H10+I10)-(D10+E10) -> 0 | L10: =SUMIFS('Daily Transactions'!C:C,'Daily Transactions'!A:A,$A10,'Daily Transactions'!B:B,"Cash Shortage",'Daily Transactions'!D:D,"Cash") -> 0
A11: =A10+1 -> 45665 | B11: =SUMIFS('Daily Transactions'!C:C,'Daily Transactions'!A:A,$A11,'Daily Transactions'!B:B,"Sales") -> 0 | C11: =SUMIFS('Daily Transactions'!C:C,'Daily Transactions'!A:A,$A11,'Daily Transactions'!B:B,"<>Sales") -> 0 | D11: =SUMIFS('Daily Transactions'!C:C,'Daily Transactions'!A:A,$A11,'Daily Transactions'!B:B,"<>Sales",'Daily Transactions'!D:D,"Cash") -> 0 | E11: =SUMIFS('Daily Transactions'!C:C,'Daily Transactions'!A:A,$A11,'Daily Transactions'!B:B,"<>Sales",'Daily Transactions'!D:D,"Bank_Cash") -> 0 | F11: =SUMIFS('Daily Transactions'!C:C,'Daily Transactions'!A:A,$A11,'Daily Transactions'!B:B,"<>Sales",'Daily Transactions'!D:D,"Bank") -> 0 | G11: =B11-C11 -> 0 | H11: =J10 -> 0 | I11: =SUMIFS('Daily Transactions'!C:C,'Daily Transactions'!A:A,$A11,'Daily Transactions'!B:B,"Sales",'Daily Transactions'!D:D,"Cash") -> 0 | J11: =(H11+I11)-(D11+E11) -> 0 | L11: =SUMIFS('Daily Transactions'!C:C,'Daily Transactions'!A:A,$A11,'Daily Transactions'!B:B,"Cash Shortage",'Daily Transactions'!D:D,"Cash") -> 0
A12: =A11+1 -> 45666 | B12: =SUMIFS('Daily Transactions'!C:C,'Daily Transactions'!A:A,$A12,'Daily Transactions'!B:B,"Sales") -> 0 | C12: =SUMIFS('Daily Transactions'!C:C,'Daily Transactions'!A:A,$A12,'Daily Transactions'!B:B,"<>Sales") -> 0 | D12: =SUMIFS('Daily Transactions'!C:C,'Daily Transactions'!A:A,$A12,'Daily Transactions'!B:B,"<>Sales",'Daily Transactions'!D:D,"Cash") -> 0 | E12: =SUMIFS('Daily Transactions'!C:C,'Daily Transactions'!A:A,$A12,'Daily Transactions'!B:B,"<>Sales",'Daily Transactions'!D:D,"Bank_Cash") -> 0 | F12: =SUMIFS('Daily Transactions'!C:C,'Daily Transactions'!A:A,$A12,'Daily Transactions'!B:B,"<>Sales",'Daily Transactions'!D:D,"Bank") -> 0 | G12: =B12-C12 -> 0 | H12: =J11 -> 0 | I12: =SUMIFS('Daily Transactions'!C:C,'Daily Transactions'!A:A,$A12,'Daily Transactions'!B:B,"Sales",'Daily Transactions'!D:D,"Cash") -> 0 | J12: =(H12+I12)-(D12+E12) -> 0 | L12: =SUMIFS('Daily Transactions'!C:C,'Daily Transactions'!A:A,$A12,'Daily Transactions'!B:B,"Cash Shortage",'Daily Transactions'!D:D,"Cash") -> 0
A13: =A12+1 -> 45667 | B13: =SUMIFS('Daily Transactions'!C:C,'Daily Transactions'!A:A,$A13,'Daily Transactions'!B:B,"Sales") -> 0 | C13: =SUMIFS('Daily Transactions'!C:C,'Daily Transactions'!A:A,$A13,'Daily Transactions'!B:B,"<>Sales") -> 0 | D13: =SUMIFS('Daily Transactions'!C:C,'Daily Transactions'!A:A,$A13,'Daily Transactions'!B:B,"<>Sales",'Daily Transactions'!D:D,"Cash") -> 0 | E13: =SUMIFS('Daily Transactions'!C:C,'Daily Transactions'!A:A,$A13,'Daily Transactions'!B:B,"<>Sales",'Daily Transactions'!D:D,"Bank_Cash") -> 0 | F13: =SUMIFS('Daily Transactions'!C:C,'Daily Transactions'!A:A,$A13,'Daily Transactions'!B:B,"<>Sales",'Daily Transactions'!D:D,"Bank") -> 0 | G13: =B13-C13 -> 0 | H13: =J12 -> 0 | I13: =SUMIFS('Daily Transactions'!C:C,'Daily Transactions'!A:A,$A13,'Daily Transactions'!B:B,"Sales",'Daily Transactions'!D:D,"Cash") -> 0 | J13: =(H13+I13)-(D13+E13) -> 0 | L13: =SUMIFS('Daily Transactions'!C:C,'Daily Transactions'!A:A,$A13,'Daily Transactions'!B:B,"Cash Shortage",'Daily Transactions'!D:D,"Cash") -> 0
A14: =A13+1 -> 45668 | B14: =SUMIFS('Daily Transactions'!C:C,'Daily Transactions'!A:A,$A14,'Daily Transactions'!B:B,"Sales") -> 0 | C14: =SUMIFS('Daily Transactions'!C:C,'Daily Transactions'!A:A,$A14,'Daily Transactions'!B:B,"<>Sales") -> 0 | D14: =SUMIFS('Daily Transactions'!C:C,'Daily Transactions'!A:A,$A14,'Daily Transactions'!B:B,"<>Sales",'Daily Transactions'!D:D,"Cash") -> 0 | E14: =SUMIFS('Daily Transactions'!C:C,'Daily Transactions'!A:A,$A14,'Daily Transactions'!B:B,"<>Sales",'Daily Transactions'!D:D,"Bank_Cash") -> 0 | F14: =SUMIFS('Daily Transactions'!C:C,'Daily Transactions'!A:A,$A14,'Daily Transactions'!B:B,"<>Sales",'Daily Transactions'!D:D,"Bank") -> 0 | G14: =B14-C14 -> 0 | H14: =J13 -> 0 | I14: =SUMIFS('Daily Transactions'!C:C,'Daily Transactions'!A:A,$A14,'Daily Transactions'!B:B,"Sales",'Daily Transactions'!D:D,"Cash") -> 0 | J14: =(H14+I14)-(D14+E14) -> 0 | L14: =SUMIFS('Daily Transactions'!C:C,'Daily Transactions'!A:A,$A14,'Daily Transactions'!B:B,"Cash Shortage",'Daily Transactions'!D:D,"Cash") -> 0
A15: =A14+1 -> 45669 | B15: =SUMIFS('Daily Transactions'!C:C,'Daily Transactions'!A:A,$A15,'Daily Transactions'!B:B,"Sales") -> 0 | C15: =SUMIFS('Daily Transactions'!C:C,'Daily Transactions'!A:A,$A15,'Daily Transactions'!B:B,"<>Sales") -> 0 | D15: =SUMIFS('Daily Transactions'!C:C,'Daily Transactions'!A:A,$A15,'Daily Transactions'!B:B,"<>Sales",'Daily Transactions'!D:D,"Cash") -> 0 | E15: =SUMIFS('Daily Transactions'!C:C,'Daily Transactions'!A:A,$A15,'Daily Transactions'!B:B,"<>Sales",'Daily Transactions'!D:D,"Bank_Cash") -> 0 | F15: =SUMIFS('Daily Transactions'!C:C,'Daily Transactions'!A:A,$A15,'Daily Transactions'!B:B,"<>Sales",'Daily Transactions'!D:D,"Bank") -> 0 | G15: =B15-C15 -> 0 | H15: =J14 -> 0 | I15: =SUMIFS('Daily Transactions'!C:C,'Daily Transactions'!A:A,$A15,'Daily Transactions'!B:B,"Sales",'Daily Transactions'!D:D,"Cash") -> 0 | J15: =(H15+I15)-(D15+E15) -> 0 | L15: =SUMIFS('Daily Transactions'!C:C,'Daily Transactions'!A:A,$A15,'Daily Transactions'!B:B,"Cash Shortage",'Daily Transactions'!D:D,"Cash") -> 0
A16: =A15+1 -> 45670 | B16: =SUMIFS('Daily Transactions'!C:C,'Daily Transactions'!A:A,$A16,'Daily Transactions'!B:B,"Sales") -> 0 | C16: =SUMIFS('Daily Transactions'!C:C,'Daily Transactions'!A:A,$A16,'Daily Transactions'!B:B,"<>Sales") -> 0 | D16: =SUMIFS('Daily Transactions'!C:C,'Daily Transactions'!A:A,$A16,'Daily Transactions'!B:B,"<>Sales",'Daily Transactions'!D:D,"Cash") -> 0 | E16: =SUMIFS('Daily Transactions'!C:C,'Daily Transactions'!A:A,$A16,'Daily Transactions'!B:B,"<>Sales",'Daily Transactions'!D:D,"Bank_Cash") -> 0 | F16: =SUMIFS('Daily Transactions'!C:C,'Daily Transactions'!A:A,$A16,'Daily Transactions'!B:B,"<>Sales",'Daily Transactions'!D:D,"Bank") -> 0 | G16: =B16-C16 -> 0 | H16: =J15 -> 0 | I16: =SUMIFS('Daily Transactions'!C:C,'Daily Transactions'!A:A,$A16,'Daily Transactions'!B:B,"Sales",'Daily Transactions'!D:D,"Cash") -> 0 | J16: =(H16+I16)-(D16+E16) -> 0 | L16: =SUMIFS('Daily Transactions'!C:C,'Daily Transactions'!A:A,$A16,'Daily Transactions'!B:B,"Cash Shortage",'Daily Transactions'!D:D,"Cash") -> 0
... A24: =A23+1 -> 45678 | B24: =SUMIFS('Daily Transactions'!C:C,'Daily Transactions'!A:A,$A24,'Daily Transactions'!B:B,"Sales") -> 0 | C24: =SUMIFS('Daily Transactions'!C:C,'Daily Transactions'!A:A,$A24,'Daily Transactions'!B:B,"<>Sales") -> 0 | D24: =SUMIFS('Daily Transactions'!C:C,'Daily Transactions'!A:A,$A24,'Daily Transactions'!B:B,"<>Sales",'Daily Transactions'!D:D,"Cash") -> 0 | E24: =SUMIFS('Daily Transactions'!C:C,'Daily Transactions'!A:A,$A24,'Daily Transactions'!B:B,"<>Sales",'Daily Transactions'!D:D,"Bank_Cash") -> 0 | F24: =SUMIFS('Daily Transactions'!C:C,'Daily Transactions'!A:A,$A24,'Daily Transactions'!B:B,"<>Sales",'Daily Transactions'!D:D,"Bank") -> 0 | G24: =B24-C24 -> 0 | H24: =J23 -> 0 | I24: =SUMIFS('Daily Transactions'!C:C,'Daily Transactions'!A:A,$A24,'Daily Transactions'!B:B,"Sales",'Daily Transactions'!D:D,"Cash") -> 0 | J24: =(H24+I24)-(D24+E24) -> 0 | L24: =SUMIFS('Daily Transactions'!C:C,'Daily Transactions'!A:A,$A24,'Daily Transactions'!B:B,"Cash Shortage",'Daily Transactions'!D:D,"Cash") -> 0
A25: =A24+1 -> 45679 | B25: =SUMIFS('Daily Transactions'!C:C,'Daily Transactions'!A:A,$A25,'Daily Transactions'!B:B,"Sales") -> 27918 | C25: =SUMIFS('Daily Transactions'!C:C,'Daily Transactions'!A:A,$A25,'Daily Transactions'!B:B,"<>Sales") -> 31943 | D25: =SUMIFS('Daily Transactions'!C:C,'Daily Transactions'!A:A,$A25,'Daily Transactions'!B:B,"<>Sales",'Daily Transactions'!D:D,"Cash") -> 1959 | E25: =SUMIFS('Daily Transactions'!C:C,'Daily Transactions'!A:A,$A25,'Daily Transactions'!B:B,"<>Sales",'Daily Transactions'!D:D,"Bank_Cash") -> 0 | F25: =SUMIFS('Daily Transactions'!C:C,'Daily Transactions'!A:A,$A25,'Daily Transactions'!B:B,"<>Sales",'Daily Transactions'!D:D,"Bank") -> 29984 | G25: =B25-C25 -> -4025 | H25: 8250 | I25: =SUMIFS('Daily Transactions'!C:C,'Daily Transactions'!A:A,$A25,'Daily Transactions'!B:B,"Sales",'Daily Transactions'!D:D,"Cash") -> 4759 | J25: =(H25+I25)-(D25+E25) -> 11050 | L25: =SUMIFS('Daily Transactions'!C:C,'Daily Transactions'!A:A,$A25,'Daily Transactions'!B:B,"Cash Shortage",'Daily Transactions'!D:D,"Cash") -> 0
A26: =A25+1 -> 45680 | B26: =SUMIFS('Daily Transactions'!C:C,'Daily Transactions'!A:A,$A26,'Daily Transactions'!B:B,"Sales") -> 13430 | C26: =SUMIFS('Daily Transactions'!C:C,'Daily Transactions'!A:A,$A26,'Daily Transactions'!B:B,"<>Sales") -> 13393 | D26: =SUMIFS('Daily Transactions'!C:C,'Daily Transactions'!A:A,$A26,'Daily Transactions'!B:B,"<>Sales",'Daily Transactions'!D:D,"Cash") -> 2110 | E26: =SUMIFS('Daily Transactions'!C:C,'Daily Transactions'!A:A,$A26,'Daily Transactions'!B:B,"<>Sales",'Daily Transactions'!D:D,"Bank_Cash") -> 0 | F26: =SUMIFS('Daily Transactions'!C:C,'Daily Transactions'!A:A,$A26,'Daily Transactions'!B:B,"<>Sales",'Daily Transactions'!D:D,"Bank") -> 11283 | G26: =B26-C26 -> 37 | H26: =J25 -> 11050 | I26: =SUMIFS('Daily Transactions'!C:C,'Daily Transactions'!A:A,$A26,'Daily Transactions'!B:B,"Sales",'Daily Transactions'!D:D,"Cash") -> 2410 | J26: =(H26+I26)-(D26+E26) -> 11350 | L26: =SUMIFS('Daily Transactions'!C:C,'Daily Transactions'!A:A,$A26,'Daily Transactions'!B:B,"Cash Shortage",'Daily Transactions'!D:D,"Cash") -> 0
A27: =A26+1 -> 45681 | B27: =SUMIFS('Daily Transactions'!C:C,'Daily Transactions'!A:A,$A27,'Daily Transactions'!B:B,"Sales") -> 24925 | C27: =SUMIFS('Daily Transactions'!C:C,'Daily Transactions'!A:A,$A27,'Daily Transactions'!B:B,"<>Sales") -> 21670 | D27: =SUMIFS('Daily Transactions'!C:C,'Daily Transactions'!A:A,$A27,'Daily Transactions'!B:B,"<>Sales",'Daily Transactions'!D:D,"Cash") -> 490 | E27: =SUMIFS('Daily Transactions'!C:C,'Daily Transactions'!A:A,$A27,'Daily Transactions'!B:B,"<>Sales",'Daily Transactions'!D:D,"Bank_Cash") -> 10300 | F27: =SUMIFS('Daily Transactions'!C:C,'Daily Transactions'!A:A,$A27,'Daily Transactions'!B:B,"<>Sales",'Daily Transactions'!D:D,"Bank") -> 10880 | G27: =B27-C27 -> 3255 | H27: =J26 -> 11350 | I27: =SUMIFS('Daily Transactions'!C:C,'Daily Transactions'!A:A,$A27,'Daily Transactions'!B:B,"Sales",'Daily Transactions'!D:D,"Cash") -> 3140 | J27: =(H27+I27)-(D27+E27) -> 3700 | L27: =SUMIFS('Daily Transactions'!C:C,'Daily Transactions'!A:A,$A27,'Daily Transactions'!B:B,"Cash Shortage",'Daily Transactions'!D:D,"Cash") -> 0
A28: =A27+1 -> 45682 | B28: =SUMIFS('Daily Transactions'!C:C,'Daily Transactions'!A:A,$A28,'Daily Transactions'!B:B,"Sales") -> 39001 | C28: =SUMIFS('Daily Transactions'!C:C,'Daily Transactions'!A:A,$A28,'Daily Transactions'!B:B,"<>Sales") -> 23322 | D28: =SUMIFS('Daily Transactions'!C:C,'Daily Transactions'!A:A,$A28,'Daily Transactions'!B:B,"<>Sales",'Daily Transactions'!D:D,"Cash") -> 3960 | E28: =SUMIFS('Daily Transactions'!C:C,'Daily Transactions'!A:A,$A28,'Daily Transactions'!B:B,"<>Sales",'Daily Transactions'!D:D,"Bank_Cash") -> 0 | F28: =SUMIFS('Daily Transactions'!C:C,'Daily Transactions'!A:A,$A28,'Daily Transactions'!B:B,"<>Sales",'Daily Transactions'!D:D,"Bank") -> 19362 | G28: =B28-C28 -> 15679 | H28: =J27 -> 3700 | I28: =SUMIFS('Daily Transactions'!C:C,'Daily Transactions'!A:A,$A28,'Daily Transactions'!B:B,"Sales",'Daily Transactions'!D:D,"Cash") -> 5660 | J28: =(H28+I28)-(D28+E28) -> 5400 | L28: =SUMIFS('Daily Transactions'!C:C,'Daily Transactions'!A:A,$A28,'Daily Transactions'!B:B,"Cash Shortage",'Daily Transactions'!D:D,"Cash") -> 0
A29: =A28+1 -> 45683 | B29: =SUMIFS('Daily Transactions'!C:C,'Daily Transactions'!A:A,$A29,'Daily Transactions'!B:B,"Sales") -> 41795 | C29: =SUMIFS('Daily Transactions'!C:C,'Daily Transactions'!A:A,$A29,'Daily Transactions'!B:B,"<>Sales") -> 19605 | D29: =SUMIFS('Daily Transactions'!C:C,'Daily Transactions'!A:A,$A29,'Daily Transactions'!B:B,"<>Sales",'Daily Transactions'!D:D,"Cash") -> 2379 | E29: =SUMIFS('Daily Transactions'!C:C,'Daily Transactions'!A:A,$A29,'Daily Transactions'!B:B,"<>Sales",'Daily Transactions'!D:D,"Bank_Cash") -> 2700 | F29: =SUMIFS('Daily Transactions'!C:C,'Daily Transactions'!A:A,$A29,'Daily Transactions'!B:B,"<>Sales",'Daily Transactions'!D:D,"Bank") -> 14526 | G29: =B29-C29 -> 22190 | H29: =J28 -> 5400 | I29: =SUMIFS('Daily Transactions'!C:C,'Daily Transactions'!A:A,$A29,'Daily Transactions'!B:B,"Sales",'Daily Transactions'!D:D,"Cash") -> 3979 | J29: =(H29+I29)-(D29+E29) -> 4300 | L29: =SUMIFS('Daily Transactions'!C:C,'Daily Transactions'!A:A,$A29,'Daily Transactions'!B:B,"Cash Shortage",'Daily Transactions'!D:D,"Cash") -> 0
A30: =A29+1 -> 45684 | B30: =SUMIFS('Daily Transactions'!C:C,'Daily Transactions'!A:A,$A30,'Daily Transactions'!B:B,"Sales") -> 21790 | C30: =SUMIFS('Daily Transactions'!C:C,'Daily Transactions'!A:A,$A30,'Daily Transactions'!B:B,"<>Sales") -> 7788 | D30: =SUMIFS('Daily Transactions'!C:C,'Daily Transactions'!A:A,$A30,'Daily Transactions'!B:B,"<>Sales",'Daily Transactions'!D:D,"Cash") -> 1290 | E30: =SUMIFS('Daily Transactions'!C:C,'Daily Transactions'!A:A,$A30,'Daily Transactions'!B:B,"<>Sales",'Daily Transactions'!D:D,"Bank_Cash") -> 0 | F30: =SUMIFS('Daily Transactions'!C:C,'Daily Transactions'!A:A,$A30,'Daily Transactions'!B:B,"<>Sales",'Daily Transactions'!D:D,"Bank") -> 6498 | G30: =B30-C30 -> 14002 | H30: =J29 -> 4300 | I30: =SUMIFS('Daily Transactions'!C:C,'Daily Transactions'!A:A,$A30,'Daily Transactions'!B:B,"Sales",'Daily Transactions'!D:D,"Cash") -> 2540 | J30: =(H30+I30)-(D30+E30) -> 5550 | L30: =SUMIFS('Daily Transactions'!C:C,'Daily Transactions'!A:A,$A30,'Daily Transactions'!B:B,"Cash Shortage",'Daily Transactions'!D:D,"Cash") -> 0
A31: =A30+1 -> 45685 | B31: =SUMIFS('Daily Transactions'!C:C,'Daily Transactions'!A:A,$A31,'Daily Transactions'!B:B,"Sales") -> 18334 | C31: =SUMIFS('Daily Transactions'!C:C,'Daily Transactions'!A:A,$A31,'Daily Transactions'!B:B,"<>Sales") -> 12279 | D31: =SUMIFS('Daily Transactions'!C:C,'Daily Transactions'!A:A,$A31,'Daily Transactions'!B:B,"<>Sales",'Daily Transactions'!D:D,"Cash") -> 1315 | E31: =SUMIFS('Daily Transactions'!C:C,'Daily Transactions'!A:A,$A31,'Daily Transactions'!B:B,"<>Sales",'Daily Transactions'!D:D,"Bank_Cash") -> 0 | F31: =SUMIFS('Daily Transactions'!C:C,'Daily Transactions'!A:A,$A31,'Daily Transactions'!B:B,"<>Sales",'Daily Transactions'!D:D,"Bank") -> 10964 | G31: =B31-C31 -> 6055 | H31: =J30 -> 5550 | I31: =SUMIFS('Daily Transactions'!C:C,'Daily Transactions'!A:A,$A31,'Daily Transactions'!B:B,"Sales",'Daily Transactions'!D:D,"Cash") -> 2415 | J31: =(H31+I31)-(D31+E31) -> 6650 | L31: =SUMIFS('Daily Transactions'!C:C,'Daily Transactions'!A:A,$A31,'Daily Transactions'!B:B,"Cash Shortage",'Daily Transactions'!D:D,"Cash") -> 0
A32: =A31+1 -> 45686 | B32: =SUMIFS('Daily Transactions'!C:C,'Daily Transactions'!A:A,$A32,'Daily Transactions'!B:B,"Sales") -> 17427 | C32: =SUMIFS('Daily Transactions'!C:C,'Daily Transactions'!A:A,$A32,'Daily Transactions'!B:B,"<>Sales") -> 12536 | D32: =SUMIFS('Daily Transactions'!C:C,'Daily Transactions'!A:A,$A32,'Daily Transactions'!B:B,"<>Sales",'Daily Transactions'!D:D,"Cash") -> 2660 | E32: =SUMIFS('Daily Transactions'!C:C,'Daily Transactions'!A:A,$A32,'Daily Transactions'!B:B,"<>Sales",'Daily Transactions'!D:D,"Bank_Cash") -> 100 | F32: =SUMIFS('Daily Transactions'!C:C,'Daily Transactions'!A:A,$A32,'Daily Transactions'!B:B,"<>Sales",'Daily Transactions'!D:D,"Bank") -> 9776 | G32: =B32-C32 -> 4891 | H32: =J31 -> 6650 | I32: =SUMIFS('Daily Transactions'!C:C,'Daily Transactions'!A:A,$A32,'Daily Transactions'!B:B,"Sales",'Daily Transactions'!D:D,"Cash") -> 2710 | J32: =(H32+I32)-(D32+E32) -> 6600 | L32: =SUMIFS('Daily Transactions'!C:C,'Daily Transactions'!A:A,$A32,'Daily Transactions'!B:B,"Cash Shortage",'Daily Transactions'!D:D,"Cash") -> 0
A33: =A32+1 -> 45687 | B33: =SUMIFS('Daily Transactions'!C:C,'Daily Transactions'!A:A,$A33,'Daily Transactions'!B:B,"Sales") -> 18440 | C33: =SUMIFS('Daily Transactions'!C:C,'Daily Transactions'!A:A,$A33,'Daily Transactions'!B:B,"<>Sales") -> 21294 | D33: =SUMIFS('Daily Transactions'!C:C,'Daily Transactions'!A:A,$A33,'Daily Transactions'!B:B,"<>Sales",'Daily Transactions'!D:D,"Cash") -> 100 | E33: =SUMIFS('Daily Transactions'!C:C,'Daily Transactions'!A:A,$A33,'Daily Transactions'!B:B,"<>Sales",'Daily Transactions'!D:D,"Bank_Cash") -> 2000 | F33: =SUMIFS('Daily Transactions'!C:C,'Daily Transactions'!A:A,$A33,'Daily Transactions'!B:B,"<>Sales",'Daily Transactions'!D:D,"Bank") -> 19194 | G33: =B33-C33 -> -2854 | H33: =J32 -> 6600 | I33: =SUMIFS('Daily Transactions'!C:C,'Daily Transactions'!A:A,$A33,'Daily Transactions'!B:B,"Sales",'Daily Transactions'!D:D,"Cash") -> 1700 | J33: =(H33+I33)-(D33+E33) -> 6200 | L33: =SUMIFS('Daily Transactions'!C:C,'Daily Transactions'!A:A,$A33,'Daily Transactions'!B:B,"Cash Shortage",'Daily Transactions'!D:D,"Cash") -> 0
A34: =A33+1 -> 45688 | B34: =SUMIFS('Daily Transactions'!C:C,'Daily Transactions'!A:A,$A34,'Daily Transactions'!B:B,"Sales") -> 25378 | C34: =SUMIFS('Daily Transactions'!C:C,'Daily Transactions'!A:A,$A34,'Daily Transactions'!B:B,"<>Sales") -> 30526 | D34: =SUMIFS('Daily Transactions'!C:C,'Daily Transactions'!A:A,$A34,'Daily Transactions'!B:B,"<>Sales",'Daily Transactions'!D:D,"Cash") -> 740 | E34: =SUMIFS('Daily Transactions'!C:C,'Daily Transactions'!A:A,$A34,'Daily Transactions'!B:B,"<>Sales",'Daily Transactions'!D:D,"Bank_Cash") -> 1500 | F34: =SUMIFS('Daily Transactions'!C:C,'Daily Transactions'!A:A,$A34,'Daily Transactions'!B:B,"<>Sales",'Daily Transactions'!D:D,"Bank") -> 28286 | G34: =B34-C34 -> -5148 | H34: =J33 -> 6200 | I34: =SUMIFS('Daily Transactions'!C:C,'Daily Transactions'!A:A,$A34,'Daily Transactions'!B:B,"Sales",'Daily Transactions'!D:D,"Cash") -> 1840 | J34: =(H34+I34)-(D34+E34) -> 5800 | L34: =SUMIFS('Daily Transactions'!C:C,'Daily Transactions'!A:A,$A34,'Daily Transactions'!B:B,"Cash Shortage",'Daily Transactions'!D:D,"Cash") -> 0
A35: =A34+1 -> 45689 | B35: =SUMIFS('Daily Transactions'!C:C,'Daily Transactions'!A:A,$A35,'Daily Transactions'!B:B,"Sales") -> 27527 | C35: =SUMIFS('Daily Transactions'!C:C,'Daily Transactions'!A:A,$A35,'Daily Transactions'!B:B,"<>Sales") -> 16775 | D35: =SUMIFS('Daily Transactions'!C:C,'Daily Transactions'!A:A,$A35,'Daily Transactions'!B:B,"<>Sales",'Daily Transactions'!D:D,"Cash") -> 4465 | E35: =SUMIFS('Daily Transactions'!C:C,'Daily Transactions'!A:A,$A35,'Daily Transactions'!B:B,"<>Sales",'Daily Transactions'!D:D,"Bank_Cash") -> 0 | F35: =SUMIFS('Daily Transactions'!C:C,'Daily Transactions'!A:A,$A35,'Daily Transactions'!B:B,"<>Sales",'Daily Transactions'!D:D,"Bank") -> 12310 | G35: =B35-C35 -> 10752 | H35: =J34 -> 5800 | I35: =SUMIFS('Daily Transactions'!C:C,'Daily Transactions'!A:A,$A35,'Daily Transactions'!B:B,"Sales",'Daily Transactions'!D:D,"Cash") -> 5015 | J35: =(H35+I35)-(D35+E35) -> 6350 | L35: =SUMIFS('Daily Transactions'!C:C,'Daily Transactions'!A:A,$A35,'Daily Transactions'!B:B,"Cash Shortage",'Daily Transactions'!D:D,"Cash") -> 0
A36: =A35+1 -> 45690 | B36: =SUMIFS('Daily Transactions'!C:C,'Daily Transactions'!A:A,$A36,'Daily Transactions'!B:B,"Sales") -> 35936 | C36: =SUMIFS('Daily Transactions'!C:C,'Daily Transactions'!A:A,$A36,'Daily Transactions'!B:B,"<>Sales") -> 29138 | D36: =SUMIFS('Daily Transactions'!C:C,'Daily Transactions'!A:A,$A36,'Daily Transactions'!B:B,"<>Sales",'Daily Transactions'!D:D,"Cash") -> 2540 | E36: =SUMIFS('Daily Transactions'!C:C,'Daily Transactions'!A:A,$A36,'Daily Transactions'!B:B,"<>Sales",'Daily Transactions'!D:D,"Bank_Cash") -> 3500 | F36: =SUMIFS('Daily Transactions'!C:C,'Daily Transactions'!A:A,$A36,'Daily Transactions'!B:B,"<>Sales",'Daily Transactions'!D:D,"Bank") -> 23098 | G36: =B36-C36 -> 6798 | H36: =J35 -> 6350 | I36: =SUMIFS('Daily Transactions'!C:C,'Daily Transactions'!A:A,$A36,'Daily Transactions'!B:B,"Sales",'Daily Transactions'!D:D,"Cash") -> 3340 | J36: =(H36+I36)-(D36+E36) -> 3650 | L36: =SUMIFS('Daily Transactions'!C:C,'Daily Transactions'!A:A,$A36,'Daily Transactions'!B:B,"Cash Shortage",'Daily Transactions'!D:D,"Cash") -> 0
A37: =A36+1 -> 45691 | B37: =SUMIFS('Daily Transactions'!C:C,'Daily Transactions'!A:A,$A37,'Daily Transactions'!B:B,"Sales") -> 22468 | C37: =SUMIFS('Daily Transactions'!C:C,'Daily Transactions'!A:A,$A37,'Daily Transactions'!B:B,"<>Sales") -> 26948 | D37: =SUMIFS('Daily Transactions'!C:C,'Daily Transactions'!A:A,$A37,'Daily Transactions'!B:B,"<>Sales",'Daily Transactions'!D:D,"Cash") -> 2915 | E37: =SUMIFS('Daily Transactions'!C:C,'Daily Transactions'!A:A,$A37,'Daily Transactions'!B:B,"<>Sales",'Daily Transactions'!D:D,"Bank_Cash") -> 0 | F37: =SUMIFS('Daily Transactions'!C:C,'Daily Transactions'!A:A,$A37,'Daily Transactions'!B:B,"<>Sales",'Daily Transactions'!D:D,"Bank") -> 24033 | G37: =B37-C37 -> -4480 | H37: =J36 -> 3650 | I37: =SUMIFS('Daily Transactions'!C:C,'Daily Transactions'!A:A,$A37,'Daily Transactions'!B:B,"Sales",'Daily Transactions'!D:D,"Cash") -> 3065 | J37: =(H37+I37)-(D37+E37) -> 3800 | L37: =SUMIFS('Daily Transactions'!C:C,'Daily Transactions'!A:A,$A37,'Daily Transactions'!B:B,"Cash Shortage",'Daily Transactions'!D:D,"Cash") -> 0
... A48: =A47+1 -> 45702 | B48: =SUMIFS('Daily Transactions'!C:C,'Daily Transactions'!A:A,$A48,'Daily Transactions'!B:B,"Sales") -> 36988 | C48: =SUMIFS('Daily Transactions'!C:C,'Daily Transactions'!A:A,$A48,'Daily Transactions'!B:B,"<>Sales") -> 6065 | D48: =SUMIFS('Daily Transactions'!C:C,'Daily Transactions'!A:A,$A48,'Daily Transactions'!B:B,"<>Sales",'Daily Transactions'!D:D,"Cash") -> 802 | E48: =SUMIFS('Daily Transactions'!C:C,'Daily Transactions'!A:A,$A48,'Daily Transactions'!B:B,"<>Sales",'Daily Transactions'!D:D,"Bank_Cash") -> 90 | F48: =SUMIFS('Daily Transactions'!C:C,'Daily Transactions'!A:A,$A48,'Daily Transactions'!B:B,"<>Sales",'Daily Transactions'!D:D,"Bank") -> 5173 | G48: =B48-C48 -> 30923 | H48: =J47 -> 7656 | I48: =SUMIFS('Daily Transactions'!C:C,'Daily Transactions'!A:A,$A48,'Daily Transactions'!B:B,"Sales",'Daily Transactions'!D:D,"Cash") -> 1999 | J48: =(H48+I48)-(D48+E48) -> 8763 | L48: =SUMIFS('Daily Transactions'!C:C,'Daily Transactions'!A:A,$A48,'Daily Transactions'!B:B,"Cash Shortage",'Daily Transactions'!D:D,"Cash") -> 0
A49: =A48+1 -> 45703 | B49: =SUMIFS('Daily Transactions'!C:C,'Daily Transactions'!A:A,$A49,'Daily Transactions'!B:B,"Sales") -> 25390 | C49: =SUMIFS('Daily Transactions'!C:C,'Daily Transactions'!A:A,$A49,'Daily Transactions'!B:B,"<>Sales") -> 10669 | D49: =SUMIFS('Daily Transactions'!C:C,'Daily Transactions'!A:A,$A49,'Daily Transactions'!B:B,"<>Sales",'Daily Transactions'!D:D,"Cash") -> 30 | E49: =SUMIFS('Daily Transactions'!C:C,'Daily Transactions'!A:A,$A49,'Daily Transactions'!B:B,"<>Sales",'Daily Transactions'!D:D,"Bank_Cash") -> 3791 | F49: =SUMIFS('Daily Transactions'!C:C,'Daily Transactions'!A:A,$A49,'Daily Transactions'!B:B,"<>Sales",'Daily Transactions'!D:D,"Bank") -> 6848 | G49: =B49-C49 -> 14721 | H49: =J48 -> 8763 | I49: =SUMIFS('Daily Transactions'!C:C,'Daily Transactions'!A:A,$A49,'Daily Transactions'!B:B,"Sales",'Daily Transactions'!D:D,"Cash") -> 5244 | J49: =(H49+I49)-(D49+E49) -> 10186 | K49: 1800 | L49: =SUMIFS('Daily Transactions'!C:C,'Daily Transactions'!A:A,$A49,'Daily Transactions'!B:B,"Cash Shortage",'Daily Transactions'!D:D,"Cash") -> 0
A50: =A49+1 -> 45704 | B50: =SUMIFS('Daily Transactions'!C:C,'Daily Transactions'!A:A,$A50,'Daily Transactions'!B:B,"Sales") -> 22504 | C50: =SUMIFS('Daily Transactions'!C:C,'Daily Transactions'!A:A,$A50,'Daily Transactions'!B:B,"<>Sales") -> 19751 | D50: =SUMIFS('Daily Transactions'!C:C,'Daily Transactions'!A:A,$A50,'Daily Transactions'!B:B,"<>Sales",'Daily Transactions'!D:D,"Cash") -> 30 | E50: =SUMIFS('Daily Transactions'!C:C,'Daily Transactions'!A:A,$A50,'Daily Transactions'!B:B,"<>Sales",'Daily Transactions'!D:D,"Bank_Cash") -> 2815 | F50: =SUMIFS('Daily Transactions'!C:C,'Daily Transactions'!A:A,$A50,'Daily Transactions'!B:B,"<>Sales",'Daily Transactions'!D:D,"Bank") -> 16906 | G50: =B50-C50 -> 2753 | H50: =J49 -> 10186 | I50: =SUMIFS('Daily Transactions'!C:C,'Daily Transactions'!A:A,$A50,'Daily Transactions'!B:B,"Sales",'Daily Transactions'!D:D,"Cash") -> 2335 | J50: =(H50+I50)-(D50+E50) -> 9676 | L50: =SUMIFS('Daily Transactions'!C:C,'Daily Transactions'!A:A,$A50,'Daily Transactions'!B:B,"Cash Shortage",'Daily Transactions'!D:D,"Cash") -> 0
A51: =A50+1 -> 45705 | B51: =SUMIFS('Daily Transactions'!C:C,'Daily Transactions'!A:A,$A51,'Daily Transactions'!B:B,"Sales") -> 13718 | C51: =SUMIFS('Daily Transactions'!C:C,'Daily Transactions'!A:A,$A51,'Daily Transactions'!B:B,"<>Sales") -> 8120 | D51: =SUMIFS('Daily Transactions'!C:C,'Daily Transactions'!A:A,$A51,'Daily Transactions'!B:B,"<>Sales",'Daily Transactions'!D:D,"Cash") -> 0 | E51: =SUMIFS('Daily Transactions'!C:C,'Daily Transactions'!A:A,$A51,'Daily Transactions'!B:B,"<>Sales",'Daily Transactions'!D:D,"Bank_Cash") -> 4705 | F51: =SUMIFS('Daily Transactions'!C:C,'Daily Transactions'!A:A,$A51,'Daily Transactions'!B:B,"<>Sales",'Daily Transactions'!D:D,"Bank") -> 3415 | G51: =B51-C51 -> 5598 | H51: =J50 -> 9676 | I51: =SUMIFS('Daily Transactions'!C:C,'Daily Transactions'!A:A,$A51,'Daily Transactions'!B:B,"Sales",'Daily Transactions'!D:D,"Cash") -> 2465 | J51: =(H51+I51)-(D51+E51) -> 7436 | L51: =SUMIFS('Daily Transactions'!C:C,'Daily Transactions'!A:A,$A51,'Daily Transactions'!B:B,"Cash Shortage",'Daily Transactions'!D:D,"Cash") -> 0
A52: =A51+1 -> 45706 | B52: =SUMIFS('Daily Transactions'!C:C,'Daily Transactions'!A:A,$A52,'Daily Transactions'!B:B,"Sales") -> 21864 | C52: =SUMIFS('Daily Transactions'!C:C,'Daily Transactions'!A:A,$A52,'Daily Transactions'!B:B,"<>Sales") -> 4597 | D52: =SUMIFS('Daily Transactions'!C:C,'Daily Transactions'!A:A,$A52,'Daily Transactions'!B:B,"<>Sales",'Daily Transactions'!D:D,"Cash") -> 15 | E52: =SUMIFS('Daily Transactions'!C:C,'Daily Transactions'!A:A,$A52,'Daily Transactions'!B:B,"<>Sales",'Daily Transactions'!D:D,"Bank_Cash") -> 135 | F52: =SUMIFS('Daily Transactions'!C:C,'Daily Transactions'!A:A,$A52,'Daily Transactions'!B:B,"<>Sales",'Daily Transactions'!D:D,"Bank") -> 4447 | G52: =B52-C52 -> 17267 | H52: =J51 -> 7436 | I52: =SUMIFS('Daily Transactions'!C:C,'Daily Transactions'!A:A,$A52,'Daily Transactions'!B:B,"Sales",'Daily Transactions'!D:D,"Cash") -> 1215 | J52: =(H52+I52)-(D52+E52) -> 8501 | L52: =SUMIFS('Daily Transactions'!C:C,'Daily Transactions'!A:A,$A52,'Daily Transactions'!B:B,"Cash Shortage",'Daily Transactions'!D:D,"Cash") -> 0
A53: =A52+1 -> 45707 | B53: =SUMIFS('Daily Transactions'!C:C,'Daily Transactions'!A:A,$A53,'Daily Transactions'!B:B,"Sales") -> 18724 | C53: =SUMIFS('Daily Transactions'!C:C,'Daily Transactions'!A:A,$A53,'Daily Transactions'!B:B,"<>Sales") -> 13749 | D53: =SUMIFS('Daily Transactions'!C:C,'Daily Transactions'!A:A,$A53,'Daily Transactions'!B:B,"<>Sales",'Daily Transactions'!D:D,"Cash") -> 40 | E53: =SUMIFS('Daily Transactions'!C:C,'Daily Transactions'!A:A,$A53,'Daily Transactions'!B:B,"<>Sales",'Daily Transactions'!D:D,"Bank_Cash") -> 5505 | F53: =SUMIFS('Daily Transactions'!C:C,'Daily Transactions'!A:A,$A53,'Daily Transactions'!B:B,"<>Sales",'Daily Transactions'!D:D,"Bank") -> 8204 | G53: =B53-C53 -> 4975 | H53: =J52 -> 8501 | I53: =SUMIFS('Daily Transactions'!C:C,'Daily Transactions'!A:A,$A53,'Daily Transactions'!B:B,"Sales",'Daily Transactions'!D:D,"Cash") -> 2677 | J53: =(H53+I53)-(D53+E53) -> 5633 | L53: =SUMIFS('Daily Transactions'!C:C,'Daily Transactions'!A:A,$A53,'Daily Transactions'!B:B,"Cash Shortage",'Daily Transactions'!D:D,"Cash") -> 0
A54: =A53+1 -> 45708 | B54: =SUMIFS('Daily Transactions'!C:C,'Daily Transactions'!A:A,$A54,'Daily Transactions'!B:B,"Sales") -> 21748 | C54: =SUMIFS('Daily Transactions'!C:C,'Daily Transactions'!A:A,$A54,'Daily Transactions'!B:B,"<>Sales") -> 7916 | D54: =SUMIFS('Daily Transactions'!C:C,'Daily Transactions'!A:A,$A54,'Daily Transactions'!B:B,"<>Sales",'Daily Transactions'!D:D,"Cash") -> 20 | E54: =SUMIFS('Daily Transactions'!C:C,'Daily Transactions'!A:A,$A54,'Daily Transactions'!B:B,"<>Sales",'Daily Transactions'!D:D,"Bank_Cash") -> 2871 | F54: =SUMIFS('Daily Transactions'!C:C,'Daily Transactions'!A:A,$A54,'Daily Transactions'!B:B,"<>Sales",'Daily Transactions'!D:D,"Bank") -> 5025 | G54: =B54-C54 -> 13832 | H54: =J53 -> 5633 | I54: =SUMIFS('Daily Transactions'!C:C,'Daily Transactions'!A:A,$A54,'Daily Transactions'!B:B,"Sales",'Daily Transactions'!D:D,"Cash") -> 4700 | J54: =(H54+I54)-(D54+E54) -> 7442 | L54: =SUMIFS('Daily Transactions'!C:C,'Daily Transactions'!A:A,$A54,'Daily Transactions'!B:B,"Cash Shortage",'Daily Transactions'!D:D,"Cash") -> 0
A55: =A54+1 -> 45709 | B55: =SUMIFS('Daily Transactions'!C:C,'Daily Transactions'!A:A,$A55,'Daily Transactions'!B:B,"Sales") -> 27657 | C55: =SUMIFS('Daily Transactions'!C:C,'Daily Transactions'!A:A,$A55,'Daily Transactions'!B:B,"<>Sales") -> 13533 | D55: =SUMIFS('Daily Transactions'!C:C,'Daily Transactions'!A:A,$A55,'Daily Transactions'!B:B,"<>Sales",'Daily Transactions'!D:D,"Cash") -> 50 | E55: =SUMIFS('Daily Transactions'!C:C,'Daily Transactions'!A:A,$A55,'Daily Transactions'!B:B,"<>Sales",'Daily Transactions'!D:D,"Bank_Cash") -> 2530 | F55: =SUMIFS('Daily Transactions'!C:C,'Daily Transactions'!A:A,$A55,'Daily Transactions'!B:B,"<>Sales",'Daily Transactions'!D:D,"Bank") -> 10953 | G55: =B55-C55 -> 14124 | H55: =J54 -> 7442 | I55: =SUMIFS('Daily Transactions'!C:C,'Daily Transactions'!A:A,$A55,'Daily Transactions'!B:B,"Sales",'Daily Transactions'!D:D,"Cash") -> 1229 | J55: =(H55+I55)-(D55+E55) -> 6091 | L55: =SUMIFS('Daily Transactions'!C:C,'Daily Transactions'!A:A,$A55,'Daily Transactions'!B:B,"Cash Shortage",'Daily Transactions'!D:D,"Cash") -> 0
A56: =A55+1 -> 45710 | B56: =SUMIFS('Daily Transactions'!C:C,'Daily Transactions'!A:A,$A56,'Daily Transactions'!B:B,"Sales") -> 24988 | C56: =SUMIFS('Daily Transactions'!C:C,'Daily Transactions'!A:A,$A56,'Daily Transactions'!B:B,"<>Sales") -> 16851 | D56: =SUMIFS('Daily Transactions'!C:C,'Daily Transactions'!A:A,$A56,'Daily Transactions'!B:B,"<>Sales",'Daily Transactions'!D:D,"Cash") -> 2040 | E56: =SUMIFS('Daily Transactions'!C:C,'Daily Transactions'!A:A,$A56,'Daily Transactions'!B:B,"<>Sales",'Daily Transactions'!D:D,"Bank_Cash") -> 3730 | F56: =SUMIFS('Daily Transactions'!C:C,'Daily Transactions'!A:A,$A56,'Daily Transactions'!B:B,"<>Sales",'Daily Transactions'!D:D,"Bank") -> 11081 | G56: =B56-C56 -> 8137 | H56: =J55 -> 6091 | I56: =SUMIFS('Daily Transactions'!C:C,'Daily Transactions'!A:A,$A56,'Daily Transactions'!B:B,"Sales",'Daily Transactions'!D:D,"Cash") -> 3140 | J56: =(H56+I56)-(D56+E56) -> 3461 | L56: =SUMIFS('Daily Transactions'!C:C,'Daily Transactions'!A:A,$A56,'Daily Transactions'!B:B,"Cash Shortage",'Daily Transactions'!D:D,"Cash") -> 0
A57: =A56+1 -> 45711 | B57: =SUMIFS('Daily Transactions'!C:C,'Daily Transactions'!A:A,$A57,'Daily Transactions'!B:B,"Sales") -> 26423 | C57: =SUMIFS('Daily Transactions'!C:C,'Daily Transactions'!A:A,$A57,'Daily Transactions'!B:B,"<>Sales") -> 5841 | D57: =SUMIFS('Daily Transactions'!C:C,'Daily Transactions'!A:A,$A57,'Daily Transactions'!B:B,"<>Sales",'Daily Transactions'!D:D,"Cash") -> 40 | E57: =SUMIFS('Daily Transactions'!C:C,'Daily Transactions'!A:A,$A57,'Daily Transactions'!B:B,"<>Sales",'Daily Transactions'!D:D,"Bank_Cash") -> 1515 | F57: =SUMIFS('Daily Transactions'!C:C,'Daily Transactions'!A:A,$A57,'Daily Transactions'!B:B,"<>Sales",'Daily Transactions'!D:D,"Bank") -> 4286 | G57: =B57-C57 -> 20582 | H57: =J56 -> 3461 | I57: =SUMIFS('Daily Transactions'!C:C,'Daily Transactions'!A:A,$A57,'Daily Transactions'!B:B,"Sales",'Daily Transactions'!D:D,"Cash") -> 1460 | J57: =(H57+I57)-(D57+E57) -> 3366 | L57: =SUMIFS('Daily Transactions'!C:C,'Daily Transactions'!A:A,$A57,'Daily Transactions'!B:B,"Cash Shortage",'Daily Transactions'!D:D,"Cash") -> 0
...

Sheet Daily Photo
K2: Item/Description | L2: Sales
C3: Expenses
B4: SUM of Amount | D4: Mode | K4: SUM of Amount | L4: f
B5: f | C5: Item/Description | D5: Bank | E5: Bank_Cash | F5: Cash | G5: (empty) | H5: Total Result | K5: Mode | L5: 45679 | M5: 45680 | N5: 45681 | O5: 45682 | P5: 45683 | Q5: 45684 | R5: 45685 | S5: 45686 | T5: 45687 | U5: 45688 | V5: 45689 | W5: 45690 | X5: 45691 | Y5: 45692 | Z5: 45693 | AA5: 45694 | AB5: 45695 | AC5: 45696 | AD5: 45697 | AE5: 45698 | AF5: 45699 | AG5: 45700 | AH5: 45701 | AI5: 45702 | AJ5: 45703 | AK5: 45704 | AL5: 45705 | AM5: 45706 | AN5: 45707 | AO5: 45708 | AP5: 45709 | AQ5: 45710 | AR5: 45711 | AS5: 45712 | AT5: 45713 | AU5: 45715 | AV5: 45716 | AW5: 45717 | AX5: 45718 | AY5: 45719 | AZ5: 45720 | BA5: 45721 | BB5: 45722 | BC5: 45723 | BD5: 45724 | BE5: 45725 | BF5: 45726 | BG5: 45727 | BH5: 45728 | BI5: 45729 | BJ5: 45730 | BK5: 45731 | BL5: 45732 | BM5: 45733 | BN5: 45734 | BO5: 45735 | BP5: 45736 | BQ5: 45737 | BR5: 45738 | BS5: 45739 | BT5: 45740 | BU5: 45741 | BV5: 45742 | BW5: 45743 | BX5: 45744 | BY5: 45745 | BZ5: 45746 | CA5: 45747 | CB5: 45748 | CC5: 45749 | CD5: 45750 | CE5: 45751 | CF5: 45752 | CG5: 45753 | CH5: 45754 | CI5: 45755 | CJ5: 45756 | CK5: 45757 | CL5: 45758 | CM5: 45759 | CN5: 45760 | CO5: 45761 | CP5: 45762 | CQ5: 45763 | CR5: 45764 | CS5: 45765 | CT5: 45766 | CU5: 45767 | CV5: 45768 | CW5: 45769 | CX5: 45770 | CY5: 45771 | CZ5: 45772 | DA5: 45773 | DB5: 45774 | DC5: 45775 | DD5: 45776 | DE5: 45777 | DF5: 45778 | DG5: 45779 | DH5: 45780 | DI5: 45781 | DJ5: 45782 | DK5: 45783 | DL5: 45784 | DM5: 45785 | DN5: 45786 | DO5: 45787 | DP5: 45788 | DQ5: 45789 | DR5: 45790 | DS5: 45791 | DT5: 45792 | DU5: 45793 | DV5: 45794 | DW5: 45795 | DX5: 45796 | DY5: 45797 | DZ5: 45798 | EA5: 45799 | EB5: 45800 | EC5: 45801 | ED5: 45802 | EE5: 45803 | EF5: 45804 | EG5: 45805 | EH5: 45806 | EI5: 45807 | EJ5: 45808 | EK5: 45809 | EL5: 45810 | EM5: 45811 | EN5: 45812 | EO5: 45813 | EP5: 45814 | EQ5: 45815 | ER5: 45816 | ES5: 45817 | ET5: 45818 | EU5: 45819 | EV5: 45820 | EW5: 45821 | EX5: 45822 | EY5: 45823 | EZ5: 45825 | FA5: 45826 | FB5: 45827 | FC5: 45828 | FD5: 45829 | FE5: 45830 | FF5: 45831 | FG5: 45832 | FH5: 45833 | FI5: 45834 | FJ5: 45835 | FK5: 45836 | FL5: 45837 | FM5: 45838 | FN5: 45839 | FO5: 45840 | FP5: 45841 | FQ5: 45842 | FR5: 45843 | FS5: 45844 | FT5: 45845 | FU5: 45846 | FV5: 45847 | FW5: 45848 | FX5: 45849 | FY5: 45850 | FZ5: 45851 | GA5: 45852 | GB5: 45853 | GC5: 45854 | GD5: 45855 | GE5: 45856 | GF5: 45857 | GG5: 45858 | GH5: 45859 | GI5: 45860 | GJ5: 45861 | GK5: 45862 | GL5: 45863 | GM5: 45864 | GN5: 45865 | GO5: 45866 | GP5: 45867 | GQ5: 45868 | GR5: 45869 | GS5: 45870 | GT5: 45871 | GU5: 45872 | GV5: 45873 | GW5: 45874 | GX5: 45875 | GY5: 45876 | GZ5: 45877 | HA5: 45878 | HB5: 45879 | HC5: 45880 | HD5: 45881 | HE5: 45882 | HF5: 45883 | HG5: 45884 | HH5: 45885 | HI5: 45886 | HJ5: 45887 | HK5: 45888 | HL5: 45889 | HM5: 45890 | HN5: 45891 | HO5: 45892 | HP5: 45893 | HQ5: 45894 | HR5: 45895 | HS5: 45896 | HT5: 45897 | HU5: 45898 | HV5: 45899 | HW5: 45900 | HX5: 45901 | HY5: 45902 | HZ5: 45903 | IA5: 45904 | IB5: 45905 | IC5: 45906 | ID5: 45907 | IE5: 45908 | IF5: 45909 | IG5: 45910 | IH5: 45911 | II5: 45912 | IJ5: 45913 | IK5: 45914 | IL5: 45915 | IM5: 45916 | IN5: 45917 | IO5: 45918 | IP5: 45919 | IQ5: 45920 | IR5: 45921 | IS5: 45922 | IT5: 45923 | IU5: 45924 | IV5: 45925 | IW5: 45926 | IX5: 45927 | IY5: 45928 | IZ5: 45929 | JA5: 45930 | JB5: 45931 | JC5: 45932 | JD5: 45933 | JE5: 45934 | JF5: 45935 | JG5: 45936 | JH5: 45937 | JI5: 45938 | JJ5: 45939 | JK5: 45940 | JL5: 45941 | JM5: 45942 | JN5: 45943 | JO5: 45944 | JP5: 45945 | JQ5: 45946 | JR5: 45947 | JS5: 45948 | JT5: 45949 | JU5: 45950 | JV5: 45951 | JW5: 45952 | JX5: 45953 | JY5: 45954 | JZ5: 45955 | KA5: 45956 | KB5: 45957 | KC5: 45958 | KD5: 45959 | KE5: 45960 | KF5: 45961 | KG5: 45962 | KH5: 45963 | KI5: 45964 | KJ5: 45965 | KK5: 45966 | KL5: 45967 | KM5: 45968 | KN5: 45969 | KO5: 45970 | KP5: 45971 | KQ5: 45972 | KR5: 45973 | KS5: 45974 | KT5: 45975 | KU5: 45976 | KV5: 45977 | KW5: 45978 | KX5: 45979 | KY5: 45980 | KZ5: 45981 | LA5: 45982 | LB5: 45983 | LC5: 45984 | LD5: 45985 | LE5: 45986 | LF5: 45987 | LG5: 45988 | LH5: Total Result
B6: 45679 | C6: Bakery | F6: 325 | H6: 325 | K6: Bank | ET6: 13949 | FE6: 3200 | LH6: 17149
C7: Chicken | D7: 5627 | H7: 5627 | K7: Card | L7: 1314 | N7: 250 | P7: 1620 | Q7: 1500 | R7: 1570 | T7: 530 | U7: 1395 | V7: 2285 | W7: 2510 | X7: 879 | Y7: 20 | AC7: 1910 | AD7: 531 | AF7: 480 | AG7: 380 | AH7: 180 | AI7: 750 | AJ7: 1685 | AK7: 1055 | AM7: 1835 | AN7: 410 | AP7: 1755 | AR7: 1350 | AS7: 765 | AU7: 2130 | AV7: 3690 | AW7: 760 | AY7: 654 | AZ7: 705 | BB7: 180 | BC7: 2755 | BD7: 449 | BE7: 2880 | BG7: 370 | BH7: 2475 | BI7: 475 | BJ7: 1088 | BL7: 1200 | BP7: 790 | BQ7: 1615 | BR7: 3315 | BS7: 1160 | BT7: 440 | BU7: 2870 | BV7: 155 | BW7: 860 | BX7: 1075 | CA7: 2090 | CB7: 400 | CE7: 790 | CF7: 1425 | CG7: 280 | CH7: 1970 | CJ7: 1370 | CK7: 1155 | CL7: 650 | CM7: 705 | CN7: 935 | CP7: 1080 | CQ7: 1270 | CT7: 1035 | CU7: 1330 | CV7: 380 | CW7: 1079 | CX7: 935 | CY7: 210 | CZ7: 1105 | DA7: 2320 | DB7: 1590 | DD7: 155 | DF7: 210 | DG7: 685 | DH7: 1460 | DJ7: 825 | DK7: 480 | DN7: 894 | DO7: 980 | DP7: 1445 | DR7: 435 | DS7: 1120 | DU7: 3920 | DW7: 1750 | DY7: 170 | DZ7: 1360 | EA7: 1055 | EB7: 225 | ED7: 260 | EE7: 80 | EG7: 230 | EH7: 1565 | EI7: 454 | EK7: 1650 | EL7: 915 | EM7: 320 | EN7: 230 | EO7: 430 | EP7: 1565 | EQ7: 520 | ER7: 410 | ES7: 799 | EU7: 2360 | EV7: 1165 | EX7: 1060 | FA7: 3010 | FB7: 1089 | FD7: 270 | FF7: 210 | FG7: 850 | FI7: 250 | FJ7: 1840 | FK7: 3263 | FM7: 1380 | FN7: 448 | FP7: 160 | FU7: 510 | FV7: 440 | FW7: 1110 | FX7: 765 | FY7: 965 | FZ7: 360 | GA7: 715 | GC7: 430 | GD7: 1135 | GF7: 300 | GG7: 1600 | GJ7: 250 | GK7: 1569 | GL7: 155 | GM7: 80 | GO7: 1139 | GP7: 175 | GQ7: 1475 | GS7: 120 | GT7: 200 | GU7: 610 | GX7: 430 | GY7: 325 | GZ7: 1020 | HB7: 1625 | HD7: 810 | HE7: 320 | HF7: 389 | HG7: 200 | HN7: 1570 | HP7: 665 | HV7: 735 | HW7: 1014 | IB7: 340 | IC7: 680 | ID7: 985 | IN7: 1170 | IP7: 1695 | IQ7: 260 | IR7: 625 | IU7: 210 | IW7: 440 | IX7: 1610 | IY7: 400 | IZ7: 1480 | JB7: 2280 | JC7: 2395 | JD7: 250 | JE7: 3030 | JF7: 380 | JH7: 230 | JI7: 1145 | JJ7: 210 | JK7: 1555 | JL7: 1660 | JM7: 2025 | JO7: 1310 | JP7: 585 | JQ7: 190 | JR7: 1255 | JS7: 620 | JT7: 1920 | JY7: 3964 | JZ7: 549 | KB7: 665 | KD7: 1750 | KF7: 2085 | KG7: 390 | KI7: 830 | KJ7: 710 | KM7: 5860 | KN7: 3915 | KO7: 1850 | KP7: 560 | KQ7: 360 | KS7: 130 | KT7: 12010 | KU7: 2725 | KW7: 720 | KX7: 210 | LB7: 710 | LC7: 2160 | LE7: 800 | LF7: 570 | LG7: 0 | LH7: 224770
C8: Dairy | D8: 1617 | F8: 855 | H8: 2472 | K8: Cash | L8: 4759 | M8: 2410 | N8: 3140 | O8: 5660 | P8: 3979 | Q8: 2540 | R8: 2415 | S8: 2710 | T8: 1700 | U8: 1840 | V8: 5015 | W8: 3340 | X8: 3065 | Y8: 2268 | Z8: 2390 | AA8: 3600 | AB8: 2160 | AC8: 5260 | AD8: 4599 | AE8: 3645 | AF8: 3210 | AG8: 4148 | AH8: 1800 | AI8: 1999 | AJ8: 5244 | AK8: 2335 | AL8: 2465 | AM8: 1215 | AN8: 2677 | AO8: 4700 | AP8: 1229 | AQ8: 3140 | AR8: 1460 | AS8: 2085 | AT8: 1240 | AU8: 4580 | AV8: 5440 | AW8: 4259 | AX8: 1870 | AY8: 2014 | AZ8: 3979 | BA8: 2234 | BB8: 1385 | BC8: 2745 | BD8: 4715 | BE8: 4743 | BF8: 1210 | BG8: 2620 | BH8: 4984 | BI8: 1360 | BJ8: 5235 | BK8: 2905 | BL8: 3548 | BM8: 1050 | BN8: 1805 | BO8: 1510 | BP8: 2080 | BQ8: 7710 | BR8: 7456 | BS8: 9034 | BT8: 4295 | BU8: 1500 | BV8: 4760 | BW8: 2640 | BX8: 1370 | BY8: 2695 | BZ8: 3074 | CA8: 3010 | CB8: 2684 | CC8: 2145 | CD8: 2320 | CE8: 2970 | CF8: 3444 | CG8: 2725 | CH8: 6595 | CI8: 1810 | CJ8: 5600 | CK8: 4635 | CL8: 1815 | CM8: 3210 | CN8: 3355 | CO8: 3600 | CP8: 2875 | CQ8: 2760 | CR8: 2440 | CS8: 2575 | CT8: 3970 | CU8: 6045 | CV8: 3440 | CW8: 2650 | CX8: 2610 | CY8: 1415 | CZ8: 3210 | DA8: 3760 | DB8: 3455 | DC8: 5320 | DD8: 4929 | DE8: 3140 | DF8: 2744 | DG8: 3895 | DH8: 2390 | DI8: 4645 | DJ8: 2934 | DK8: 1225 | DL8: 5790 | DM8: 800 | DN8: 2500 | DO8: 6055 | DP8: 1950 | DQ8: 3370 | DR8: 4000 | DS8: 3225 | DT8: 1060 | DU8: 580 | DV8: 5435 | DW8: 5350 | DX8: 4265 | DY8: 2110 | DZ8: 6335 | EA8: 1954 | EB8: 3139 | EC8: 2400 | ED8: 3565 | EE8: 1200 | EF8: 4119 | EG8: 2770 | EH8: 3295 | EI8: 1710 | EJ8: 2580 | EK8: 2169 | EL8: 2319 | EM8: 1140 | EN8: 3900 | EO8: 3230 | EP8: 2865 | EQ8: 1610 | ER8: 2381 | ES8: 1795 | ET8: 3179 | EU8: 1992 | EV8: 4055 | EW8: 1420 | EX8: 3725 | EY8: 6130 | EZ8: 3145 | FA8: 2362 | FB8: 5944 | FC8: 4245 | FD8: 5233 | FE8: 6085 | FF8: 3307 | FG8: 2760 | FH8: 3117 | FI8: 4255 | FJ8: 3435 | FK8: 3325 | FL8: 4070 | FM8: 390 | FN8: 3120 | FO8: 1660 | FP8: 3790 | FQ8: 3555 | FR8: 6324 | FS8: 2615 | FT8: 1870 | FU8: 2989 | FV8: 1895 | FW8: 1939 | FX8: 5103 | FY8: 4694 | FZ8: 7223 | GA8: 860 | GB8: 3053 | GC8: 5329 | GD8: 3555 | GE8: 735 | GF8: 2930 | GG8: 2960 | GH8: 680 | GI8: 3455 | GJ8: 1850 | GK8: 1050 | GL8: 1855 | GM8: 2360 | GN8: 3865 | GO8: 1720 | GP8: 940 | GQ8: 3789 | GR8: 1949 | GS8: 1880 | GT8: 2675 | GU8: 3559 | GV8: 4025 | GW8: 3035 | GX8: 1825 | GY8: 4147 | GZ8: 1180 | HA8: 2189 | HB8: 2960 | HC8: 910 | HD8: 1810 | HE8: 1310 | HF8: 3750 | HG8: 3070 | HH8: 2530 | HI8: 2105 | HJ8: 1650 | HK8: 380 | HL8: 750 | HM8: 2355 | HN8: 3160 | HO8: 5603 | HP8: 2560 | HQ8: 2913 | HR8: 1125 | HS8: 1310 | HT8: 2390 | HU8: 1935 | HV8: 1470 | HW8: 520 | HX8: 2400 | HY8: 3403 | HZ8: 900 | IA8: 3178 | IB8: 1940 | IC8: 3365 | ID8: 2655 | IE8: 406 | IF8: 1295 | IG8: 2839 | IH8: 3311 | II8: 3119 | IJ8: 1475 | IK8: 1550 | IL8: 1759 | IM8: 2790 | IN8: 2000 | IO8: 4180 | IP8: 5625 | IQ8: 2414 | IR8: 1825 | IS8: 1430 | IT8: 2820 | IU8: 1230 | IV8: 1610 | IW8: 1570 | IX8: 1910 | IY8: 1335 | IZ8: 340 | JA8: 3070 | JB8: 3920 | JC8: 2930 | JD8: 1485 | JE8: 1820 | JF8: 5655 | JG8: 1270 | JH8: 3550 | JI8: 3470 | JJ8: 2854 | JK8: 4545 | JL8: 1275 | JM8: 5165 | JN8: 1744 | JO8: 3670 | JP8: 3015 | JQ8: 5155 | JR8: 1415 | JS8: 2780 | JT8: 3390 | JU8: 3190 | JV8: 4740 | JW8: 4335 | JX8: 5059 | JY8: 3110 | JZ8: 5789 | KA8: 2424 | KB8: 4625 | KC8: 3699 | KD8: 6418 | KE8: 3435 | KF8: 3450 | KG8: 591 | KH8: 5673 | KI8: 1924 | KJ8: 7490 | KK8: 4975 | KL8: 5289 | KM8: 1960 | KN8: 3380 | KO8: 10912 | KP8: 1010 | KQ8: 4715 | KR8: 2880 | KS8: 3675 | KT8: 2765 | KU8: 3214 | KV8: 4490 | KW8: 1660 | KX8: 2128 | KY8: 3679 | KZ8: 2745 | LA8: 5385 | LB8: 10140 | LC8: 4690 | LD8: 3050 | LE8: 4280 | LF8: 2960 | LG8: 4570 | LH8: 959881
C9: Electric Work | F9: 60 | H9: 60 | K9: Due | U9: 210 | AO9: 180 | AP9: 230 | AT9: 100 | AV9: 260 | BS9: 530 | DO9: 1520 | DS9: 170 | EB9: 300 | ED9: 30 | EJ9: 389 | EO9: 260 | FO9: 840 | FW9: 200 | HW9: 910 | IE9: 580 | II9: 240 | IL9: 370 | IM9: 250 | IN9: 880 | IQ9: 310 | IR9: 470 | JD9: 1280 | JE9: 1670 | JG9: 680 | JH9: 320 | JI9: 250 | JL9: 575 | JN9: 670 | JR9: 446 | JV9: 1270 | KA9: 420 | KI9: 2700 | KN9: 1130 | KX9: 530 | LB9: 300 | LH9: 21470
